Workbook

Sheet 1
E3: PRO MUNDO COMEX S.A.C.
E4: RUC: 20612452432
E7: COTIZACION N002
B8: NOMBRE: | C8: MARIBEL VILMA GONZALES HUANCA | E8: SERVICIO: | F8: CARGA CONSOLIDADA | I8: N° CAJAS: | J8: =+'2'!F7 -> 0
B9: APELLIDO: | E9: FECHA: | F9: =+TODAY() -> 45969 | I9: PESO: | J9: 284.5 Kg
B10: DNI/RUC: | C10: 41877382 | E10: ORIGEN: | F10: CHINA | I10: MEDIDA:
B11: TELEFONO: | C11: 51 965 497 474 | E11: CLIENTE: | F11: MANUAL | I11: CBM | J11: ='2'!K7 -> 2.3
B13: CALCULO DE BASE IMPONIBLE | K13: MONTO | L13: MONEDA
B14: VALOR DE CARGA | K14: ='2'!K11 -> 5662.08 | L14: USD
B15: FLETE INTERNACIONAL + SEGURO | K15: ='2'!K14 + '2'!K17 -> 631.0654 | L15: USD
B16: VALOR CIF | K16: =SUM(K14:K15) -> 6293.1454 | L16: USD
B19: CALCULO DE TRIBUTOS | J19: % | K19: MONTO | L19: MONEDA
B20: ADVALOREM | J20: =MAX('2'!C27:I27) -> 0 | K20: ='2'!K28 -> 0 | L20: USD | N20: Hola MARIBEL VILMA GONZALES HUANCA 😁 un gusto saludarte! A continuación te envío la cotización final de tu importación📋📦. 🙋‍♂️ PAGO PENDIENTE : ☑️Costo CBM: $457.17804 ☑️Impuestos: $1392.67 ☑️ Total: $1849.84804 Pronto le aviso nuevos avances, que tengan buen día🚢 Último día de pago:
B21: IGV | J21: 0.16 | K21: ='2'!K29 -> 1006.9033 | L21: USD
B22: IPM | J22: 0.02 | K22: ='2'!K30 -> 125.86291 | L22: USD
B23: SUB TOTAL | K23: =SUM(K20:K22) -> 1132.7662 | L23: USD
B25: PERCEPCIÓN | J25: 3.5% | K25: ='2'!K31 -> 259.90691 | L25: USD
B26: TOTAL | K26: =K23+K25 -> 1392.6731 | L26: USD
B28: RESUMEN DE COTIZACIÓN | K28: MONTO | L28: MONEDA
B29: VALOR DE CARGA (PAGO AL PROVEEDOR) | K29: =K14 -> 5662.08 | L29: USD
B30: SERVICIO DE IMPORTACIÓN (ORIGEN -FLETE - DESTINO) | K30: =IF(J11<1, '2'!O7, '2'!O7*J11) -> 885.109 | L30: USD
B31: IMPUESTOS | K31: =K26 -> 1392.6731 | L31: USD
B32: MONTO TOTAL | K32: =SUM(K29:K31) -> 7939.8621 | L32: USD
B34: SIMULACIÓN DEL PRECIO PUESTO EN PERÚ POR PIEZA
B35: # ITEM | C35: NOMBRE PRODUCTO | F35: CANTIDAD | G35: COSTO UNI. | I35: PRECIO U. | J35: TOTAL | K35: PRECIO UNIT. (SOLES)
B36: 1 | C36: BOINA MODELO LAZO | F36: ='2'!C10 -> 440 | G36: ='2'!C8 -> 1.55 | I36: ='2'!C46 -> 2.1735451 | J36: ='2'!C44 -> 956.35984 | K36: ='2'!C47 -> 8.0421169
B37: 2 | C37: GORRA DE INVIERNO | F37: ='2'!D10 -> 480 | G37: ='2'!D8 -> 1.65 | I37: ='2'!D46 -> 2.3137738 | J37: ='2'!D44 -> 1110.6114 | K37: ='2'!D47 -> 8.5609631
B38: 3 | C38: SOMBRERO MODELO LAZO | F38: ='2'!E10 -> 300 | G38: ='2'!E8 -> 1.8 | I38: ='2'!E46 -> 2.5241169 | J38: ='2'!E44 -> 757.23507 | K38: ='2'!E47 -> 9.3392325
B39: 4 | C39: SOMBRERO MODELO LISTON | F39: ='2'!F10 -> 194 | G39: ='2'!F8 -> 2.02 | I39: ='2'!F46 -> 2.8326201 | J39: ='2'!F44 -> 549.52829 | K39: ='2'!F47 -> 10.480694
B40: 5 | C40: GORRO DE INVIERNO PARA NIÑAS | F40: ='2'!G10 -> 850 | G40: ='2'!G8 -> 1.8635294 | I40: ='2'!G46 -> 2.6132034 | J40: ='2'!G44 -> 2221.2229 | K40: ='2'!G47 -> 9.6688524
B41: 6 | C41: GORRA DE INVIERNO MODELO OREJAS | F41: ='2'!H10 -> 300 | G41: ='2'!H8 -> 1.83 | I41: ='2'!H46 -> 2.5661855 | J41: ='2'!H44 -> 769.85565 | K41: ='2'!H47 -> 9.4948864
B42: 7 | C42: SOMBRERO MODELO OSO | F42: ='2'!I10 -> 240 | G42: ='2'!I8 -> 1.65 | I42: ='2'!I46 -> 2.3137738 | J42: ='2'!I44 -> 555.30571 | K42: ='2'!I47 -> 8.5609631
B43: 8 | C43: GORRA DE INVIERNO MODELO OSO | F43: ='2'!J10 -> 360 | G43: ='2'!J8 -> 2.02 | I43: ='2'!J46 -> 2.8326201 | J43: ='2'!J44 -> 1019.7432 | K43: ='2'!J47 -> 10.480694
B44: TOTAL | F44: =SUM(F36:F43) -> 3164 | J44: =SUM(J36:J43) -> 7939.8621
B45: NOTAS:
B46: *Las fechas brindadas son estimadas, estan sujetas a variación.
B47: *No se emite comprobante por concepto de "PERCEPCIÓN, ANTI DUMPING, GESTIÓN DE COMPRA"
B48: *A nosotros se nos pagan los Gastos Logísticos + Impuestos una semana antes de que el contenedor
B49: llegue al puerto del Callao.
B50: *El tipo de cambio referencial usado para la conversión a soles es del 3.70
...

Sheet 2
B3: Calculo de Tributos
B5: Nombres | C5: BOINA MODELO LAZO | D5: GORRA DE INVIERNO | E5: SOMBRERO MODELO LAZO | F5: SOMBRERO MODELO LISTON | G5: GORRO DE INVIERNO PARA NIÑAS | H5: GORRA DE INVIERNO MODELO OREJAS | I5: SOMBRERO MODELO OSO | J5: GORRA DE INVIERNO MODELO OSO | K5: Total
B6: Peso | C6: 0 | D6: 0 | E6: 0 | F6: 0 | G6: 0 | H6: 0 | I6: 0 | J6: 0 | K6: 284.5 | N6: Tipo Cliente | O6: Tarifa
B7: Valor CBM | C7: 0 | D7: 0 | E7: 0 | F7: 0 | G7: 0 | H7: 0 | I7: 0 | J7: 0 | K7: 2.3 | N7: MANUAL | O7: 384.83
B8: Valor Unitario | C8: 1.55 | D8: 1.65 | E8: 1.8 | F8: 2.02 | G8: 1.8635294 | H8: 1.83 | I8: 1.65 | J8: 2.02
B9: Valoracion | C9: 0 | D9: 0 | E9: 0 | F9: 0 | G9: 0 | H9: 0 | I9: 0 | J9: 0
B10: Cantidad | C10: 440 | D10: 480 | E10: 300 | F10: 194 | G10: 850 | H10: 300 | I10: 240 | J10: 360 | K10: =SUM(C10:J10) -> 3164
B11: Valor FOB | C11: =C8*C10 -> 682 | D11: =D8*D10 -> 792 | E11: =E8*E10 -> 540 | F11: =F8*F10 -> 391.88 | G11: =G8*G10 -> 1584 | H11: =H8*H10 -> 549 | I11: =I8*I10 -> 396 | J11: =J8*J10 -> 727.2 | K11: =SUM(C11:J11) -> 5662.08
B12: Valor FOB Valoracion | C12: =C10*C9 -> 0 | D12: =D10*D9 -> 0 | E12: =E10*E9 -> 0 | F12: =F10*F9 -> 0 | G12: =G10*G9 -> 0 | H12: =H10*H9 -> 0 | I12: =I10*I9 -> 0 | J12: =J10*J9 -> 0 | K12: =SUM(C12:J12) -> 0
B13: Distribucion % | C13: =C11/K11 -> 0.12045044 | D13: =D11/K11 -> 0.13987792 | E13: =E11/K11 -> 0.095371312 | F13: =F11/K11 -> 0.069211315 | G13: =G11/K11 -> 0.27975585 | H13: =H11/K11 -> 0.096960834 | I13: =I11/K11 -> 0.069938962 | J13: =J11/K11 -> 0.12843337
B14: Flete | C14: =K14*C13 -> 63.967059 | D14: =K14*D13 -> 74.284326 | E14: =K14*E13 -> 50.648404 | F14: =K14*F13 -> 36.755734 | G14: =K14*G13 -> 148.56865 | H14: =K14*H13 -> 51.492544 | I14: =K14*I13 -> 37.142163 | J14: =K14*J13 -> 68.206518 | K14: =IF(K7<1, O7*0.6, O7*0.6*K7) -> 531.0654
B15: Valor CFR | C15: =C11+C14 -> 745.96706 | D15: =D11+D14 -> 866.28433 | E15: =E11+E14 -> 590.6484 | F15: =F11+F14 -> 428.63573 | G15: =G11+G14 -> 1732.5687 | H15: =H11+H14 -> 600.49254 | I15: =I11+I14 -> 433.14216 | J15: =J11+J14 -> 795.40652 | K15: =SUM(C15:J15) -> 6193.1454
B16: CFR Valorizado | C16: =C12+C14 -> 63.967059 | D16: =D12+D14 -> 74.284326 | E16: =E12+E14 -> 50.648404 | F16: =F12+F14 -> 36.755734 | G16: =G12+G14 -> 148.56865 | H16: =H12+H14 -> 51.492544 | I16: =I12+I14 -> 37.142163 | J16: =J12+J14 -> 68.206518 | K16: =SUM(C16:J16) -> 531.0654
B17: Seguro | C17: =IF(K11>5000,100*C13,50*C13) -> 12.045044 | D17: =IF(K11>5000,100*D13,50*D13) -> 13.987792 | E17: =IF(K11>5000,100*E13,50*E13) -> 9.5371312 | F17: =IF(K11>5000,100*F13,50*F13) -> 6.9211315 | G17: =IF(K11>5000,100*G13,50*G13) -> 27.975585 | H17: =IF(K11>5000,100*H13,50*H13) -> 9.6960834 | I17: =IF(K11>5000,100*I13,50*I13) -> 6.9938962 | J17: =IF(K11>5000,100*J13,50*J13) -> 12.843337 | K17: =SUM(C17:J17) -> 100
B18: Valor CIF | C18: =C15+C17 -> 758.0121 | D18: =D15+D17 -> 880.27212 | E18: =E15+E17 -> 600.18554 | F18: =F15+F17 -> 435.55687 | G18: =G15+G17 -> 1760.5442 | H18: =H15+H17 -> 610.18863 | I18: =I15+I17 -> 440.13606 | J18: =J15+J17 -> 808.24985 | K18: =SUM(C18:J18) -> 6293.1454
B19: CIF Valorizado | C19: =C16+C17 -> 76.012102 | D19: =D16+D17 -> 88.272119 | E19: =E16+E17 -> 60.185535 | F19: =F16+F17 -> 43.676866 | G19: =G16+G17 -> 176.54424 | H19: =H16+H17 -> 61.188628 | I19: =I16+I17 -> 44.136059 | J19: =J16+J17 -> 81.049854 | K19: =SUM(C19:J19) -> 631.0654
B23: Tributos Aplicables
B26: ANTIDUMPING | C26: 0 | D26: 0 | E26: 0 | F26: 0 | G26: 0 | H26: 0 | I26: 0 | J26: 0 | K26: =SUM(C26:J26) -> 0
C27: 0 | D27: 0 | E27: 0 | F27: 0 | G27: 0 | H27: 0 | I27: 0 | J27: 0 | K27: =SUM(C27:J27) -> 0
B28: AD VALOREM | C28: =MAX(C19,C18)*C27 -> 0 | D28: =MAX(D19,D18)*D27 -> 0 | E28: =MAX(E19,E18)*E27 -> 0 | F28: =MAX(F19,F18)*F27 -> 0 | G28: =MAX(G19,G18)*G27 -> 0 | H28: =MAX(H19,H18)*H27 -> 0 | I28: =MAX(I19,I18)*I27 -> 0 | J28: =MAX(J19,J18)*J27 -> 0 | K28: =SUM(C28:J28) -> 0
B29: IGV | C29: =0.16*(MAX(C19,C18)+C28) -> 121.28194 | D29: =0.16*(MAX(D19,D18)+D28) -> 140.84354 | E29: =0.16*(MAX(E19,E18)+E28) -> 96.029686 | F29: =0.16*(MAX(F19,F18)+F28) -> 69.689099 | G29: =0.16*(MAX(G19,G18)+G28) -> 281.68708 | H29: =0.16*(MAX(H19,H18)+H28) -> 97.63018 | I29: =0.16*(MAX(I19,I18)+I28) -> 70.421769 | J29: =0.16*(MAX(J19,J18)+J28) -> 129.31998 | K29: =SUM(C29:J29) -> 1006.9033
B30: IPM | C30: =0.02*(MAX(C19,C18)+C28) -> 15.160242 | D30: =0.02*(MAX(D19,D18)+D28) -> 17.605442 | E30: =0.02*(MAX(E19,E18)+E28) -> 12.003711 | F30: =0.02*(MAX(F19,F18)+F28) -> 8.7111373 | G30: =0.02*(MAX(G19,G18)+G28) -> 35.210885 | H30: =0.02*(MAX(H19,H18)+H28) -> 12.203773 | I30: =0.02*(MAX(I19,I18)+I28) -> 8.8027212 | J30: =0.02*(MAX(J19,J18)+J28) -> 16.164997 | K30: =SUM(C30:J30) -> 125.86291
B31: PERCEPCION | C31: =0.035*(MAX(C18,C19) +C28+C29+C30) -> 31.3059 | D31: =0.035*(MAX(D18,D19) +D28+D29+D30) -> 36.355238 | E31: =0.035*(MAX(E18,E19) +E28+E29+E30) -> 24.787663 | F31: =0.035*(MAX(F18,F19) +F28+F29+F30) -> 17.988499 | G31: =0.035*(MAX(G18,G19) +G28+G29+G30) -> 72.710477 | H31: =0.035*(MAX(H18,H19) +H28+H29+H30) -> 25.20079 | I31: =0.035*(MAX(I18,I19) +I28+I29+I30) -> 18.177619 | J31: =0.035*(MAX(J18,J19) +J28+J29+J30) -> 33.380719 | K31: =SUM(C31:J31) -> 259.90691
B32: TOTAL | C32: =SUM(C28:C31) -> 167.74808 | D32: =SUM(D28:D31) -> 194.80422 | E32: =SUM(E28:E31) -> 132.82106 | F32: =SUM(F28:F31) -> 96.388734 | G32: =SUM(G28:G31) -> 389.60844 | H32: =SUM(H28:H31) -> 135.03474 | I32: =SUM(I28:I31) -> 97.40211 | J32: =SUM(J28:J31) -> 178.86569 | K32: =SUM(K28:K31) -> 1392.6731
B37: Costos Destinos
B40: ITEM | C40: =C13*K40 -> 42.644706 | D40: =D13*K40 -> 49.522884 | E40: =E13*K40 -> 33.765603 | F40: =F13*K40 -> 24.503823 | G40: =G13*K40 -> 99.045768 | H40: =H13*K40 -> 34.328363 | I40: =I13*K40 -> 24.761442 | J40: =J13*K40 -> 45.471012 | K40: =IF(K7<1, O7*0.4,O7*0.4*K7) -> 354.0436
B43: ITEM | C43: BOINA MODELO LAZO | D43: GORRA DE INVIERNO | E43: SOMBRERO MODELO LAZO | F43: SOMBRERO MODELO LISTON | G43: GORRO DE INVIERNO PARA NIÑAS | H43: GORRA DE INVIERNO MODELO OREJAS | I43: SOMBRERO MODELO OSO | J43: GORRA DE INVIERNO MODELO OSO | K43: Total
B44: COSTO TOTAL | C44: =SUM(C15,C40,C32,(C26)) -> 956.35984 | D44: =SUM(D15,D40,D32,(D26)) -> 1110.6114 | E44: =SUM(E15,E40,E32,(E26)) -> 757.23507 | F44: =SUM(F15,F40,F32,(F26)) -> 549.52829 | G44: =SUM(G15,G40,G32,(G26)) -> 2221.2229 | H44: =SUM(H15,H40,H32,(H26)) -> 769.85565 | I44: =SUM(I15,I40,I32,(I26)) -> 555.30571 | J44: =SUM(J15,J40,J32,(J26)) -> 1019.7432 | K44: =SUM(C44:J44) -> 7939.8621
B45: CANTIDAD | C45: 440 | D45: 480 | E45: 300 | F45: 194 | G45: 850 | H45: 300 | I45: 240 | J45: 360
B46: COSTO UNITARIO | C46: =SUM(C44/C45) -> 2.1735451 | D46: =SUM(D44/D45) -> 2.3137738 | E46: =SUM(E44/E45) -> 2.5241169 | F46: =SUM(F44/F45) -> 2.8326201 | G46: =SUM(G44/G45) -> 2.6132034 | H46: =SUM(H44/H45) -> 2.5661855 | I46: =SUM(I44/I45) -> 2.3137738 | J46: =SUM(J44/J45) -> 2.8326201
B47: COSTO SOLES | C47: =C46*3.7 -> 8.0421169 | D47: =D46*3.7 -> 8.5609631 | E47: =E46*3.7 -> 9.3392325 | F47: =F46*3.7 -> 10.480694 | G47: =G46*3.7 -> 9.6688524 | H47: =H46*3.7 -> 9.4948864 | I47: =I46*3.7 -> 8.5609631 | J47: =J46*3.7 -> 10.480694
