Workbook

Sheet 1
E3: PRO MUNDO COMEX S.A.C.
E4: RUC: 20612452432
E7: COTIZACION N002
B8: NOMBRE: | C8: CHRISTOPHER ARBAIZA SOLIS | E8: SERVICIO: | F8: CARGA CONSOLIDADA | I8: N° CAJAS: | J8: =+'2'!F7 -> 0
B9: APELLIDO: | E9: FECHA: | F9: =+TODAY() -> 45967 | I9: PESO: | J9: 3.085 Tn
B10: DNI/RUC: | E10: ORIGEN: | F10: CHINA | I10: MEDIDA:
B11: TELEFONO: | C11: 51972263251 | E11: CLIENTE: | F11: MANUAL | I11: CBM | J11: ='2'!Q7 -> 13.93
B13: CALCULO DE BASE IMPONIBLE | K13: MONTO | L13: MONEDA
B14: VALOR DE CARGA | K14: ='2'!Q11 -> 13595.25 | L14: USD
B15: FLETE INTERNACIONAL + SEGURO | K15: ='2'!Q14 + '2'!Q17 -> 2512.24 | L15: USD
B16: VALOR CIF | K16: =SUM(K14:K15) -> 16107.49 | L16: USD
B19: CALCULO DE TRIBUTOS | J19: % | K19: MONTO | L19: MONEDA
B20: ADVALOREM | J20: =MAX('2'!C27:O27) -> 0 | K20: ='2'!Q28 -> 0 | L20: USD | N20: Hola CHRISTOPHER ARBAIZA SOLIS 😁 un gusto saludarte! A continuación te envío la cotización final de tu importación📋📦. 🙋‍♂️ PAGO PENDIENTE : ☑️Costo CBM: $341.70444 ☑️Impuestos: $3562.77 ☑️ Total: $3904.47444 Pronto le aviso nuevos avances, que tengan buen día🚢 Último día de pago:
B21: IGV | J21: 0.16 | K21: ='2'!Q29 -> 2577.1984 | L21: USD
B22: IPM | J22: 0.02 | K22: ='2'!Q30 -> 322.1498 | L22: USD
B23: SUB TOTAL | K23: =SUM(K20:K22) -> 2899.3482 | L23: USD
B25: PERCEPCIÓN | J25: 3.5% | K25: ='2'!Q31 -> 665.23934 | L25: USD
B26: TOTAL | K26: =K23+K25 -> 3564.5875 | L26: USD
B28: RESUMEN DE COTIZACIÓN | K28: MONTO | L28: MONEDA
B29: VALOR DE CARGA (PAGO AL PROVEEDOR) | K29: =K14 -> 13595.25 | L29: USD
B30: SERVICIO DE IMPORTACIÓN (ORIGEN -FLETE - DESTINO) | K30: =IF(J11<1, '2'!U7, '2'!U7*J11) -> 4020.4 | L30: USD
B31: IMPUESTOS | K31: =K26 -> 3564.5875 | L31: USD
B32: MONTO TOTAL | K32: =SUM(K29:K31) -> 21180.238 | L32: USD
B34: SIMULACIÓN DEL PRECIO PUESTO EN PERÚ POR PIEZA
B35: # ITEM | C35: NOMBRE PRODUCTO | F35: CANTIDAD | G35: COSTO UNI. | I35: PRECIO U. | J35: TOTAL | K35: PRECIO UNIT. (SOLES)
B36: 1 | C36: PAPEL COREANO PARA ENVOLTURA DE FLORES | F36: ='2'!C10 -> 2200 | G36: ='2'!C8 -> 0.65 | I36: ='2'!C46 -> 1.0126444 | J36: ='2'!C44 -> 2227.8178 | K36: ='2'!C47 -> 3.7467844
B37: 2 | C37: CINTA DECORATIVA | F37: ='2'!D10 -> 2930 | G37: ='2'!D8 -> 0.8559727 | I37: ='2'!D46 -> 1.3335323 | J37: ='2'!D44 -> 3907.2496 | K37: ='2'!D47 -> 4.9340695
B38: 3 | C38: CINTA DECORATIVA SATINADA | F38: ='2'!E10 -> 555 | G38: ='2'!E8 -> 1.85 | I38: ='2'!E46 -> 2.8821419 | J38: ='2'!E44 -> 1599.5887 | K38: ='2'!E47 -> 10.663925
B39: 4 | C39: ENVOLTURA PARA RAMOS ONDULADO | F39: ='2'!F10 -> 1700 | G39: ='2'!F8 -> 0.5 | I39: ='2'!F46 -> 0.77895727 | J39: ='2'!F44 -> 1324.2274 | K39: ='2'!F47 -> 2.8821419
B40: 5 | C40: FLORES ARTIFICIALES DECORATIVAS | F40: ='2'!G10 -> 4000 | G40: ='2'!G8 -> 0.54 | I40: ='2'!G46 -> 0.84127385 | J40: ='2'!G44 -> 3365.0954 | K40: ='2'!G47 -> 3.1127132
B41: 6 | C41: BOLSA DECORATIVA PARA FLORES | F41: ='2'!H10 -> 1400 | G41: ='2'!H8 -> 0.35 | I41: ='2'!H46 -> 0.54527009 | J41: ='2'!H44 -> 763.37812 | K41: ='2'!H47 -> 2.0174993
B42: 7 | C42: BOLSA DE REGALO CON CADENITA | F42: ='2'!I10 -> 2750 | G42: ='2'!I8 -> 0.28 | I42: ='2'!I46 -> 0.43621607 | J42: ='2'!I44 -> 1199.5942 | K42: ='2'!I47 -> 1.6139995
B43: 8 | C43: BOLSA CON LAZO PARA FLORES | F43: ='2'!J10 -> 1250 | G43: ='2'!J8 -> 0.29 | I43: ='2'!J46 -> 0.45179521 | J43: ='2'!J44 -> 564.74402 | K43: ='2'!J47 -> 1.6716423
B44: 9 | C44: CAJA DECORATIVA PARA FLORES | F44: ='2'!K10 -> 1100 | G44: ='2'!K8 -> 0.16 | I44: ='2'!K46 -> 0.24926632 | J44: ='2'!K44 -> 274.19296 | K44: ='2'!K47 -> 0.9222854
B45: 10 | C45: BOLSA DE DECORACION PARA FLORES | F45: ='2'!L10 -> 2800 | G45: ='2'!L8 -> 0.29 | I45: ='2'!L46 -> 0.45179521 | J45: ='2'!L44 -> 1265.0266 | K45: ='2'!L47 -> 1.6716423
B46: 11 | C46: BOLSA DE REGALO CON ASAS | F46: ='2'!M10 -> 6300 | G46: ='2'!M8 -> 0.24761905 | I46: ='2'!M46 -> 0.38576931 | J46: ='2'!M44 -> 2430.3467 | K46: ='2'!M47 -> 1.4273465
B47: 12 | C47: BOLSA DE CORAZON PARA FLORES | F47: ='2'!N10 -> 1800 | G47: ='2'!N8 -> 0.32 | I47: ='2'!N46 -> 0.49853265 | J47: ='2'!N44 -> 897.35877 | K47: ='2'!N47 -> 1.8445708
B48: 13 | C48: BOLSA TRANSPARENTE PARA FLORES | F48: ='2'!O10 -> 1200 | G48: ='2'!O8 -> 0.49583333 | I48: ='2'!O46 -> 0.77246595 | J48: ='2'!O44 -> 926.95915 | K48: ='2'!O47 -> 2.858124
B49: 14 | C49: PORTA ROSAS DE CARTON | F49: ='2'!P10 -> 1550 | G49: ='2'!P8 -> 0.18 | I49: ='2'!P46 -> 0.28042462 | J49: ='2'!P44 -> 434.65815 | K49: ='2'!P47 -> 1.0375711
B50: TOTAL | F50: =SUM(F36:F49) -> 31535 | J50: =SUM(J36:J49) -> 21180.238
...

Sheet 2
B3: Calculo de Tributos
B5: Nombres | C5: PAPEL COREANO PARA ENVOLTURA DE FLORES | D5: CINTA DECORATIVA | E5: CINTA DECORATIVA SATINADA | F5: ENVOLTURA PARA RAMOS ONDULADO | G5: FLORES ARTIFICIALES DECORATIVAS | H5: BOLSA DECORATIVA PARA FLORES | I5: BOLSA DE REGALO CON CADENITA | J5: BOLSA CON LAZO PARA FLORES | K5: CAJA DECORATIVA PARA FLORES | L5: BOLSA DE DECORACION PARA FLORES | M5: BOLSA DE REGALO CON ASAS | N5: BOLSA DE CORAZON PARA FLORES | O5: BOLSA TRANSPARENTE PARA FLORES | P5: PORTA ROSAS DE CARTON | Q5: Total
B6: Peso | C6: 0 | D6: 0 | E6: 0 | F6: 0 | G6: 0 | H6: 0 | I6: 0 | J6: 0 | K6: 0 | L6: 0 | M6: 0 | N6: 0 | O6: 0 | P6: 0 | Q6: 3.09 | T6: Tipo Cliente | U6: Tarifa
B7: Valor CBM | C7: 0 | D7: 0 | E7: 0 | F7: 0 | G7: 0 | H7: 0 | I7: 0 | J7: 0 | K7: 0 | L7: 0 | M7: 0 | N7: 0 | O7: 0 | P7: 0 | Q7: 13.93 | T7: MANUAL | U7: 288.6145
B8: Valor Unitario | C8: 0.65 | D8: 0.8559727 | E8: 1.85 | F8: 0.5 | G8: 0.54 | H8: 0.35 | I8: 0.28 | J8: 0.29 | K8: 0.16 | L8: 0.29 | M8: 0.24761905 | N8: 0.32 | O8: 0.49583333 | P8: 0.18
B9: Valoracion | C9: 0 | D9: 0 | E9: 0 | F9: 0 | G9: 0 | H9: 0 | I9: 0 | J9: 0 | K9: 0 | L9: 0 | M9: 0 | N9: 0 | O9: 0 | P9: 0
B10: Cantidad | C10: 2200 | D10: 2930 | E10: 555 | F10: 1700 | G10: 4000 | H10: 1400 | I10: 2750 | J10: 1250 | K10: 1100 | L10: 2800 | M10: 6300 | N10: 1800 | O10: 1200 | P10: 1550 | Q10: =SUM(C10:P10) -> 31535
B11: Valor FOB | C11: =C8*C10 -> 1430 | D11: =D8*D10 -> 2508 | E11: =E8*E10 -> 1026.75 | F11: =F8*F10 -> 850 | G11: =G8*G10 -> 2160 | H11: =H8*H10 -> 490 | I11: =I8*I10 -> 770 | J11: =J8*J10 -> 362.5 | ... P11: =P8*P10 -> 279 | Q11: =SUM(C11:P11) -> 13595.25
B12: Valor FOB Valoracion | C12: =C10*C9 -> 0 | D12: =D10*D9 -> 0 | E12: =E10*E9 -> 0 | F12: =F10*F9 -> 0 | G12: =G10*G9 -> 0 | H12: =H10*H9 -> 0 | I12: =I10*I9 -> 0 | J12: =J10*J9 -> 0 | ... P12: =P10*P9 -> 0 | Q12: =SUM(C12:P12) -> 0
B13: Distribucion % | C13: =C11/Q11 -> 0.1051838 | D13: =D11/Q11 -> 0.1844762 | E13: =E11/Q11 -> 0.075522701 | F13: =F11/Q11 -> 0.062521837 | G13: =G11/Q11 -> 0.15887902 | H13: =H11/Q11 -> 0.036042 | I13: =I11/Q11 -> 0.056637429 | J13: =J11/Q11 -> 0.026663724 | K13: =K11/Q11 -> 0.012945698 | L13: =L11/Q11 -> 0.059726743 | M13: =M11/Q11 -> 0.11474596 | N13: =N11/Q11 -> 0.042367739 | O13: =O11/Q11 -> 0.043765286 | P13: =P11/Q11 -> 0.020521873
B14: Flete | C14: =Q14*C13 -> 253.72856 | D14: =Q14*D13 -> 445.00086 | E14: =Q14*E13 -> 182.17888 | F14: =Q14*F13 -> 150.81767 | G14: =Q14*G13 -> 383.25433 | H14: =Q14*H13 -> 86.941954 | I14: =Q14*I13 -> 136.62307 | J14: =Q14*J13 -> 64.319302 | K14: =Q14*K13 -> 31.22813 | L14: =Q14*L13 -> 144.07524 | M14: =Q14*M13 -> 276.79479 | N14: =Q14*N13 -> 102.20115 | O14: =Q14*O13 -> 105.57237 | P14: =Q14*P13 -> 49.503684 | Q14: =IF(Q7<1, U7*0.6, U7*0.6*Q7) -> 2412.24
B15: Valor CFR | C15: =C11+C14 -> 1683.7286 | D15: =D11+D14 -> 2953.0009 | E15: =E11+E14 -> 1208.9289 | F15: =F11+F14 -> 1000.8177 | G15: =G11+G14 -> 2543.2543 | H15: =H11+H14 -> 576.94195 | I15: =I11+I14 -> 906.62307 | J15: =J11+J14 -> 426.8193 | ... P15: =P11+P14 -> 328.50368 | Q15: =SUM(C15:P15) -> 16007.49
B16: CFR Valorizado | C16: =C12+C14 -> 253.72856 | D16: =D12+D14 -> 445.00086 | E16: =E12+E14 -> 182.17888 | F16: =F12+F14 -> 150.81767 | G16: =G12+G14 -> 383.25433 | H16: =H12+H14 -> 86.941954 | I16: =I12+I14 -> 136.62307 | J16: =J12+J14 -> 64.319302 | ... P16: =P12+P14 -> 49.503684 | Q16: =SUM(C16:P16) -> 2412.24
B17: Seguro | C17: =IF(Q11>5000,100*C13,50*C13) -> 10.51838 | D17: =IF(Q11>5000,100*D13,50*D13) -> 18.44762 | E17: =IF(Q11>5000,100*E13,50*E13) -> 7.5522701 | F17: =IF(Q11>5000,100*F13,50*F13) -> 6.2521837 | G17: =IF(Q11>5000,100*G13,50*G13) -> 15.887902 | H17: =IF(Q11>5000,100*H13,50*H13) -> 3.6042 | I17: =IF(Q11>5000,100*I13,50*I13) -> 5.6637429 | J17: =IF(Q11>5000,100*J13,50*J13) -> 2.6663724 | K17: =IF(Q11>5000,100*K13,50*K13) -> 1.2945698 | L17: =IF(Q11>5000,100*L13,50*L13) -> 5.9726743 | M17: =IF(Q11>5000,100*M13,50*M13) -> 11.474596 | N17: =IF(Q11>5000,100*N13,50*N13) -> 4.2367739 | O17: =IF(Q11>5000,100*O13,50*O13) -> 4.3765286 | P17: =IF(Q11>5000,100*P13,50*P13) -> 2.0521873 | Q17: =SUM(C17:P17) -> 100
B18: Valor CIF | C18: =C15+C17 -> 1694.2469 | D18: =D15+D17 -> 2971.4485 | E18: =E15+E17 -> 1216.4811 | F18: =F15+F17 -> 1007.0699 | G18: =G15+G17 -> 2559.1422 | H18: =H15+H17 -> 580.54615 | I18: =I15+I17 -> 912.28681 | J18: =J15+J17 -> 429.48567 | ... P18: =P15+P17 -> 330.55587 | Q18: =SUM(C18:P18) -> 16107.49
B19: CIF Valorizado | C19: =C16+C17 -> 264.24694 | D19: =D16+D17 -> 463.44848 | E19: =E16+E17 -> 189.73115 | F19: =F16+F17 -> 157.06986 | G19: =G16+G17 -> 399.14223 | H19: =H16+H17 -> 90.546154 | I19: =I16+I17 -> 142.28681 | J19: =J16+J17 -> 66.985675 | ... P19: =P16+P17 -> 51.555871 | Q19: =SUM(C19:P19) -> 2512.24
B23: Tributos Aplicables
B26: ANTIDUMPING | C26: 0 | D26: 0 | E26: 0 | F26: 0 | G26: 0 | H26: 0 | I26: 0 | J26: 0 | K26: 0 | L26: 0 | M26: 0 | N26: 0 | O26: 0 | P26: 0 | Q26: =SUM(C26:P26) -> 0
C27: 0 | D27: 0 | E27: 0 | F27: 0 | G27: 0 | H27: 0 | I27: 0 | J27: 0 | K27: 0 | L27: 0 | M27: 0 | N27: 0 | O27: 0 | P27: 0 | Q27: =SUM(C27:P27) -> 0
B28: AD VALOREM | C28: =MAX(C19,C18)*C27 -> 0 | D28: =MAX(D19,D18)*D27 -> 0 | E28: =MAX(E19,E18)*E27 -> 0 | F28: =MAX(F19,F18)*F27 -> 0 | G28: =MAX(G19,G18)*G27 -> 0 | H28: =MAX(H19,H18)*H27 -> 0 | I28: =MAX(I19,I18)*I27 -> 0 | J28: =MAX(J19,J18)*J27 -> 0 | ... P28: =MAX(P19,P18)*P27 -> 0 | Q28: =SUM(C28:P28) -> 0
B29: IGV | C29: =0.16*(MAX(C19,C18)+C28) -> 271.07951 | D29: =0.16*(MAX(D19,D18)+D28) -> 475.43176 | E29: =0.16*(MAX(E19,E18)+E28) -> 194.63698 | F29: =0.16*(MAX(F19,F18)+F28) -> 161.13118 | G29: =0.16*(MAX(G19,G18)+G28) -> 409.46276 | H29: =0.16*(MAX(H19,H18)+H28) -> 92.887385 | I29: =0.16*(MAX(I19,I18)+I28) -> 145.96589 | J29: =0.16*(MAX(J19,J18)+J28) -> 68.717708 | ... P29: =0.16*(MAX(P19,P18)+P28) -> 52.888939 | Q29: =SUM(C29:P29) -> 2577.1984
B30: IPM | C30: =0.02*(MAX(C19,C18)+C28) -> 33.884939 | D30: =0.02*(MAX(D19,D18)+D28) -> 59.42897 | E30: =0.02*(MAX(E19,E18)+E28) -> 24.329623 | F30: =0.02*(MAX(F19,F18)+F28) -> 20.141397 | G30: =0.02*(MAX(G19,G18)+G28) -> 51.182845 | H30: =0.02*(MAX(H19,H18)+H28) -> 11.610923 | I30: =0.02*(MAX(I19,I18)+I28) -> 18.245736 | J30: =0.02*(MAX(J19,J18)+J28) -> 8.5897135 | ... P30: =0.02*(MAX(P19,P18)+P28) -> 6.6111174 | Q30: =SUM(C30:P30) -> 322.1498
B31: PERCEPCION | C31: =0.035*(MAX(C18,C19) +C28+C29+C30) -> 69.972399 | D31: =0.035*(MAX(D18,D19) +D28+D29+D30) -> 122.72082 | E31: =0.035*(MAX(E18,E19) +E28+E29+E30) -> 50.240671 | F31: =0.035*(MAX(F18,F19) +F28+F29+F30) -> 41.591985 | G31: =0.035*(MAX(G18,G19) +G28+G29+G30) -> 105.69257 | H31: =0.035*(MAX(H18,H19) +H28+H29+H30) -> 23.976556 | I31: =0.035*(MAX(I18,I19) +I28+I29+I30) -> 37.677445 | J31: =0.035*(MAX(J18,J19) +J28+J29+J30) -> 17.737758 | ... P31: =0.035*(MAX(P18,P19) +P28+P29+P30) -> 13.651957 | Q31: =SUM(C31:P31) -> 665.23934
B32: TOTAL | C32: =SUM(C28:C31) -> 374.93685 | D32: =SUM(D28:D31) -> 657.58155 | E32: =SUM(E28:E31) -> 269.20728 | F32: =SUM(F28:F31) -> 222.86456 | G32: =SUM(G28:G31) -> 566.33818 | H32: =SUM(H28:H31) -> 128.47486 | I32: =SUM(I28:I31) -> 201.88907 | J32: =SUM(J28:J31) -> 95.04518 | ... Q32: =SUM(Q28:Q31) -> 3564.5875
B37: Costos Destinos
B40: ITEM | C40: =C13*Q40 -> 169.15237 | D40: =D13*Q40 -> 296.66724 | E40: =E13*Q40 -> 121.45259 | F40: =F13*Q40 -> 100.54512 | G40: =G13*Q40 -> 255.50288 | H40: =H13*Q40 -> 57.961302 | I40: =I13*Q40 -> 91.082047 | J40: =J13*Q40 -> 42.879535 | K40: =K13*Q40 -> 20.818754 | L40: =L13*Q40 -> 96.050158 | M40: =M13*Q40 -> 184.52986 | N40: =N13*Q40 -> 68.134102 | O40: =O13*Q40 -> 70.381582 | P40: =P13*Q40 -> 33.002456 | Q40: =IF(Q7<1, U7*0.4,U7*0.4*Q7) -> 1608.16
B43: ITEM | C43: PAPEL COREANO PARA ENVOLTURA DE FLORES | D43: CINTA DECORATIVA | E43: CINTA DECORATIVA SATINADA | F43: ENVOLTURA PARA RAMOS ONDULADO | G43: FLORES ARTIFICIALES DECORATIVAS | H43: BOLSA DECORATIVA PARA FLORES | I43: BOLSA DE REGALO CON CADENITA | J43: BOLSA CON LAZO PARA FLORES | K43: CAJA DECORATIVA PARA FLORES | L43: BOLSA DE DECORACION PARA FLORES | M43: BOLSA DE REGALO CON ASAS | N43: BOLSA DE CORAZON PARA FLORES | O43: BOLSA TRANSPARENTE PARA FLORES | P43: PORTA ROSAS DE CARTON | Q43: Total
B44: COSTO TOTAL | C44: =SUM(C15,C40,C32,(C26)) -> 2227.8178 | D44: =SUM(D15,D40,D32,(D26)) -> 3907.2496 | E44: =SUM(E15,E40,E32,(E26)) -> 1599.5887 | F44: =SUM(F15,F40,F32,(F26)) -> 1324.2274 | G44: =SUM(G15,G40,G32,(G26)) -> 3365.0954 | H44: =SUM(H15,H40,H32,(H26)) -> 763.37812 | I44: =SUM(I15,I40,I32,(I26)) -> 1199.5942 | J44: =SUM(J15,J40,J32,(J26)) -> 564.74402 | ... P44: =SUM(P15,P40,P32,(P26)) -> 434.65815 | Q44: =SUM(C44:P44) -> 21180.238
B45: CANTIDAD | C45: 2200 | D45: 2930 | E45: 555 | F45: 1700 | G45: 4000 | H45: 1400 | I45: 2750 | J45: 1250 | K45: 1100 | L45: 2800 | M45: 6300 | N45: 1800 | O45: 1200 | P45: 1550
B46: COSTO UNITARIO | C46: =SUM(C44/C45) -> 1.0126444 | D46: =SUM(D44/D45) -> 1.3335323 | E46: =SUM(E44/E45) -> 2.8821419 | F46: =SUM(F44/F45) -> 0.77895727 | G46: =SUM(G44/G45) -> 0.84127385 | H46: =SUM(H44/H45) -> 0.54527009 | I46: =SUM(I44/I45) -> 0.43621607 | J46: =SUM(J44/J45) -> 0.45179521 | ... P46: =SUM(P44/P45) -> 0.28042462
B47: COSTO SOLES | C47: =C46*3.7 -> 3.7467844 | D47: =D46*3.7 -> 4.9340695 | E47: =E46*3.7 -> 10.663925 | F47: =F46*3.7 -> 2.8821419 | G47: =G46*3.7 -> 3.1127132 | H47: =H46*3.7 -> 2.0174993 | I47: =I46*3.7 -> 1.6139995 | J47: =J46*3.7 -> 1.6716423 | ... P47: =P46*3.7 -> 1.0375711
