Workbook

Sheet 1
E3: PRO MUNDO COMEX S.A.C.
E4: RUC: 20612452432
E7: COTIZACION N002
B8: NOMBRE: | C8: Joan Jonathan | E8: SERVICIO: | F8: CARGA CONSOLIDADA | I8: N° CAJAS: | J8: =+'2'!F7 -> 8
B9: APELLIDO: | C9: Rosillo Juarez | E9: FECHA: | F9: =+TODAY() -> 46184 | I9: PESO: | J9: =+'2'!F8 -> 116
B10: DNI/RUC: | C10: 40828284 | E10: ORIGEN: | F10: CHINA | I10: QTY PROVEEDORES | J10: 0
B11: TELEFONO: | C11: 969094294 | E11: CLIENTE: | I11: VOLUMEN: | J11: =+'2'!F9 -> 1.188
B13: CALCULO DE BASE IMPONIBLE | K13: MONTO | L13: MONEDA
B14: VALOR DE CARGA | K14: ='2'!F13 -> 944.03 | L14: USD
B15: COSTOS FOB | L15: USD
B16: FLETE INTERNACIONAL + SEGURO | K16: ='2'!F16+'2'!F19 -> 299.48 | L16: USD
B17: VALOR CIF | K17: =SUM(K14:K16) -> 1243.51 | L17: USD
B19: CALCULO DE TRIBUTOS | J19: % | K19: MONTO | L19: MONEDA
B20: ADVALOREM | J20: =MAX('2'!C26:E26) -> 0.04 | K20: ='2'!F27 -> 33.510476 | L20: USD
B21: ISC | J21: 0 | K21: 0 | L21: USD
B22: IGV | J22: 0.16 | K22: ='2'!F29 -> 204.32328 | L22: USD
B23: IPM | J23: 0.02 | K23: ='2'!F30 -> 25.54041 | L23: USD
B24: SUB TOTAL | K24: =SUM(K20:K23) -> 263.37416 | L24: USD
B26: PERCEPCIÓN | J26: 3.5% | K26: ='2'!F31 -> 52.740946 | L26: USD
B27: TOTAL | K27: =K24+K26 -> 316.11511 | L27: USD
B29: CALCULO DE SERVICIO DE IMPORTACIÓN | J29: IGV | K29: MONTO | L29: MONEDA
B30: COSTOS FOB | J30: Gravado | L30: USD
B31: FLETE INTERNACIONAL | J31: No gravado | L31: USD
B32: COSTOS EN DESTINO | J32: Gravado | L32: USD
B33: SUB TOTAL | K33: =SUM(K30:K32) -> 0 | L33: USD
B35: RECARGOS OPERATIVOS ( QTY PROVEEDORES Y/O ITEMS) | K35: 0 | L35: USD
B36: DESCUENTO APLICABLE | K36: 0 | L36: USD
B37: TOTAL | K37: =SUM(K33+K35)-K36 -> 0 | L37: USD
B39: RESUMEN DE COTIZACIÓN | K39: MONTO | L39: MONEDA
B40: SERVICIO DE IMPORTACIÓN | K40: =K37 -> 0 | L40: USD
B41: IMPUESTOS | K41: =K27 -> 316.11511 | L41: USD
B42: SERVICIO DE MONTACARGA | K42: 0 | L42: USD
B43: SERVICIO DE ENVIO (ALMACEN-AGENCIA) | K43: 0 | L43: USD
B44: RECARGOS ADUANEROS (BQ O SANCIONES) | K44: 0 | L44: USD
B45: MONTO TOTAL | K45: =SUM(K40:K44) -> 316.11511 | L45: USD
B47: SIMULACIÓN DEL PRECIO PUESTO EN PERÚ POR PIEZA
B48: # ITEM | C48: NOMBRE PRODUCTO | F48: CANTIDAD | G48: COSTO UNI. | I48: PRECIO U. | J48: TOTAL | K48: PRECIO UNIT. (SOLES)
B49: 1 | C49: =+'2'!$C$6 -> Kids Car Seat Belt Pillow | F49: =+'2'!$C$46 -> 100 | G49: =+'2'!$C$10 -> 6.36 | I49: =+'2'!$C$47 -> 11.424506 | J49: =+F49*I49 -> 1142.4506 | K49: =I49*3.7 -> 42.270672
B50: TOTAL | F50: =+SUM(F49:F49) -> 100 | J50: =+SUM(J49:J49) -> 1142.4506
B53: NOTAS:
...

Sheet 2
B3: CALCULOS DE TRIBUTOS
B6: NOMBRE | C6: Kids Car Seat Belt Pillow | D6: Car Headrest | E6: Bluetooth sleep mask | F6: TOTAL
B7: CANTIDAD CAJONES | C7: 7 | E7: 1 | F7: =SUM(C7:E7) -> 8
B8: PESO (KG) | C8: 110 | E8: 6 | F8: =SUM(C8:E8) -> 116 | J8: NUEVO | M8: CLIENTE
B9: TOTAL CBM | C9: 1.154 | E9: 0.034 | F9: =SUM(C9:E9) -> 1.188 | J9: CBM | K9: TARIFA | M9: CBM | N9: TARIFA
B10: VALOR UNITARIO | C10: 6.36 | D10: 8.03 | E10: 6 | J10: 0.1 - 0.5 | K10: 250 | M10: 0.1 - 0.5 | N10: 250
B11: VALOR ZAPATILLAS | J11: 0.1 | M11: 0.1
B12: CANTIDAD | C12: 100 | D12: 1 | E12: 50 | F12: =SUM(C12:E12) -> 151 | J12: 0.6 - 1.0 | K12: 350 | M12: 0.6 - 1.0 | N12: 325
B13: VALOR FOB | C13: =C10*C12 -> 636 | D13: =D10*D12 -> 8.03 | E13: =E10*E12 -> 300 | F13: =SUM(C13:E13) -> 944.03 | J13: 1.1 - 2.0 | K13: 350 | M13: 1.1 - 2.0 | N13: 325
B14: VALOR FOB | C14: =(MAX(C10:C11))*C12 -> 636 | D14: =(MAX(D10:D11))*D12 -> 8.03 | E14: =(MAX(E10:E11))*E12 -> 300 | F14: =SUM(C14:E14) -> 944.03 | J14: 0.1 | M14: 0.1
B15: DISTRIBUCIÓN % | C15: =C13/$F$13 -> 0.6737074 | D15: =D13/$F$13 -> 0.0085060856 | E15: =E13/$F$13 -> 0.31778651 | F15: TOTAL | J15: 2.1 - 3.0 | K15: 325 | M15: 2.1 - 3.0 | N15: 300
B16: FLETE | C16: =$F$16*C15 -> 168.07652 | D16: =$F$16*D15 -> 2.1220982 | E16: =$F$16*E15 -> 79.281379 | F16: =+J25 -> 249.48 | J16: 3.1 - 4.0 | K16: 300 | M16: 3.1 - 4.0 | N16: 275
B17: VALOR CFR | C17: =C13+C16 -> 804.07652 | D17: =D13+D16 -> 10.152098 | E17: =E13+E16 -> 379.28138 | F17: =SUM(C17:E17) -> 1193.51 | J17: 4.1 + | K17: 280 | M17: 4.1 + | N17: 250
B18: CFR CALZADO | C18: =C14+C16 -> 804.07652 | D18: =D14+D16 -> 10.152098 | E18: =E14+E16 -> 379.28138 | F18: =SUM(C18:E18) -> 1193.51
B19: SEGURO | C19: =$F$19*C15 -> 33.68537 | D19: =$F$19*D15 -> 0.42530428 | E19: =$F$19*E15 -> 15.889326 | F19: =IF(F13<5000,50,100) -> 50
B20: VALOR CIF | C20: =C17+C19 -> 837.76189 | D20: =D17+D19 -> 10.577403 | E20: =E17+E19 -> 395.1707 | F20: =SUM(C20:E20) -> 1243.51 | J20: CBM | K20: COBRO
B21: CIF CALZADO | C21: =C18+C19 -> 837.76189 | F21: =SUM(C21:E21) -> 837.76189
J22: =+F9 -> 1.188 | K22: =J22*K13 -> 415.8
B23: TRIBUTOS APLICABLES
J24: FLETE (60%) | K24: DESTINO (40%)
J25: =K22*60% -> 249.48 | K25: =K22*40% -> 166.32
C26: 0.04 | D26: 0 | E26: 0 | F26: TOTAL
B27: AD VALOREM | C27: =C20*C26 -> 33.510476 | D27: =D20*D26 -> 0 | E27: =E20*E26 -> 0 | F27: =SUM(C27:E27) -> 33.510476
B28: ISC | C28: 0 | D28: =ROUND((MAX(D17:D18)+D26)*D27,10) -> 0 | F28: 0
B29: IGV 16% | C29: =((MAX(C20:C21))+C27)*16% -> 139.40358 | D29: =((MAX(D20:D21))+D27)*16% -> 1.6923844 | E29: =((MAX(E20:E21))+E27)*16% -> 63.227313 | F29: =SUM(C29:E29) -> 204.32328
B30: IPM 2% | C30: =((MAX(C20:C21))+C27)*2% -> 17.425447 | D30: =((MAX(D20:D21))+D27)*2% -> 0.21154805 | E30: =((MAX(E20:E21))+E27)*2% -> 7.9034141 | F30: =SUM(C30:E30) -> 25.54041
B31: PERCEPCIÓN 3.5% | C31: =(C20+C27+C29+C30)*3.5% -> 35.983549 | D31: =(D20+D27+D29+D30)*3.5% -> 0.43684672 | E31: =(E20+E27+E29+E30)*3.5% -> 16.32055 | F31: =SUM(C31:E31) -> 52.740946
B32: TOTAL | C32: =SUM(C27:C31) -> 226.32305 | D32: =SUM(D27:D31) -> 2.3407792 | E32: =SUM(E27:E31) -> 87.451277 | F32: =SUM(C32:E32) -> 316.11511 | J32: T. CAMBIO | K32: 3.7
B36: COSTOS DESTINOS
C38: =+C15 -> 0.6737074 | D38: =+D15 -> 0.0085060856 | E38: =+E15 -> 0.31778651 | F38: TOTAL
B39: ITEM | C39: =$F$39*C38 -> 112.05102 | D39: =$F$39*D38 -> 1.4147322 | E39: =$F$39*E38 -> 52.854253 | F39: =+K25 -> 166.32
B42: COSTO TOTAL DE IMPORTACIÓN
B44: ITEM | C44: =C6 -> Kids Car Seat Belt Pillow | D44: =D6 -> Car Headrest | E44: =E6 -> Bluetooth sleep mask
B45: COSTO TOTAL | C45: =C17+C32+C39 -> 1142.4506 | D45: =D17+D32+D39 -> 13.90761 | E45: =E17+E32+E39 -> 519.58691 | F45: =SUM(C45:E45) -> 1675.9451
B46: CANTIDAD | C46: =+C12 -> 100 | D46: =+D12 -> 1 | E46: =+E12 -> 50
B47: COSTO UNITARIO | C47: =C45/C46 -> 11.424506 | D47: =D45/D46 -> 13.90761 | E47: =E45/E46 -> 10.391738
B48: COSTO SOLES | C48: =C47*$K$32 -> 42.270672 | D48: =D47*$K$32 -> 51.458155 | E48: =E47*$K$32 -> 38.449431
