Workbook

Sheet 1
C3: PRO MUNDO COMEX S.A.C.
C5: RUC: 20612452432
D7: COTIZACION Nº20240000001
A8: NOMBRE: | D8: SERVICIO: | E8: CARGA CONSOLIDADA | H8: N° CAJAS: | I8: =+'2'!D5 -> 1
A9: DNI/RUC: | D9: FECHA: | E9: =+TODAY() -> 46253 | H9: PESO: | I9: =+'2'!D6 -> 23.2
A10: CORREO: | D10: ORIGEN: | E10: CHINA | H10: MEDIDA | I10: 0 | J10: 0 | K10: 0
A11: TELEFONO: | D11: CLIENTE: | H11: VOLUMEN: | I11: =+'2'!D8 -> 0.084
A13: CALCULO DE BASE IMPONIBLE | J13: MONTO | K13: MONEDA
A14: VALOR DE CARGA | J14: ='2'!D18 -> 1220 | K14: USD
A15: COSTOS FOB | J15: 0 | K15: USD
A16: FLETE INTERNACIONAL + SEGURO | J16: 0 | K16: USD
A17: VALOR CIF | J17: =SUM(J14:J16) -> 1220 | K17: USD
A19: CALCULO DE TRIBUTOS | I19: % | J19: MONTO | K19: MONEDA
A20: ADVALOREM | I20: =MAX('2'!C34:C34) -> 0 | J20: ='2'!D35 -> #REF! | K20: USD
A21: ISC | I21: 0 | J21: 0 | K21: USD
A22: IGV | I22: 0.16 | J22: ='2'!D38 -> #REF! | K22: USD
A23: IPM | I23: 0.02 | J23: ='2'!D39 -> #REF! | K23: USD
A24: ANTIDUMPING | I24: =MAX('2'!C31:C31) -> 0 | J24: ='2'!D32 -> 0 | K24: USD
A25: SUB TOTAL | J25: =SUM(J20:J24) -> #REF! | K25: USD
A27: PERCEPCIÓN | I27: 3.5% | J27: ='2'!D40 -> #REF! | K27: USD
A28: TOTAL | J28: =J25+J27 -> #REF! | K28: USD
A30: CALCULO DE SERVICIO DE IMPORTACIÓN | I30: IGV | J30: MONTO | K30: MONEDA
A31: COSTOS FOB | I31: Gravado | J31: 0 | K31: USD
A32: FLETE INTERNACIONAL | I32: No gravado | J32: 0 | K32: USD
A33: COSTOS EN DESTINO | I33: Gravado | J33: 0 | K33: USD
A34: SUB TOTAL | J34: =SUM(J31:J33) -> 0 | K34: USD
A36: RECARGOS OPERATIVOS ( QTY PROVEEDORES Y/O ITEMS) | J36: 0 | K36: USD
A37: DESCUENTO APLICABLE | J37: 0 | K37: USD
A38: TOTAL | J38: =SUM(J34+J36)-J37 -> 0 | K38: USD
A40: RESUMEN DE COTIZACIÓN | J40: MONTO | K40: MONEDA
A41: SERVICIO DE IMPORTACIÓN | J41: =J38 -> 0 | K41: USD
A42: IMPUESTOS | J42: =J28 -> #REF! | K42: USD
A43: MONTO TOTAL | J43: =SUM(J41:J42) -> #REF! | K43: USD | M43: RESUMEN DE COSTOS UNITARIOS
A45: SIMULACIÓN DEL PRECIO PUESTO EN PERÚ POR PIEZA | M45: # ITEM | N45: NOMBRE PRODUCTO | O45: VALOR CHINA USD | P45: VALOR PERU USD | Q45: VALOR PERU SOLES
A46: # ITEM | B46: NOMBRE PRODUCTO | E46: CANTIDAD | F46: COSTO UNI. | H46: PRECIO U. | I46: TOTAL | J46: PRECIO UNIT. (SOLES)
A47: TOTAL | E47: =+SUM(#REF!) -> #REF! | I47: =+SUM(#REF!) -> #REF!
M48: RESUMEN DE PAGOS DE SERVICIO DE IMPORTACIÓN
A49: NOTAS:
A50: *Las fechas brindadas son estimadas, estan sujetas a variación.
A51: *No se emite comprobante por concepto de "PERCEPCIÓN, ANTI DUMPING, GESTIÓN DE COMPRA" | M51: DESTINATARIO | O51: MONTO | R51: CONCEPTO
...

Sheet 2
B1: CALCULOS DE TRIBUTOS
D3: TOTALES
B4: N PROVEEDOR | C4: 1 | D4: =COUNT(C4:C4) -> 1
B5: N° CAJAS: | C5: 1 | D5: =SUM(C5:C5) -> 1
B6: PESO (KG) | C6: 23.2 | D6: =SUM(C6:C6) -> 23.2
B7: MEDIDA
B8: VOL. X PROVEEDOR | C8: 0.084 | D8: =SUM(C8:C8) -> 0.084
C10: 1
B11: NOMBRE | C11: BASE DE LAMPARA LED | D11: TOTAL
B12: CANTIDAD CAJONES | D12: =SUM(C12:C12) -> 0
B13: PESO (KG) | D13: =SUM(C13:C13) -> 0
B14: TOTAL CBM | D14: =SUM(C14:C14) -> 0
B15: VALOR UNITARIO | C15: 12.2
B16: VALOR ZAPATILLAS | G16: ='1'!E11 -> 0 | J16: 0.4
B17: CANTIDAD | C17: 100 | D17: =SUM(C17:C17) -> 100
B18: VALOR EXW | C18: =C15*C17 -> 1220 | D18: =SUM(C18:C18) -> 1220
B19: VALOR FOB | C19: =(MAX(C15:C16))*C17 -> 1220 | D19: =SUM(C19:C19) -> 1220
B20: DISTRIBUCIÓN % | C20: =C18/$D$18 -> 1 | D20: TOTAL
B21: COSTOS FOB | C21: 0 | D21: 0
B22: FLETE | C22: =$D$22*C20 -> #REF! | D22: =IF(#REF!=0,IF('1'!E11="NUEVO",'2'!#REF!*60%,IF('1'!E11="ANTIGUO",'2'!#REF!*60%,IF('1'!E11="SOCIO",60%*(250*'1'!I11),IF('1'!E11="PILOTO",60%*(250*'1'!I11),IF('2'!#REF!>0,60%*(250*'1'!I11),IF('1'!E11="MANUAL",60%*(IF('1'!#REF!>250,('1'!#REF!*'1'!I11),IF('1'!#REF!<=250,(250*'1'!I11)))))))))),IF(#REF!<=250,(250*'1'!I11)*60%,#REF!*60%)) -> #REF!
B23: VALOR CFR | C23: =C18+C22 -> #REF! | D23: =SUM(C23:C24) -> #REF!
B24: CFR CALZADO | C24: =C19+C22 -> #REF! | D24: =SUM(C24:C24) -> #REF!
B25: SEGURO | C25: =$D$25*C20 -> 50 | D25: =IF(D18<5000,50,100) -> 50
B26: VALOR CIF | C26: =C23+C25 -> #REF! | D26: =SUM(C26:C27) -> #REF!
B27: CIF CALZADO | C27: =C24+C25 -> #REF! | D27: =SUM(C27:C27) -> #REF!
B29: TRIBUTOS APLICABLES
B32: ANTIDUMPING | C32: =C17*C31 -> 0 | D32: =SUM(C32:C32) -> 0
C34: 0 | D34: TOTAL
B35: AD VALOREM | C35: =MAX(C26:C27)*C34 -> #REF! | D35: =SUM(C35:C35) -> #REF!
C36: 0 | D36: 0
B37: ISC | C37: =ROUND((MAX(C26:C27)+C35)*C36,10) -> #REF! | D37: =ROUND((MAX(D26:D27)+D35)*D36,10) -> #REF!
B38: IGV 16% | C38: =((MAX(C26:C27))+C35)*16% -> #REF! | D38: =SUM(C38:C38) -> #REF!
B39: IPM 2% | C39: =((MAX(C26:C27))+C35)*2% -> #REF! | D39: =SUM(C39:C39) -> #REF!
B40: PERCEPCIÓN 3.5% | C40: =(C26+C35+C38+C39)*3.5% -> #REF! | D40: =SUM(C40:C40) -> #REF!
B41: TOTAL | C41: =SUM(C35:C40) -> #REF! | D41: =SUM(C41:C41) -> #REF!
O43: TC | P43: 3.7
B45: COSTOS DESTINOS
C47: =+C20 -> 1 | D47: TOTAL
B48: ITEM | C48: =$D$48*C47 -> #REF! | D48: =IF(#REF!=0,IF('1'!E11="NUEVO",'2'!#REF!*40%,IF('1'!E11="ANTIGUO",'2'!#REF!*40%,IF('1'!E11="SOCIO",40%*(250*'1'!I11),IF('1'!E11="PILOTO",40%*(250*'1'!I11),IF('2'!#REF!>0,40%*(250*'1'!I11),IF('1'!E11="MANUAL",40%*(IF('1'!#REF!>250,('1'!#REF!*'1'!I11),IF('1'!#REF!<=250,(250*'1'!I11)))))))))),IF(#REF!<=250,(250*'1'!I11)*40%,#REF!*40%)) -> #REF!
B51: COSTO TOTAL DE IMPORTACIÓN
...
