Workbook

Sheet 1
E3: PRO MUNDO COMEX S.A.C.
E4: RUC: 20612452432
E7: COTIZACION N002
B8: NOMBRE: | C8: BRYAN RENZO QUILCA COAQUIRA | E8: SERVICIO: | F8: CARGA CONSOLIDADA | I8: N° CAJAS: | J8: =+'2'!F7 -> 0
B9: APELLIDO: | E9: FECHA: | F9: =+TODAY() -> 45969 | I9: PESO: | J9: 5.519 Tn
B10: DNI/RUC: | C10: 76632038 | E10: ORIGEN: | F10: CHINA | I10: MEDIDA:
B11: TELEFONO: | C11: 51 974 318 400 | E11: CLIENTE: | F11: MANUAL | I11: CBM | J11: ='2'!R7 -> 13.62
B13: CALCULO DE BASE IMPONIBLE | K13: MONTO | L13: MONEDA
B14: VALOR DE CARGA | K14: ='2'!R11 -> 33607.33 | L14: USD
B15: FLETE INTERNACIONAL + SEGURO | K15: ='2'!R14 + '2'!R17 -> 2581.5912 | L15: USD
B16: VALOR CIF | K16: =SUM(K14:K15) -> 36188.921 | L16: USD
B19: CALCULO DE TRIBUTOS | J19: % | K19: MONTO | L19: MONEDA
B20: ADVALOREM | J20: =MAX('2'!C27:P27) -> 0 | K20: ='2'!R28 -> 80.761224 | L20: USD | N20: Hola BRYAN RENZO QUILCA COAQUIRA 😁 un gusto saludarte! A continuación te envío la cotización final de tu importación📋📦. 🙋‍♂️ PAGO PENDIENTE : ☑️Costo CBM: $360.75996 ☑️Impuestos: $8107.24 ☑️ Total: $8467.99996 Pronto le aviso nuevos avances, que tengan buen día🚢 Último día de pago:
B21: IGV | J21: 0.16 | K21: ='2'!R29 -> 5803.1492 | L21: USD
B22: IPM | J22: 0.02 | K22: ='2'!R30 -> 725.39365 | L22: USD
B23: SUB TOTAL | K23: =SUM(K20:K22) -> 6609.3041 | L23: USD
B25: PERCEPCIÓN | J25: 3.5% | K25: ='2'!R31 -> 1497.9379 | L25: USD
B26: TOTAL | K26: =K23+K25 -> 8107.242 | L26: USD
B28: RESUMEN DE COTIZACIÓN | K28: MONTO | L28: MONEDA
B29: VALOR DE CARGA (PAGO AL PROVEEDOR) | K29: =K14 -> 33607.33 | L29: USD
B30: SERVICIO DE IMPORTACIÓN (ORIGEN -FLETE - DESTINO) | K30: =IF(J11<1, '2'!V7, '2'!V7*J11) -> 4135.9854 | L30: USD
B31: IMPUESTOS | K31: =K26 -> 8107.242 | L31: USD
B32: MONTO TOTAL | K32: =SUM(K29:K31) -> 45850.557 | L32: USD
B34: SIMULACIÓN DEL PRECIO PUESTO EN PERÚ POR PIEZA
B35: # ITEM | C35: NOMBRE PRODUCTO | F35: CANTIDAD | G35: COSTO UNI. | I35: PRECIO U. | J35: TOTAL | K35: PRECIO UNIT. (SOLES)
B36: 1 | C36: EXTRACTOR DE CABLE ELÉCTRICO DE ACERO | F36: ='2'!C10 -> 405 | G36: ='2'!C8 -> 5.35 | I36: ='2'!C46 -> 7.2833156 | J36: ='2'!C44 -> 2949.7428 | K36: ='2'!C47 -> 26.948268
B37: 2 | C37: PISTOLA DE IMPACTO NEUMATICA | F37: ='2'!D10 -> 300 | G37: ='2'!D8 -> 11.4 | I37: ='2'!D46 -> 15.519588 | J37: ='2'!D44 -> 4655.8765 | K37: ='2'!D47 -> 57.422477
B38: 3 | C38: DOBLADOR DE TUBO MANUAL | F38: ='2'!E10 -> 306 | G38: ='2'!E8 -> 4.08 | I38: ='2'!E46 -> 5.554379 | J38: ='2'!E44 -> 1699.64 | K38: ='2'!E47 -> 20.551202
B39: 4 | C39: LLAVE DE EXTENSIÓN TALADRO ELÉCTRICO | F39: ='2'!F10 -> 204 | G39: ='2'!F8 -> 19.1 | I39: ='2'!F46 -> 26.002117 | J39: ='2'!F44 -> 5304.432 | K39: ='2'!F47 -> 96.207835
B40: 5 | C40: PLANTILLA PARA BISAGRA DE ACERO | F40: ='2'!G10 -> 350 | G40: ='2'!G8 -> 8.25 | I40: ='2'!G46 -> 11.231281 | J40: ='2'!G44 -> 3930.9484 | K40: ='2'!G47 -> 41.55574
B41: 6 | C41: LLAVE DE EXTENSION UNIVERSAL | F41: ='2'!H10 -> 100 | G41: ='2'!H8 -> 3.8 | I41: ='2'!H46 -> 5.1731961 | J41: ='2'!H44 -> 517.31961 | K41: ='2'!H47 -> 19.140826
B42: 7 | C42: SET DE ABRIDORES DE AGUJEROS CON BROCAS | F42: ='2'!I10 -> 300 | G42: ='2'!I8 -> 14.5 | I42: ='2'!I46 -> 19.739827 | J42: ='2'!I44 -> 5921.9482 | K42: ='2'!I47 -> 73.037361
B43: 8 | C43: AFILADOR DE BROCAS ELECTRICO | F43: ='2'!J10 -> 300 | G43: ='2'!J8 -> 13.55 | I43: ='2'!J46 -> 18.446528 | J43: ='2'!J44 -> 5533.9585 | K43: ='2'!J47 -> 68.252155
B44: 9 | C44: TABLA DE ESMERILADO MANUAL | F44: ='2'!K10 -> 400 | G44: ='2'!K8 -> 4.75 | I44: ='2'!K46 -> 6.4664952 | J44: ='2'!K44 -> 2586.5981 | K44: ='2'!K47 -> 23.926032
B45: 10 | C45: LLAVE MULTIPLICADORA DE TORSION | F45: ='2'!L10 -> 200 | G45: ='2'!L8 -> 15.2 | I45: ='2'!L46 -> 20.692785 | J45: ='2'!L44 -> 4138.5569 | K45: ='2'!L47 -> 76.563303
B46: 11 | C46: REGLA PARA RECORTE DE MADERA | F46: ='2'!M10 -> 300 | G46: ='2'!M8 -> 6.55 | I46: ='2'!M46 -> 8.9169565 | J46: ='2'!M44 -> 2675.087 | K46: ='2'!M47 -> 32.992739
B47: 12 | C47: COMPRESOR DE PISTÓN DE FRENO DE DISCO | F47: ='2'!N10 -> 300 | G47: ='2'!N8 -> 3.65 | I47: ='2'!N46 -> 4.968991 | J47: ='2'!N44 -> 1490.6973 | K47: ='2'!N47 -> 18.385267
B48: 13 | C48: DESTORNILADOR CON PUNTAS INTERCAMBIABLES | F48: ='2'!O10 -> 288 | G48: ='2'!O8 -> 3.9 | I48: ='2'!O46 -> 5.3093329 | J48: ='2'!O44 -> 1529.0879 | K48: ='2'!O47 -> 19.644532
B49: 14 | C49: CORTADOR DE TUBOS AJUSTABLE | F49: ='2'!P10 -> 200 | G49: ='2'!P8 -> 4.1 | I49: ='2'!P46 -> 5.5816064 | J49: ='2'!P44 -> 1116.3213 | K49: ='2'!P47 -> 20.651944
B50: 15 | C50: PAPEL DE LIJA PARA TABLA ESMERILADO | F50: ='2'!Q10 -> 10000 | G50: ='2'!Q8 -> 0.125 | I50: ='2'!Q46 -> 0.18003429 | J50: ='2'!Q44 -> 1800.3429 | K50: ='2'!Q47 -> 0.66612689
...

Sheet 2
B3: Calculo de Tributos
B5: Nombres | C5: EXTRACTOR DE CABLE ELÉCTRICO DE ACERO | D5: PISTOLA DE IMPACTO NEUMATICA | E5: DOBLADOR DE TUBO MANUAL | F5: LLAVE DE EXTENSIÓN TALADRO ELÉCTRICO | G5: PLANTILLA PARA BISAGRA DE ACERO | H5: LLAVE DE EXTENSION UNIVERSAL | I5: SET DE ABRIDORES DE AGUJEROS CON BROCAS | J5: AFILADOR DE BROCAS ELECTRICO | K5: TABLA DE ESMERILADO MANUAL | L5: LLAVE MULTIPLICADORA DE TORSION | M5: REGLA PARA RECORTE DE MADERA | N5: COMPRESOR DE PISTÓN DE FRENO DE DISCO | O5: DESTORNILADOR CON PUNTAS INTERCAMBIABLES | P5: CORTADOR DE TUBOS AJUSTABLE | Q5: PAPEL DE LIJA PARA TABLA ESMERILADO | R5: Total
B6: Peso | C6: 0 | D6: 0 | E6: 0 | F6: 0 | G6: 0 | H6: 0 | I6: 0 | J6: 0 | K6: 0 | L6: 0 | M6: 0 | N6: 0 | O6: 0 | P6: 0 | Q6: 0 | R6: 5.52 | U6: Tipo Cliente | V6: Tarifa
B7: Valor CBM | C7: 0 | D7: 0 | E7: 0 | F7: 0 | G7: 0 | H7: 0 | I7: 0 | J7: 0 | K7: 0 | L7: 0 | M7: 0 | N7: 0 | O7: 0 | P7: 0 | Q7: 0 | R7: 13.62 | U7: MANUAL | V7: 303.67
B8: Valor Unitario | C8: 5.35 | D8: 11.4 | E8: 4.08 | F8: 19.1 | G8: 8.25 | H8: 3.8 | I8: 14.5 | J8: 13.55 | K8: 4.75 | L8: 15.2 | M8: 6.55 | N8: 3.65 | O8: 3.9 | P8: 4.1 | Q8: 0.125
B9: Valoracion | C9: 0 | D9: 0 | E9: 0 | F9: 0 | G9: 0 | H9: 0 | I9: 0 | J9: 0 | K9: 0 | L9: 0 | M9: 0 | N9: 0 | O9: 0 | P9: 0 | Q9: 0
B10: Cantidad | C10: 405 | D10: 300 | E10: 306 | F10: 204 | G10: 350 | H10: 100 | I10: 300 | J10: 300 | K10: 400 | L10: 200 | M10: 300 | N10: 300 | O10: 288 | P10: 200 | Q10: 10000 | R10: =SUM(C10:Q10) -> 13953
B11: Valor FOB | C11: =C8*C10 -> 2166.75 | D11: =D8*D10 -> 3420 | E11: =E8*E10 -> 1248.48 | F11: =F8*F10 -> 3896.4 | G11: =G8*G10 -> 2887.5 | H11: =H8*H10 -> 380 | I11: =I8*I10 -> 4350 | J11: =J8*J10 -> 4065 | ... Q11: =Q8*Q10 -> 1250 | R11: =SUM(C11:Q11) -> 33607.33
B12: Valor FOB Valoracion | C12: =C10*C9 -> 0 | D12: =D10*D9 -> 0 | E12: =E10*E9 -> 0 | F12: =F10*F9 -> 0 | G12: =G10*G9 -> 0 | H12: =H10*H9 -> 0 | I12: =I10*I9 -> 0 | J12: =J10*J9 -> 0 | ... Q12: =Q10*Q9 -> 0 | R12: =SUM(C12:Q12) -> 0
B13: Distribucion % | C13: =C11/R11 -> 0.064472542 | D13: =D11/R11 -> 0.10176351 | E13: =E11/R11 -> 0.037149039 | F13: =F11/R11 -> 0.11593899 | G13: =G11/R11 -> 0.085918756 | H13: =H11/R11 -> 0.011307057 | I13: =I11/R11 -> 0.12943605 | J13: =J11/R11 -> 0.12095576 | K13: =K11/R11 -> 0.056535286 | L13: =L11/R11 -> 0.090456457 | M13: =M11/R11 -> 0.058469387 | N13: =N11/R11 -> 0.032582178 | O13: =O11/R11 -> 0.03342128 | P13: =P11/R11 -> 0.024399439 | Q13: =Q11/R11 -> 0.037194267
B14: Flete | C14: =R14*C13 -> 159.9945 | D14: =R14*D13 -> 252.53545 | E14: =R14*E13 -> 92.188729 | F14: =R14*F13 -> 287.71319 | G14: =R14*G13 -> 213.21523 | H14: =R14*H13 -> 28.059494 | I14: =R14*I13 -> 321.20736 | J14: =R14*J13 -> 300.16274 | K14: =R14*K13 -> 140.29747 | L14: =R14*L13 -> 224.47595 | M14: =R14*M13 -> 145.09712 | N14: =R14*N13 -> 80.855647 | O14: =R14*O13 -> 82.937957 | P14: =R14*P13 -> 60.549434 | Q14: =R14*Q13 -> 92.300967 | R14: =IF(R7<1, V7*0.6, V7*0.6*R7) -> 2481.5912
B15: Valor CFR | C15: =C11+C14 -> 2326.7445 | D15: =D11+D14 -> 3672.5354 | E15: =E11+E14 -> 1340.6687 | F15: =F11+F14 -> 4184.1132 | G15: =G11+G14 -> 3100.7152 | H15: =H11+H14 -> 408.05949 | I15: =I11+I14 -> 4671.2074 | J15: =J11+J14 -> 4365.1627 | ... Q15: =Q11+Q14 -> 1342.301 | R15: =SUM(C15:Q15) -> 36088.921
B16: CFR Valorizado | C16: =C12+C14 -> 159.9945 | D16: =D12+D14 -> 252.53545 | E16: =E12+E14 -> 92.188729 | F16: =F12+F14 -> 287.71319 | G16: =G12+G14 -> 213.21523 | H16: =H12+H14 -> 28.059494 | I16: =I12+I14 -> 321.20736 | J16: =J12+J14 -> 300.16274 | ... Q16: =Q12+Q14 -> 92.300967 | R16: =SUM(C16:Q16) -> 2481.5912
B17: Seguro | C17: =IF(R11>5000,100*C13,50*C13) -> 6.4472542 | D17: =IF(R11>5000,100*D13,50*D13) -> 10.176351 | E17: =IF(R11>5000,100*E13,50*E13) -> 3.7149039 | F17: =IF(R11>5000,100*F13,50*F13) -> 11.593899 | G17: =IF(R11>5000,100*G13,50*G13) -> 8.5918756 | H17: =IF(R11>5000,100*H13,50*H13) -> 1.1307057 | I17: =IF(R11>5000,100*I13,50*I13) -> 12.943605 | J17: =IF(R11>5000,100*J13,50*J13) -> 12.095576 | K17: =IF(R11>5000,100*K13,50*K13) -> 5.6535286 | L17: =IF(R11>5000,100*L13,50*L13) -> 9.0456457 | M17: =IF(R11>5000,100*M13,50*M13) -> 5.8469387 | N17: =IF(R11>5000,100*N13,50*N13) -> 3.2582178 | O17: =IF(R11>5000,100*O13,50*O13) -> 3.342128 | P17: =IF(R11>5000,100*P13,50*P13) -> 2.4399439 | Q17: =IF(R11>5000,100*Q13,50*Q13) -> 3.7194267 | R17: =SUM(C17:Q17) -> 100
B18: Valor CIF | C18: =C15+C17 -> 2333.1918 | D18: =D15+D17 -> 3682.7118 | E18: =E15+E17 -> 1344.3836 | F18: =F15+F17 -> 4195.7071 | G18: =G15+G17 -> 3109.3071 | H18: =H15+H17 -> 409.1902 | I18: =I15+I17 -> 4684.151 | J18: =J15+J17 -> 4377.2583 | ... Q18: =Q15+Q17 -> 1346.0204 | R18: =SUM(C18:Q18) -> 36188.921
B19: CIF Valorizado | C19: =C16+C17 -> 166.44175 | D19: =D16+D17 -> 262.7118 | E19: =E16+E17 -> 95.903633 | F19: =F16+F17 -> 299.30709 | G19: =G16+G17 -> 221.80711 | H19: =H16+H17 -> 29.1902 | I19: =I16+I17 -> 334.15097 | J19: =J16+J17 -> 312.25832 | ... Q19: =Q16+Q17 -> 96.020393 | R19: =SUM(C19:Q19) -> 2581.5912
B23: Tributos Aplicables
B26: ANTIDUMPING | C26: 0 | D26: 0 | E26: 0 | F26: 0 | G26: 0 | H26: 0 | I26: 0 | J26: 0 | K26: 0 | L26: 0 | M26: 0 | N26: 0 | O26: 0 | P26: 0 | Q26: 0 | R26: =SUM(C26:Q26) -> 0
C27: 0 | D27: 0 | E27: 0 | F27: 0 | G27: 0 | H27: 0 | I27: 0 | J27: 0 | K27: 0 | L27: 0 | M27: 0 | N27: 0 | O27: 0 | P27: 0 | Q27: 0.06 | R27: =SUM(C27:Q27) -> 0.06
B28: AD VALOREM | C28: =MAX(C19,C18)*C27 -> 0 | D28: =MAX(D19,D18)*D27 -> 0 | E28: =MAX(E19,E18)*E27 -> 0 | F28: =MAX(F19,F18)*F27 -> 0 | G28: =MAX(G19,G18)*G27 -> 0 | H28: =MAX(H19,H18)*H27 -> 0 | I28: =MAX(I19,I18)*I27 -> 0 | J28: =MAX(J19,J18)*J27 -> 0 | ... Q28: =MAX(Q19,Q18)*Q27 -> 80.761224 | R28: =SUM(C28:Q28) -> 80.761224
B29: IGV | C29: =0.16*(MAX(C19,C18)+C28) -> 373.31068 | D29: =0.16*(MAX(D19,D18)+D28) -> 589.23389 | E29: =0.16*(MAX(E19,E18)+E28) -> 215.10138 | F29: =0.16*(MAX(F19,F18)+F28) -> 671.31313 | G29: =0.16*(MAX(G19,G18)+G28) -> 497.48914 | H29: =0.16*(MAX(H19,H18)+H28) -> 65.470432 | I29: =0.16*(MAX(I19,I18)+I28) -> 749.46416 | J29: =0.16*(MAX(J19,J18)+J28) -> 700.36133 | ... Q29: =0.16*(MAX(Q19,Q18)+Q28) -> 228.28506 | R29: =SUM(C29:Q29) -> 5803.1492
B30: IPM | C30: =0.02*(MAX(C19,C18)+C28) -> 46.663835 | D30: =0.02*(MAX(D19,D18)+D28) -> 73.654236 | E30: =0.02*(MAX(E19,E18)+E28) -> 26.887673 | F30: =0.02*(MAX(F19,F18)+F28) -> 83.914142 | G30: =0.02*(MAX(G19,G18)+G28) -> 62.186142 | H30: =0.02*(MAX(H19,H18)+H28) -> 8.183804 | I30: =0.02*(MAX(I19,I18)+I28) -> 93.683019 | J30: =0.02*(MAX(J19,J18)+J28) -> 87.545166 | ... Q30: =0.02*(MAX(Q19,Q18)+Q28) -> 28.535632 | R30: =SUM(C30:Q30) -> 725.39365
B31: PERCEPCION | C31: =0.035*(MAX(C18,C19) +C28+C29+C30) -> 96.360819 | D31: =0.035*(MAX(D18,D19) +D28+D29+D30) -> 152.096 | E31: =0.035*(MAX(E18,E19) +E28+E29+E30) -> 55.523044 | F31: =0.035*(MAX(F18,F19) +F28+F29+F30) -> 173.2827 | G31: =0.035*(MAX(G18,G19) +G28+G29+G30) -> 128.41438 | H31: =0.035*(MAX(H18,H19) +H28+H29+H30) -> 16.899555 | I31: =0.035*(MAX(I18,I19) +I28+I29+I30) -> 193.45544 | J31: =0.035*(MAX(J18,J19) +J28+J29+J30) -> 180.78077 | ... Q31: =0.035*(MAX(Q18,Q19) +Q28+Q29+Q30) -> 58.926081 | R31: =SUM(C31:Q31) -> 1497.9379
B32: TOTAL | C32: =SUM(C28:C31) -> 516.33533 | D32: =SUM(D28:D31) -> 814.98412 | E32: =SUM(E28:E31) -> 297.5121 | F32: =SUM(F28:F31) -> 928.50998 | G32: =SUM(G28:G31) -> 688.08966 | H32: =SUM(H28:H31) -> 90.553791 | I32: =SUM(I28:I31) -> 1036.6026 | J32: =SUM(J28:J31) -> 968.68727 | ... R32: =SUM(R28:R31) -> 8107.242
B37: Costos Destinos
B40: ITEM | C40: =C13*R40 -> 106.663 | D40: =D13*R40 -> 168.35696 | E40: =E13*R40 -> 61.459153 | F40: =F13*R40 -> 191.80879 | G40: =G13*R40 -> 142.14349 | H40: =H13*R40 -> 18.706329 | I40: =I13*R40 -> 214.13824 | J40: =J13*R40 -> 200.1085 | K40: =K13*R40 -> 93.531646 | L40: =L13*R40 -> 149.65063 | M40: =M13*R40 -> 96.731413 | N40: =N13*R40 -> 53.903765 | O40: =O13*R40 -> 55.291971 | P40: =P13*R40 -> 40.366289 | Q40: =Q13*R40 -> 61.533978 | R40: =IF(R7<1, V7*0.4,V7*0.4*R7) -> 1654.3942
B43: ITEM | C43: EXTRACTOR DE CABLE ELÉCTRICO DE ACERO | D43: PISTOLA DE IMPACTO NEUMATICA | E43: DOBLADOR DE TUBO MANUAL | F43: LLAVE DE EXTENSIÓN TALADRO ELÉCTRICO | G43: PLANTILLA PARA BISAGRA DE ACERO | H43: LLAVE DE EXTENSION UNIVERSAL | I43: SET DE ABRIDORES DE AGUJEROS CON BROCAS | J43: AFILADOR DE BROCAS ELECTRICO | K43: TABLA DE ESMERILADO MANUAL | L43: LLAVE MULTIPLICADORA DE TORSION | M43: REGLA PARA RECORTE DE MADERA | N43: COMPRESOR DE PISTÓN DE FRENO DE DISCO | O43: DESTORNILADOR CON PUNTAS INTERCAMBIABLES | P43: CORTADOR DE TUBOS AJUSTABLE | Q43: PAPEL DE LIJA PARA TABLA ESMERILADO | R43: Total
B44: COSTO TOTAL | C44: =SUM(C15,C40,C32,(C26)) -> 2949.7428 | D44: =SUM(D15,D40,D32,(D26)) -> 4655.8765 | E44: =SUM(E15,E40,E32,(E26)) -> 1699.64 | F44: =SUM(F15,F40,F32,(F26)) -> 5304.432 | G44: =SUM(G15,G40,G32,(G26)) -> 3930.9484 | H44: =SUM(H15,H40,H32,(H26)) -> 517.31961 | I44: =SUM(I15,I40,I32,(I26)) -> 5921.9482 | J44: =SUM(J15,J40,J32,(J26)) -> 5533.9585 | ... Q44: =SUM(Q15,Q40,Q32,(Q26)) -> 1800.3429 | R44: =SUM(C44:Q44) -> 45850.557
B45: CANTIDAD | C45: 405 | D45: 300 | E45: 306 | F45: 204 | G45: 350 | H45: 100 | I45: 300 | J45: 300 | K45: 400 | L45: 200 | M45: 300 | N45: 300 | O45: 288 | P45: 200 | Q45: 10000
B46: COSTO UNITARIO | C46: =SUM(C44/C45) -> 7.2833156 | D46: =SUM(D44/D45) -> 15.519588 | E46: =SUM(E44/E45) -> 5.554379 | F46: =SUM(F44/F45) -> 26.002117 | G46: =SUM(G44/G45) -> 11.231281 | H46: =SUM(H44/H45) -> 5.1731961 | I46: =SUM(I44/I45) -> 19.739827 | J46: =SUM(J44/J45) -> 18.446528 | ... Q46: =SUM(Q44/Q45) -> 0.18003429
B47: COSTO SOLES | C47: =C46*3.7 -> 26.948268 | D47: =D46*3.7 -> 57.422477 | E47: =E46*3.7 -> 20.551202 | F47: =F46*3.7 -> 96.207835 | G47: =G46*3.7 -> 41.55574 | H47: =H46*3.7 -> 19.140826 | I47: =I46*3.7 -> 73.037361 | J47: =J46*3.7 -> 68.252155 | ... Q47: =Q46*3.7 -> 0.66612689
