Workbook

Sheet 1
E3: PRO MUNDO COMEX S.A.C.
E4: RUC: 20612452432
E7: COTIZACION N002
B8: NOMBRE: | C8: JERRY PRADO PIÑAS | E8: SERVICIO: | F8: CARGA CONSOLIDADA | I8: N° CAJAS: | J8: =+'2'!F7 -> 0
B9: APELLIDO: | E9: FECHA: | F9: =+TODAY() -> 45969 | I9: PESO: | J9: 441.9 Kg
B10: DNI/RUC: | C10: 10716327499 | E10: ORIGEN: | F10: CHINA | I10: MEDIDA:
B11: TELEFONO: | C11: 51953354629 | E11: CLIENTE: | F11: NUEVO | I11: CBM | J11: ='2'!E7 -> 0.25
B13: CALCULO DE BASE IMPONIBLE | K13: MONTO | L13: MONEDA
B14: VALOR DE CARGA | K14: ='2'!E11 -> 4081.4 | L14: USD
B15: FLETE INTERNACIONAL + SEGURO | K15: ='2'!E14 + '2'!E17 -> 218 | L15: USD
B16: VALOR CIF | K16: =SUM(K14:K15) -> 4299.4 | L16: USD
B19: CALCULO DE TRIBUTOS | J19: % | K19: MONTO | L19: MONEDA
B20: ADVALOREM | J20: =MAX('2'!C27:C27) -> 0 | K20: ='2'!E28 -> 0 | L20: USD | N20: Hola JERRY PRADO PIÑAS 😁 un gusto saludarte! A continuación te envío la cotización final de tu importación📋📦. 🙋‍♂️ PAGO PENDIENTE : ☑️Costo CBM: $332.64 ☑️Impuestos: $951.46 ☑️ Total: $1284.1 Pronto le aviso nuevos avances, que tengan buen día🚢 Último día de pago:
B21: IGV | J21: 0.16 | K21: ='2'!E29 -> 687.904 | L21: USD
B22: IPM | J22: 0.02 | K22: ='2'!E30 -> 85.988 | L22: USD
B23: SUB TOTAL | K23: =SUM(K20:K22) -> 773.892 | L23: USD
B25: PERCEPCIÓN | J25: 3.5% | K25: ='2'!E31 -> 177.56522 | L25: USD
B26: TOTAL | K26: =K23+K25 -> 951.45722 | L26: USD
B28: RESUMEN DE COTIZACIÓN | K28: MONTO | L28: MONEDA
B29: VALOR DE CARGA (PAGO AL PROVEEDOR) | K29: =K14 -> 4081.4 | L29: USD
B30: SERVICIO DE IMPORTACIÓN (ORIGEN -FLETE - DESTINO) | K30: =IF(J11<1, '2'!I7, '2'!I7*J11) -> 280 | L30: USD
B31: IMPUESTOS | K31: =K26 -> 951.45722 | L31: USD
B32: MONTO TOTAL | K32: =SUM(K29:K31) -> 5312.8572 | L32: USD
B34: SIMULACIÓN DEL PRECIO PUESTO EN PERÚ POR PIEZA
B35: # ITEM | C35: NOMBRE PRODUCTO | F35: CANTIDAD | G35: COSTO UNI. | I35: PRECIO U. | J35: TOTAL | K35: PRECIO UNIT. (SOLES)
B36: 1 | C36: SOPORTE DE VIDRIO | F36: ='2'!C10 -> 3120 | G36: ='2'!C8 -> 1.22 | I36: ='2'!C46 -> 1.5881035 | J36: ='2'!C44 -> 4954.8831 | K36: ='2'!C47 -> 5.8759831
B37: 2 | C37: BOLA HUECA PARA PASAMANOS | F37: ='2'!D10 -> 500 | G37: ='2'!D8 -> 0.55 | I37: ='2'!D46 -> 0.71594832 | J37: ='2'!D44 -> 357.97416 | K37: ='2'!D47 -> 2.6490088
B38: TOTAL | F38: =SUM(F36:F37) -> 3620 | J38: =SUM(J36:J37) -> 5312.8572
B40: NOTAS:
B41: *Las fechas brindadas son estimadas, estan sujetas a variación.
B42: *No se emite comprobante por concepto de "PERCEPCIÓN, ANTI DUMPING, GESTIÓN DE COMPRA"
B43: *A nosotros se nos pagan los Gastos Logísticos + Impuestos una semana antes de que el contenedor
B44: llegue al puerto del Callao.
B45: *El tipo de cambio referencial usado para la conversión a soles es del 3.70
D48: PRO MUNDO COMEX S.A.C.
D49: RUC: 20612452432
B52: TÉRMINOS Y CONDICIONES:
B54: 1. Todos los pagos se realizan en dólares.
B55: 2.Todas las marcas de los productos deben ser verificadas por el cliente,
B56: No se aceptan marcas con medidas de frontera.
...

Sheet 2
B3: Calculo de Tributos
B5: Nombres | C5: SOPORTE DE VIDRIO | D5: BOLA HUECA PARA PASAMANOS | E5: Total
B6: Peso | C6: 0 | D6: 0 | E6: 441.9 | H6: Tipo Cliente | I6: Tarifa
B7: Valor CBM | C7: 0 | D7: 0 | E7: 0.25 | H7: NUEVO | I7: 280
B8: Valor Unitario | C8: 1.22 | D8: 0.55
B9: Valoracion | C9: 0 | D9: 0
B10: Cantidad | C10: 3120 | D10: 500 | E10: =SUM(C10:D10) -> 3620
B11: Valor FOB | C11: =C8*C10 -> 3806.4 | D11: =D8*D10 -> 275 | E11: =SUM(C11:D11) -> 4081.4
B12: Valor FOB Valoracion | C12: =C10*C9 -> 0 | D12: =D10*D9 -> 0 | E12: =SUM(C12:D12) -> 0
B13: Distribucion % | C13: =C11/E11 -> 0.93262116 | D13: =D11/E11 -> 0.067378841
B14: Flete | C14: =E14*C13 -> 156.68035 | D14: =E14*D13 -> 11.319645 | E14: =IF(E7<1, I7*0.6, I7*0.6*E7) -> 168
B15: Valor CFR | C15: =C11+C14 -> 3963.0804 | D15: =D11+D14 -> 286.31965 | E15: =SUM(C15:D15) -> 4249.4
B16: CFR Valorizado | C16: =C12+C14 -> 156.68035 | D16: =D12+D14 -> 11.319645 | E16: =SUM(C16:D16) -> 168
B17: Seguro | C17: =IF(E11>5000,100*C13,50*C13) -> 46.631058 | D17: =IF(E11>5000,100*D13,50*D13) -> 3.368942 | E17: =SUM(C17:D17) -> 50
B18: Valor CIF | C18: =C15+C17 -> 4009.7114 | D18: =D15+D17 -> 289.68859 | E18: =SUM(C18:D18) -> 4299.4
B19: CIF Valorizado | C19: =C16+C17 -> 203.31141 | D19: =D16+D17 -> 14.688587 | E19: =SUM(C19:D19) -> 218
B23: Tributos Aplicables
B26: ANTIDUMPING | C26: 0 | D26: 0 | E26: =SUM(C26:D26) -> 0
C27: 0 | D27: 0 | E27: =SUM(C27:D27) -> 0
B28: AD VALOREM | C28: =MAX(C19,C18)*C27 -> 0 | D28: =MAX(D19,D18)*D27 -> 0 | E28: =SUM(C28:D28) -> 0
B29: IGV | C29: =0.16*(MAX(C19,C18)+C28) -> 641.55383 | D29: =0.16*(MAX(D19,D18)+D28) -> 46.350174 | E29: =SUM(C29:D29) -> 687.904
B30: IPM | C30: =0.02*(MAX(C19,C18)+C28) -> 80.194228 | D30: =0.02*(MAX(D19,D18)+D28) -> 5.7937717 | E30: =SUM(C30:D30) -> 85.988
B31: PERCEPCION | C31: =0.035*(MAX(C18,C19) +C28+C29+C30) -> 165.60108 | D31: =0.035*(MAX(D18,D19) +D28+D29+D30) -> 11.964139 | E31: =SUM(C31:D31) -> 177.56522
B32: TOTAL | C32: =SUM(C28:C31) -> 887.34914 | D32: =SUM(D28:D31) -> 64.108084 | E32: =SUM(E28:E31) -> 951.45722
B37: Costos Destinos
B40: ITEM | C40: =C13*E40 -> 104.45357 | D40: =D13*E40 -> 7.5464301 | E40: =IF(E7<1, I7*0.4,I7*0.4*E7) -> 112
B43: ITEM | C43: SOPORTE DE VIDRIO | D43: BOLA HUECA PARA PASAMANOS | E43: Total
B44: COSTO TOTAL | C44: =SUM(C15,C40,C32,(C26)) -> 4954.8831 | D44: =SUM(D15,D40,D32,(D26)) -> 357.97416 | E44: =SUM(C44:D44) -> 5312.8572
B45: CANTIDAD | C45: 3120 | D45: 500
B46: COSTO UNITARIO | C46: =SUM(C44/C45) -> 1.5881035 | D46: =SUM(D44/D45) -> 0.71594832
B47: COSTO SOLES | C47: =C46*3.7 -> 5.8759831 | D47: =D46*3.7 -> 2.6490088
