Workbook

Sheet 1
E3: PRO MUNDO COMEX S.A.C.
E4: RUC: 20612452432
E7: COTIZACION N002
B8: NOMBRE: | C8: RUSSELL GILMER FONSECA RAYO | E8: SERVICIO: | F8: CARGA CONSOLIDADA | I8: N° CAJAS: | J8: =+'2'!F7 -> 0
B9: APELLIDO: | E9: FECHA: | F9: =+TODAY() -> 45969 | I9: PESO: | J9: 215.3 Kg
B10: DNI/RUC: | C10: 47574817 | E10: ORIGEN: | F10: CHINA | I10: MEDIDA:
B11: TELEFONO: | C11: 51 954 198 550 | E11: CLIENTE: | F11: MANUAL | I11: CBM | J11: ='2'!J7 -> 0.93
B13: CALCULO DE BASE IMPONIBLE | K13: MONTO | L13: MONEDA
B14: VALOR DE CARGA | K14: ='2'!J11 -> 2101.5 | L14: USD
B15: FLETE INTERNACIONAL + SEGURO | K15: ='2'!J14 + '2'!J17 -> 296 | L15: USD
B16: VALOR CIF | K16: =SUM(K14:K15) -> 2397.5 | L16: USD
B19: CALCULO DE TRIBUTOS | J19: % | K19: MONTO | L19: MONEDA
B20: ADVALOREM | J20: =MAX('2'!C27:H27) -> 0 | K20: ='2'!J28 -> 0 | L20: USD | N20: Hola RUSSELL GILMER FONSECA RAYO 😁 un gusto saludarte! A continuación te envío la cotización final de tu importación📋📦. 🙋‍♂️ PAGO PENDIENTE : ☑️Costo CBM: $487.08 ☑️Impuestos: $530.57 ☑️ Total: $1017.65 Pronto le aviso nuevos avances, que tengan buen día🚢 Último día de pago:
B21: IGV | J21: 0.16 | K21: ='2'!J29 -> 383.6 | L21: USD
B22: IPM | J22: 0.02 | K22: ='2'!J30 -> 47.95 | L22: USD
B23: SUB TOTAL | K23: =SUM(K20:K22) -> 431.55 | L23: USD
B25: PERCEPCIÓN | J25: 3.5% | K25: ='2'!J31 -> 99.01675 | L25: USD
B26: TOTAL | K26: =K23+K25 -> 530.56675 | L26: USD
B28: RESUMEN DE COTIZACIÓN | K28: MONTO | L28: MONEDA
B29: VALOR DE CARGA (PAGO AL PROVEEDOR) | K29: =K14 -> 2101.5 | L29: USD
B30: SERVICIO DE IMPORTACIÓN (ORIGEN -FLETE - DESTINO) | K30: =IF(J11<1, '2'!N7, '2'!N7*J11) -> 410 | L30: USD
B31: IMPUESTOS | K31: =K26 -> 530.56675 | L31: USD
B32: MONTO TOTAL | K32: =SUM(K29:K31) -> 3042.0667 | L32: USD
B34: SIMULACIÓN DEL PRECIO PUESTO EN PERÚ POR PIEZA
B35: # ITEM | C35: NOMBRE PRODUCTO | F35: CANTIDAD | G35: COSTO UNI. | I35: PRECIO U. | J35: TOTAL | K35: PRECIO UNIT. (SOLES)
B36: 1 | C36: SOMBRERO DE PESCADOR | F36: ='2'!C10 -> 150 | G36: ='2'!C8 -> 1.59 | I36: ='2'!C46 -> 2.3016351 | J36: ='2'!C44 -> 345.24526 | K36: ='2'!C47 -> 8.5160498
B37: 2 | C37: PASAMONTAÑAS | F37: ='2'!D10 -> 75 | G37: ='2'!D8 -> 1 | I37: ='2'!D46 -> 1.4475692 | J37: ='2'!D44 -> 108.56769 | K37: ='2'!D47 -> 5.3560062
B38: 3 | C38: CUBRIDOR DE BOCAS | F38: ='2'!E10 -> 100 | G38: ='2'!E8 -> 0.8 | I38: ='2'!E46 -> 1.1580554 | J38: ='2'!E44 -> 115.80554 | K38: ='2'!E47 -> 4.2848049
B39: 4 | C39: ESTUCHE PARA ESPOSAS | F39: ='2'!F10 -> 100 | G39: ='2'!F8 -> 2.6 | I39: ='2'!F46 -> 3.76368 | J39: ='2'!F44 -> 376.368 | K39: ='2'!F47 -> 13.925616
B40: 5 | C40: JUEGO DE RODILLERAS Y CODERAS | F40: ='2'!G10 -> 250 | G40: ='2'!G8 -> 2.9 | I40: ='2'!G46 -> 4.1979508 | J40: ='2'!G44 -> 1049.4877 | K40: ='2'!G47 -> 15.532418
B41: 6 | C41: CORREA AJUSTABLE TACTICA | F41: ='2'!H10 -> 400 | G41: ='2'!H8 -> 1.2125 | I41: ='2'!H46 -> 1.7551777 | J41: ='2'!H44 -> 702.07108 | K41: ='2'!H47 -> 6.4941575
B42: 7 | C42: GORRO TACTICO MILITAR | F42: ='2'!I10 -> 140 | G42: ='2'!I8 -> 1.7 | I42: ='2'!I46 -> 2.4608677 | J42: ='2'!I44 -> 344.52148 | K42: ='2'!I47 -> 9.1052105
B43: TOTAL | F43: =SUM(F36:F42) -> 1215 | J43: =SUM(J36:J42) -> 3042.0667
B44: NOTAS:
B45: *Las fechas brindadas son estimadas, estan sujetas a variación.
B46: *No se emite comprobante por concepto de "PERCEPCIÓN, ANTI DUMPING, GESTIÓN DE COMPRA"
B47: *A nosotros se nos pagan los Gastos Logísticos + Impuestos una semana antes de que el contenedor
B48: llegue al puerto del Callao.
B49: *El tipo de cambio referencial usado para la conversión a soles es del 3.70
D52: PRO MUNDO COMEX S.A.C.
...

Sheet 2
B3: Calculo de Tributos
B5: Nombres | C5: SOMBRERO DE PESCADOR | D5: PASAMONTAÑAS | E5: CUBRIDOR DE BOCAS | F5: ESTUCHE PARA ESPOSAS | G5: JUEGO DE RODILLERAS Y CODERAS | H5: CORREA AJUSTABLE TACTICA | I5: GORRO TACTICO MILITAR | J5: Total
B6: Peso | C6: 0 | D6: 0 | E6: 0 | F6: 0 | G6: 0 | H6: 0 | I6: 0 | J6: 215.3 | M6: Tipo Cliente | N6: Tarifa
B7: Valor CBM | C7: 0 | D7: 0 | E7: 0 | F7: 0 | G7: 0 | H7: 0 | I7: 0 | J7: 0.93 | M7: MANUAL | N7: 410
B8: Valor Unitario | C8: 1.59 | D8: 1 | E8: 0.8 | F8: 2.6 | G8: 2.9 | H8: 1.2125 | I8: 1.7
B9: Valoracion | C9: 0 | D9: 0 | E9: 0 | F9: 0 | G9: 0 | H9: 0 | I9: 0
B10: Cantidad | C10: 150 | D10: 75 | E10: 100 | F10: 100 | G10: 250 | H10: 400 | I10: 140 | J10: =SUM(C10:I10) -> 1215
B11: Valor FOB | C11: =C8*C10 -> 238.5 | D11: =D8*D10 -> 75 | E11: =E8*E10 -> 80 | F11: =F8*F10 -> 260 | G11: =G8*G10 -> 725 | H11: =H8*H10 -> 485 | I11: =I8*I10 -> 238 | J11: =SUM(C11:I11) -> 2101.5
B12: Valor FOB Valoracion | C12: =C10*C9 -> 0 | D12: =D10*D9 -> 0 | E12: =E10*E9 -> 0 | F12: =F10*F9 -> 0 | G12: =G10*G9 -> 0 | H12: =H10*H9 -> 0 | I12: =I10*I9 -> 0 | J12: =SUM(C12:I12) -> 0
B13: Distribucion % | C13: =C11/J11 -> 0.11349036 | D13: =D11/J11 -> 0.035688794 | E13: =E11/J11 -> 0.038068047 | F13: =F11/J11 -> 0.12372115 | G13: =G11/J11 -> 0.34499167 | H13: =H11/J11 -> 0.23078753 | I13: =I11/J11 -> 0.11325244
B14: Flete | C14: =J14*C13 -> 27.91863 | D14: =J14*D13 -> 8.7794433 | E14: =J14*E13 -> 9.3647395 | F14: =J14*F13 -> 30.435403 | G14: =J14*G13 -> 84.867951 | H14: =J14*H13 -> 56.773733 | I14: =J14*I13 -> 27.8601 | J14: =IF(J7<1, N7*0.6, N7*0.6*J7) -> 246
B15: Valor CFR | C15: =C11+C14 -> 266.41863 | D15: =D11+D14 -> 83.779443 | E15: =E11+E14 -> 89.364739 | F15: =F11+F14 -> 290.4354 | G15: =G11+G14 -> 809.86795 | H15: =H11+H14 -> 541.77373 | I15: =I11+I14 -> 265.8601 | J15: =SUM(C15:I15) -> 2347.5
B16: CFR Valorizado | C16: =C12+C14 -> 27.91863 | D16: =D12+D14 -> 8.7794433 | E16: =E12+E14 -> 9.3647395 | F16: =F12+F14 -> 30.435403 | G16: =G12+G14 -> 84.867951 | H16: =H12+H14 -> 56.773733 | I16: =I12+I14 -> 27.8601 | J16: =SUM(C16:I16) -> 246
B17: Seguro | C17: =IF(J11>5000,100*C13,50*C13) -> 5.6745182 | D17: =IF(J11>5000,100*D13,50*D13) -> 1.7844397 | E17: =IF(J11>5000,100*E13,50*E13) -> 1.9034023 | F17: =IF(J11>5000,100*F13,50*F13) -> 6.1860576 | G17: =IF(J11>5000,100*G13,50*G13) -> 17.249584 | H17: =IF(J11>5000,100*H13,50*H13) -> 11.539377 | I17: =IF(J11>5000,100*I13,50*I13) -> 5.6626219 | J17: =SUM(C17:I17) -> 50
B18: Valor CIF | C18: =C15+C17 -> 272.09315 | D18: =D15+D17 -> 85.563883 | E18: =E15+E17 -> 91.268142 | F18: =F15+F17 -> 296.62146 | G18: =G15+G17 -> 827.11754 | H18: =H15+H17 -> 553.31311 | I18: =I15+I17 -> 271.52272 | J18: =SUM(C18:I18) -> 2397.5
B19: CIF Valorizado | C19: =C16+C17 -> 33.593148 | D19: =D16+D17 -> 10.563883 | E19: =E16+E17 -> 11.268142 | F19: =F16+F17 -> 36.621461 | G19: =G16+G17 -> 102.11754 | H19: =H16+H17 -> 68.31311 | I19: =I16+I17 -> 33.522722 | J19: =SUM(C19:I19) -> 296
B23: Tributos Aplicables
B26: ANTIDUMPING | C26: 0 | D26: 0 | E26: 0 | F26: 0 | G26: 0 | H26: 0 | I26: 0 | J26: =SUM(C26:I26) -> 0
C27: 0 | D27: 0 | E27: 0 | F27: 0 | G27: 0 | H27: 0 | I27: 0 | J27: =SUM(C27:I27) -> 0
B28: AD VALOREM | C28: =MAX(C19,C18)*C27 -> 0 | D28: =MAX(D19,D18)*D27 -> 0 | E28: =MAX(E19,E18)*E27 -> 0 | F28: =MAX(F19,F18)*F27 -> 0 | G28: =MAX(G19,G18)*G27 -> 0 | H28: =MAX(H19,H18)*H27 -> 0 | I28: =MAX(I19,I18)*I27 -> 0 | J28: =SUM(C28:I28) -> 0
B29: IGV | C29: =0.16*(MAX(C19,C18)+C28) -> 43.534904 | D29: =0.16*(MAX(D19,D18)+D28) -> 13.690221 | E29: =0.16*(MAX(E19,E18)+E28) -> 14.602903 | F29: =0.16*(MAX(F19,F18)+F28) -> 47.459434 | G29: =0.16*(MAX(G19,G18)+G28) -> 132.33881 | H29: =0.16*(MAX(H19,H18)+H28) -> 88.530098 | I29: =0.16*(MAX(I19,I18)+I28) -> 43.443635 | J29: =SUM(C29:I29) -> 383.6
B30: IPM | C30: =0.02*(MAX(C19,C18)+C28) -> 5.441863 | D30: =0.02*(MAX(D19,D18)+D28) -> 1.7112777 | E30: =0.02*(MAX(E19,E18)+E28) -> 1.8253628 | F30: =0.02*(MAX(F19,F18)+F28) -> 5.9324292 | G30: =0.02*(MAX(G19,G18)+G28) -> 16.542351 | H30: =0.02*(MAX(H19,H18)+H28) -> 11.066262 | I30: =0.02*(MAX(I19,I18)+I28) -> 5.4304544 | J30: =SUM(C30:I30) -> 47.95
B31: PERCEPCION | C31: =0.035*(MAX(C18,C19) +C28+C29+C30) -> 11.237447 | D31: =0.035*(MAX(D18,D19) +D28+D29+D30) -> 3.5337884 | E31: =0.035*(MAX(E18,E19) +E28+E29+E30) -> 3.7693743 | F31: =0.035*(MAX(F18,F19) +F28+F29+F30) -> 12.250466 | G31: =0.035*(MAX(G18,G19) +G28+G29+G30) -> 34.159954 | H31: =0.035*(MAX(H18,H19) +H28+H29+H30) -> 22.851831 | I31: =0.035*(MAX(I18,I19) +I28+I29+I30) -> 11.213888 | J31: =SUM(C31:I31) -> 99.01675
B32: TOTAL | C32: =SUM(C28:C31) -> 60.214214 | D32: =SUM(D28:D31) -> 18.935287 | E32: =SUM(E28:E31) -> 20.19764 | F32: =SUM(F28:F31) -> 65.642329 | G32: =SUM(G28:G31) -> 183.04111 | H32: =SUM(H28:H31) -> 122.44819 | I32: =SUM(I28:I31) -> 60.087978 | J32: =SUM(J28:J31) -> 530.56675
B37: Costos Destinos
B40: ITEM | C40: =C13*J40 -> 18.61242 | D40: =D13*J40 -> 5.8529622 | E40: =E13*J40 -> 6.2431596 | F40: =F13*J40 -> 20.290269 | G40: =G13*J40 -> 56.578634 | H40: =H13*J40 -> 37.849155 | I40: =I13*J40 -> 18.5734 | J40: =IF(J7<1, N7*0.4,N7*0.4*J7) -> 164
B43: ITEM | C43: SOMBRERO DE PESCADOR | D43: PASAMONTAÑAS | E43: CUBRIDOR DE BOCAS | F43: ESTUCHE PARA ESPOSAS | G43: JUEGO DE RODILLERAS Y CODERAS | H43: CORREA AJUSTABLE TACTICA | I43: GORRO TACTICO MILITAR | J43: Total
B44: COSTO TOTAL | C44: =SUM(C15,C40,C32,(C26)) -> 345.24526 | D44: =SUM(D15,D40,D32,(D26)) -> 108.56769 | E44: =SUM(E15,E40,E32,(E26)) -> 115.80554 | F44: =SUM(F15,F40,F32,(F26)) -> 376.368 | G44: =SUM(G15,G40,G32,(G26)) -> 1049.4877 | H44: =SUM(H15,H40,H32,(H26)) -> 702.07108 | I44: =SUM(I15,I40,I32,(I26)) -> 344.52148 | J44: =SUM(C44:I44) -> 3042.0667
B45: CANTIDAD | C45: 150 | D45: 75 | E45: 100 | F45: 100 | G45: 250 | H45: 400 | I45: 140
B46: COSTO UNITARIO | C46: =SUM(C44/C45) -> 2.3016351 | D46: =SUM(D44/D45) -> 1.4475692 | E46: =SUM(E44/E45) -> 1.1580554 | F46: =SUM(F44/F45) -> 3.76368 | G46: =SUM(G44/G45) -> 4.1979508 | H46: =SUM(H44/H45) -> 1.7551777 | I46: =SUM(I44/I45) -> 2.4608677
B47: COSTO SOLES | C47: =C46*3.7 -> 8.5160498 | D47: =D46*3.7 -> 5.3560062 | E47: =E46*3.7 -> 4.2848049 | F47: =F46*3.7 -> 13.925616 | G47: =G46*3.7 -> 15.532418 | H47: =H46*3.7 -> 6.4941575 | I47: =I46*3.7 -> 9.1052105
