Workbook

Sheet 1
E3: PRO MUNDO COMEX S.A.C.
E4: RUC: 20612452432
E7: COTIZACION N002
B8: NOMBRE: | C8: CELIA ROSA CEDAMANOS VARELA | E8: SERVICIO: | F8: CARGA CONSOLIDADA | I8: N° CAJAS: | J8: =+'2'!F7 -> 0
B9: APELLIDO: | E9: FECHA: | F9: =+TODAY() -> 45971 | I9: PESO: | J9: 40 Kg
B10: DNI/RUC: | C10: 18008095 | E10: ORIGEN: | F10: CHINA | I10: MEDIDA:
B11: TELEFONO: | C11: 51 999 699 816 | E11: CLIENTE: | F11: NUEVO | I11: CBM | J11: ='2'!H7 -> 0.94
B13: CALCULO DE BASE IMPONIBLE | K13: MONTO | L13: MONEDA
B14: VALOR DE CARGA | K14: ='2'!H11 -> 797 | L14: USD
B15: FLETE INTERNACIONAL + SEGURO | K15: ='2'!H14 + '2'!H17 -> 275 | L15: USD
B16: VALOR CIF | K16: =SUM(K14:K15) -> 1072 | L16: USD
B19: CALCULO DE TRIBUTOS | J19: % | K19: MONTO | L19: MONEDA
B20: ADVALOREM | J20: =MAX('2'!C27:F27) -> 0.06 | K20: ='2'!H28 -> 5.084266 | L20: USD | N20: Hola CELIA ROSA CEDAMANOS VARELA 😁 un gusto saludarte! A continuación te envío la cotización final de tu importación📋📦. 🙋‍♂️ PAGO PENDIENTE : ☑️Costo CBM: $445.5 ☑️Impuestos: $243.44 ☑️ Total: $688.94 Pronto le aviso nuevos avances, que tengan buen día🚢 Último día de pago:
B21: IGV | J21: 0.16 | K21: ='2'!H29 -> 172.33348 | L21: USD
B22: IPM | J22: 0.02 | K22: ='2'!H30 -> 21.541685 | L22: USD
B23: SUB TOTAL | K23: =SUM(K20:K22) -> 198.95943 | L23: USD
B25: PERCEPCIÓN | J25: 3.5% | K25: ='2'!H31 -> 44.48358 | L25: USD
B26: TOTAL | K26: =K23+K25 -> 243.44301 | L26: USD
B28: RESUMEN DE COTIZACIÓN | K28: MONTO | L28: MONEDA
B29: VALOR DE CARGA (PAGO AL PROVEEDOR) | K29: =K14 -> 797 | L29: USD
B30: SERVICIO DE IMPORTACIÓN (ORIGEN -FLETE - DESTINO) | K30: =IF(J11<1, '2'!L7, '2'!L7*J11) -> 375 | L30: USD
B31: IMPUESTOS | K31: =K26 -> 243.44301 | L31: USD
B32: MONTO TOTAL | K32: =SUM(K29:K31) -> 1415.443 | L32: USD
B34: SIMULACIÓN DEL PRECIO PUESTO EN PERÚ POR PIEZA
B35: # ITEM | C35: NOMBRE PRODUCTO | F35: CANTIDAD | G35: COSTO UNI. | I35: PRECIO U. | J35: TOTAL | K35: PRECIO UNIT. (SOLES)
B36: 1 | C36: FREIDORA DE AIRE DE 10L | F36: ='2'!C10 -> 10 | G36: ='2'!C8 -> 14.8 | I36: ='2'!C46 -> 26.168955 | J36: ='2'!C44 -> 261.68955 | K36: ='2'!C47 -> 96.825134
B37: 2 | C37: LICUADORA 2 EN 1 BATIDORA | F37: ='2'!D10 -> 2 | G37: ='2'!D8 -> 7.5 | I37: ='2'!D46 -> 14.000511 | J37: ='2'!D44 -> 28.001022 | K37: ='2'!D47 -> 51.80189
B38: 3 | C38: FREIDORA DE AIRE DE 15L | F38: ='2'!E10 -> 6 | G38: ='2'!E8 -> 20.5 | I38: ='2'!E46 -> 36.247539 | J38: ='2'!E44 -> 217.48524 | K38: ='2'!E47 -> 134.1159
B39: 4 | C39: ARBOL SENTETICO NAVIDEÑO | F39: ='2'!F10 -> 2 | G39: ='2'!F8 -> 24 | I39: ='2'!F46 -> 44.801635 | J39: ='2'!F44 -> 89.603269 | K39: ='2'!F47 -> 165.76605
B40: 5 | C40: SET DE CUBIERTOS | F40: ='2'!G10 -> 300 | G40: ='2'!G8 -> 1.5433333 | I40: ='2'!G46 -> 2.7288798 | J40: ='2'!G44 -> 818.66394 | K40: ='2'!G47 -> 10.096855
B41: TOTAL | F41: =SUM(F36:F40) -> 320 | J41: =SUM(J36:J40) -> 1415.443
B42: NOTAS:
B43: *Las fechas brindadas son estimadas, estan sujetas a variación.
B44: *No se emite comprobante por concepto de "PERCEPCIÓN, ANTI DUMPING, GESTIÓN DE COMPRA"
B45: *A nosotros se nos pagan los Gastos Logísticos + Impuestos una semana antes de que el contenedor
B46: llegue al puerto del Callao.
B47: *El tipo de cambio referencial usado para la conversión a soles es del 3.70
D50: PRO MUNDO COMEX S.A.C.
D51: RUC: 20612452432
B54: TÉRMINOS Y CONDICIONES:
...

Sheet 2
B3: Calculo de Tributos
B5: Nombres | C5: FREIDORA DE AIRE DE 10L | D5: LICUADORA 2 EN 1 BATIDORA | E5: FREIDORA DE AIRE DE 15L | F5: ARBOL SENTETICO NAVIDEÑO | G5: SET DE CUBIERTOS | H5: Total
B6: Peso | C6: 0 | D6: 0 | E6: 0 | F6: 0 | G6: 0 | H6: 40 | K6: Tipo Cliente | L6: Tarifa
B7: Valor CBM | C7: 0 | D7: 0 | E7: 0 | F7: 0 | G7: 0 | H7: 0.94 | K7: NUEVO | L7: 375
B8: Valor Unitario | C8: 14.8 | D8: 7.5 | E8: 20.5 | F8: 24 | G8: 1.5433333
B9: Valoracion | C9: 0 | D9: 0 | E9: 0 | F9: 0 | G9: 0
B10: Cantidad | C10: 10 | D10: 2 | E10: 6 | F10: 2 | G10: 300 | H10: =SUM(C10:G10) -> 320
B11: Valor FOB | C11: =C8*C10 -> 148 | D11: =D8*D10 -> 15 | E11: =E8*E10 -> 123 | F11: =F8*F10 -> 48 | G11: =G8*G10 -> 463 | H11: =SUM(C11:G11) -> 797
B12: Valor FOB Valoracion | C12: =C10*C9 -> 0 | D12: =D10*D9 -> 0 | E12: =E10*E9 -> 0 | F12: =F10*F9 -> 0 | G12: =G10*G9 -> 0 | H12: =SUM(C12:G12) -> 0
B13: Distribucion % | C13: =C11/H11 -> 0.18569636 | D13: =D11/H11 -> 0.018820577 | E13: =E11/H11 -> 0.15432873 | F13: =F11/H11 -> 0.060225847 | G13: =G11/H11 -> 0.58092848
B14: Flete | C14: =H14*C13 -> 41.781681 | D14: =H14*D13 -> 4.2346299 | E14: =H14*E13 -> 34.723965 | F14: =H14*F13 -> 13.550816 | G14: =H14*G13 -> 130.70891 | H14: =IF(H7<1, L7*0.6, L7*0.6*H7) -> 225
B15: Valor CFR | C15: =C11+C14 -> 189.78168 | D15: =D11+D14 -> 19.23463 | E15: =E11+E14 -> 157.72396 | F15: =F11+F14 -> 61.550816 | G15: =G11+G14 -> 593.70891 | H15: =SUM(C15:G15) -> 1022
B16: CFR Valorizado | C16: =C12+C14 -> 41.781681 | D16: =D12+D14 -> 4.2346299 | E16: =E12+E14 -> 34.723965 | F16: =F12+F14 -> 13.550816 | G16: =G12+G14 -> 130.70891 | H16: =SUM(C16:G16) -> 225
B17: Seguro | C17: =IF(H11>5000,100*C13,50*C13) -> 9.2848181 | D17: =IF(H11>5000,100*D13,50*D13) -> 0.94102886 | E17: =IF(H11>5000,100*E13,50*E13) -> 7.7164366 | F17: =IF(H11>5000,100*F13,50*F13) -> 3.0112923 | G17: =IF(H11>5000,100*G13,50*G13) -> 29.046424 | H17: =SUM(C17:G17) -> 50
B18: Valor CIF | C18: =C15+C17 -> 199.0665 | D18: =D15+D17 -> 20.175659 | E18: =E15+E17 -> 165.4404 | F18: =F15+F17 -> 64.562108 | G18: =G15+G17 -> 622.75533 | H18: =SUM(C18:G18) -> 1072
B19: CIF Valorizado | C19: =C16+C17 -> 51.066499 | D19: =D16+D17 -> 5.1756587 | E19: =E16+E17 -> 42.440402 | F19: =F16+F17 -> 16.562108 | G19: =G16+G17 -> 159.75533 | H19: =SUM(C19:G19) -> 275
B23: Tributos Aplicables
B26: ANTIDUMPING | C26: 0 | D26: 0 | E26: 0 | F26: 0 | G26: 0 | H26: =SUM(C26:G26) -> 0
C27: 0 | D27: 0.06 | E27: 0 | F27: 0.06 | G27: 0 | H27: =SUM(C27:G27) -> 0.12
B28: AD VALOREM | C28: =MAX(C19,C18)*C27 -> 0 | D28: =MAX(D19,D18)*D27 -> 1.2105395 | E28: =MAX(E19,E18)*E27 -> 0 | F28: =MAX(F19,F18)*F27 -> 3.8737265 | G28: =MAX(G19,G18)*G27 -> 0 | H28: =SUM(C28:G28) -> 5.084266
B29: IGV | C29: =0.16*(MAX(C19,C18)+C28) -> 31.85064 | D29: =0.16*(MAX(D19,D18)+D28) -> 3.4217917 | E29: =0.16*(MAX(E19,E18)+E28) -> 26.470464 | F29: =0.16*(MAX(F19,F18)+F28) -> 10.949734 | G29: =0.16*(MAX(G19,G18)+G28) -> 99.640853 | H29: =SUM(C29:G29) -> 172.33348
B30: IPM | C30: =0.02*(MAX(C19,C18)+C28) -> 3.98133 | D30: =0.02*(MAX(D19,D18)+D28) -> 0.42772396 | E30: =0.02*(MAX(E19,E18)+E28) -> 3.308808 | F30: =0.02*(MAX(F19,F18)+F28) -> 1.3687167 | G30: =0.02*(MAX(G19,G18)+G28) -> 12.455107 | H30: =SUM(C30:G30) -> 21.541685
B31: PERCEPCION | C31: =0.035*(MAX(C18,C19) +C28+C29+C30) -> 8.2214464 | D31: =0.035*(MAX(D18,D19) +D28+D29+D30) -> 0.88324999 | E31: =0.035*(MAX(E18,E19) +E28+E29+E30) -> 6.8326886 | F31: =0.035*(MAX(F18,F19) +F28+F29+F30) -> 2.8264 | G31: =0.035*(MAX(G18,G19) +G28+G29+G30) -> 25.719795 | H31: =SUM(C31:G31) -> 44.48358
B32: TOTAL | C32: =SUM(C28:C31) -> 44.053416 | D32: =SUM(D28:D31) -> 5.9433052 | E32: =SUM(E28:E31) -> 36.611961 | F32: =SUM(F28:F31) -> 19.018577 | G32: =SUM(G28:G31) -> 137.81576 | H32: =SUM(H28:H31) -> 243.44301
B37: Costos Destinos
B40: ITEM | C40: =C13*H40 -> 27.854454 | D40: =D13*H40 -> 2.8230866 | E40: =E13*H40 -> 23.14931 | F40: =F13*H40 -> 9.033877 | G40: =G13*H40 -> 87.139272 | H40: =IF(H7<1, L7*0.4,L7*0.4*H7) -> 150
B43: ITEM | C43: FREIDORA DE AIRE DE 10L | D43: LICUADORA 2 EN 1 BATIDORA | E43: FREIDORA DE AIRE DE 15L | F43: ARBOL SENTETICO NAVIDEÑO | G43: SET DE CUBIERTOS | H43: Total
B44: COSTO TOTAL | C44: =SUM(C15,C40,C32,(C26)) -> 261.68955 | D44: =SUM(D15,D40,D32,(D26)) -> 28.001022 | E44: =SUM(E15,E40,E32,(E26)) -> 217.48524 | F44: =SUM(F15,F40,F32,(F26)) -> 89.603269 | G44: =SUM(G15,G40,G32,(G26)) -> 818.66394 | H44: =SUM(C44:G44) -> 1415.443
B45: CANTIDAD | C45: 10 | D45: 2 | E45: 6 | F45: 2 | G45: 300
B46: COSTO UNITARIO | C46: =SUM(C44/C45) -> 26.168955 | D46: =SUM(D44/D45) -> 14.000511 | E46: =SUM(E44/E45) -> 36.247539 | F46: =SUM(F44/F45) -> 44.801635 | G46: =SUM(G44/G45) -> 2.7288798
B47: COSTO SOLES | C47: =C46*3.7 -> 96.825134 | D47: =D46*3.7 -> 51.80189 | E47: =E46*3.7 -> 134.1159 | F47: =F46*3.7 -> 165.76605 | G47: =G46*3.7 -> 10.096855
