Workbook

Sheet 1
E3: PRO MUNDO COMEX S.A.C.
E4: RUC: 20612452432
E7: COTIZACION N002
B8: NOMBRE: | C8: ANTHONY ROCCA CAQUI | E8: SERVICIO: | F8: CARGA CONSOLIDADA | I8: N° CAJAS: | J8: =+'2'!F7 -> 0.06
B9: APELLIDO: | E9: FECHA: | F9: =+TODAY() -> 45917 | I9: PESO: | J9: 22.3 Kg
B10: DNI/RUC: | E10: ORIGEN: | F10: CHINA | I10: MEDIDA: | J10: 0
B11: TELEFONO: | C11: 51 951880948 | E11: CLIENTE: | F11: ANTIGUO | I11: CBM | J11: 0.06
B13: CALCULO DE BASE IMPONIBLE | K13: MONTO | L13: MONEDA
B14: VALOR DE CARGA | K14: ='2'!E11 -> 16 | L14: USD
B15: FLETE INTERNACIONAL + SEGURO | K15: ='2'!E14 + '2'!E17 -> 47179.281 | L15: USD
B16: VALOR CIF | K16: =SUM(K14:K15) -> 47195.281 | L16: USD
B19: CALCULO DE TRIBUTOS | J19: % | K19: MONTO | L19: MONEDA
B20: ADVALOREM | J20: =MAX('2'!C26:E26) -> 0 | K20: ='2'!E28 -> 63.227313 | L20: USD | N20: Hola ANTHONY ROCCA CAQUI 😁 un gusto saludarte! A continuación te envío la cotización final de tu importación📋📦. 🙋‍♂️ PAGO PENDIENTE : ☑️Costo CBM: $0 ☑️Impuestos: $174.9 ☑️ Total: $174.9 Pronto le aviso nuevos avances, que tengan buen día🚢 Último día de pago:
B21: IGV | J21: 0.16 | K21: ='2'!E29 -> 7.9034141 | L21: USD
B22: IPM | J22: 0.02 | K22: ='2'!E30 -> 16.32055 | L22: USD
B23: SUB TOTAL | K23: =SUM(K20:K22) -> 87.451277 | L23: USD
B25: PERCEPCIÓN | J25: 3.5% | K25: ='2'!E31 -> 87.451277 | L25: USD
B26: TOTAL | K26: =K23+K25 -> 174.90255 | L26: USD
B28: RESUMEN DE COTIZACIÓN | K28: MONTO | L28: MONEDA
B29: VALOR DE CARGA (PAGO AL PROVEEDOR) | K29: =K14 -> 16 | L29: USD
B30: SERVICIO DE IMPORTACIÓN (ORIGEN -FLETE - DESTINO) | K30: =IF(J11<1, '2'!E40, '2'!E40*J11) -> 0 | L30: USD
B31: IMPUESTOS | K31: =K20+K21+K22+K25 -> 174.90255 | L31: USD
B32: MONTO TOTAL | K32: =K29+K30+K31 -> 190.90255 | L32: USD
B34: SIMULACIÓN DEL PRECIO PUESTO EN PERÚ POR PIEZA
B35: # ITEM | C35: NOMBRE PRODUCTO | F35: CANTIDAD | G35: COSTO UNI. | I35: PRECIO U. | J35: TOTAL | K35: PRECIO UNIT. (SOLES)
B36: 1 | C36: =+'2'!$C$6 -> 0 | F36: =+'2'!$C$45 -> 1000 | G36: =+'2'!$C$10 -> 1000 | I36: =+'2'!$C$46 -> 194.42712 | J36: =+F36*I36 -> 194427.12 | K36: =I36*3.7 -> 719.38034
B37: 2 | C37: =+'2'!$D$6 -> 0 | F37: =+'2'!$D$45 -> 45 | G37: =+'2'!$D$10 -> 45 | I37: =+'2'!$D$46 -> 57.301787 | J37: =+F37*I37 -> 2578.5804 | K37: =I37*3.7 -> 212.01661
B38: 3 | C38: =+'2'!$E$6 -> 0 | F38: =+'2'!$E$45 -> 1600 | G38: =+'2'!$E$10 -> 1600 | I38: =+'2'!$E$46 -> 19.609513 | J38: =+F38*I38 -> 31375.22 | K38: =I38*3.7 -> 72.555197
B39: TOTAL | F39: =+SUM(F36:F38) -> 2645 | J39: =+SUM(J36:J38) -> 228380.92
B42: NOTAS:
B43: *Las fechas brindadas son estimadas, estan sujetas a variación.
B44: *No se emite comprobante por concepto de "PERCEPCIÓN, ANTI DUMPING, GESTIÓN DE COMPRA"
B45: *A nosotros se nos pagan los Gastos Logísticos + Impuestos una semana antes de que el contenedor
B46: llegue al puerto del Callao.
B47: *El tipo de cambio referencial usado para la conversión a soles es del 3.70
D50: PRO MUNDO COMEX S.A.C.
D51: RUC: 20612452432
B54: TÉRMINOS Y CONDICIONES:
B56: 1. Todos los pagos se realizan en dólares.
B57: 2.Todas las marcas de los productos deben ser verificadas por el cliente,
...

Sheet 2
B3: Calculo de Tributos
B5: Nombres | C5: CERRADURA DE MALETA DE EQUIPAJE | D5: BROCA DE LIJADO PARA MANICURA | E5: DISCOS DE LIJA PARA MANICURA | F5: Total
B6: Peso | C6: 0 | D6: 0 | E6: 0 | F6: 22.3 | I6: Tipo Cliente | J6: Tarifa
B7: Valor CBM | C7: 0 | D7: 0 | E7: 0 | F7: 0.06 | I7: ANTIGUO | J7: 260
B8: Valor Unitario | C8: 0.06 | D8: 0.06 | E8: 0.01
B9: Valoracion | C9: 0 | D9: 0 | E9: 0
B10: Cantidad | C10: 1000 | D10: 45 | E10: 1600 | F10: =SUM(C10:E10) -> 2645
B11: Valor FOB | C11: =C8*C10 -> 60 | D11: =D8*D10 -> 2.7 | E11: =E8*E10 -> 16 | F11: =SUM(C11:E11) -> 78.7
B12: Valor FOB Valoracion | C12: =C10*C9 -> 0 | D12: =D10*D9 -> 0 | E12: =E10*E9 -> 0
B13: Distribucion % | C13: =C11/F11 -> 636 | D13: =D11/F11 -> 8.03 | E13: =E11/F11 -> 300
B14: Flete | C14: =F14*C13 -> 99216 | D14: =F14*D13 -> 1252.68 | E14: =F14*E13 -> 46800 | F14: =IF(F7<1, J7*0.6, J7*0.6*F7) -> 156
B15: Valor CFR | C15: =C11+C14 -> 99276 | D15: =D11+D14 -> 1255.38 | E15: =E11+E14 -> 0.31778651
B16: CFR Valorizado | C16: =C12+C14 -> 99216 | D16: =D12+D14 -> 1252.68 | E16: =E12+E14 -> 79.281379
B17: Seguro | C17: =IF(F11>5000,100*C13,50*C13) -> 31800 | D17: =IF(F11>5000,100*D13,50*D13) -> 401.5 | E17: =IF(F11>5000,100*E13,50*E13) -> 379.28138
B18: Valor CIF | C18: =C15+C17 -> 131076 | D18: =D15+D17 -> 1656.88 | E18: =E15+E17 -> 379.59917
B19: CIF Valorizado | C19: =C16+C17 -> 131016 | D19: =D16+D17 -> 1654.18 | E19: =E16+E17 -> 15.889326
B23: Tributos Aplicables
B26: ANTIDUMPING | C26: 0 | D26: 0 | E26: 0 | F26: =SUM(C26:E26) -> 0
C27: 0 | D27: 0.06 | E27: 0 | F27: =SUM(C27:E27) -> 0.06
B28: AD VALOREM | C28: =MAX(C19,C18)*C27 -> 0 | D28: =MAX(D19,D18)*D27 -> 99.4128 | E28: =MAX(E19,E18)*E27 -> 63.227313 | F28: =SUM(C28:E28) -> 162.64011
B29: IGV | C29: =0.16*(MAX(C19,C18)+C28) -> 20972.16 | D29: =0.16*(MAX(D19,D18)+D28) -> 281.00685 | E29: =0.16*(MAX(E19,E18)+E28) -> 7.9034141 | F29: =SUM(C29:E29) -> 21261.07
B30: IPM | C30: =0.02*(MAX(C19,C18)+C28) -> 2621.52 | D30: =0.02*(MAX(D19,D18)+D28) -> 35.125856 | E30: =0.02*(MAX(E19,E18)+E28) -> 16.32055 | F30: =SUM(C30:E30) -> 2672.9664
B31: PERCEPCION | C31: =0.035*(MAX(C18,C19) +C28+C29+C30) -> 5413.4388 | D31: =0.035*(MAX(D18,D19) +D28+D29+D30) -> 72.534893 | E31: =0.035*(MAX(E18,E19) +E28+E29+E30) -> 87.451277 | F31: =SUM(C31:E31) -> 5573.425
B32: TOTAL | C32: =SUM(C28:C31) -> 29007.119 | D32: =SUM(D28:D31) -> 488.0804 | E32: =SUM(E28:E31) -> 174.90255 | F32: =SUM(F28:F31) -> 29670.102
B37: Costos Destinos
B40: ITEM | C40: =C13*F40 -> 66144 | D40: =D13*F40 -> 835.12 | E40: =E13*F40 -> 31200 | F40: =IF(F7<1, J7*0.4,J7*0.4*F7) -> 104
B43: ITEM | C43: CERRADURA DE MALETA DE EQUIPAJE | D43: BROCA DE LIJADO PARA MANICURA | E43: DISCOS DE LIJA PARA MANICURA | F43: Total
B44: COSTO TOTAL | C44: =SUM(C15,C40,C32,(C26)) -> 194427.12 | D44: =SUM(D15,D40,D32,(D26)) -> 2578.5804 | E44: =SUM(E15,E40,E32,(E26)) -> 31375.22 | F44: =SUM(C44:E44) -> 228380.92
B45: CANTIDAD | C45: 1000 | D45: 45 | E45: 1600
B46: COSTO UNITARIO | C46: =SUM(C44/C45) -> 194.42712 | D46: =SUM(D44/D45) -> 57.301787 | E46: =SUM(E44/E45) -> 19.609513
B47: COSTO SOLES | C47: =C46*3.7 -> 719.38034 | D47: =D46*3.7 -> 212.01661 | E47: =E46*3.7 -> 72.555197
