Workbook

Sheet 1
E3: PRO MUNDO COMEX S.A.C.
E4: RUC: 20612452432
E7: COTIZACION N002
B8: NOMBRE: | C8: BRAIN HANS RINCÓN SONCCO | E8: SERVICIO: | F8: CARGA CONSOLIDADA | I8: N° CAJAS: | J8: =+'2'!F7 -> 0
B9: APELLIDO: | E9: FECHA: | F9: =+TODAY() -> 45917 | I9: PESO: | J9: 1.8297 Tn
B10: DNI/RUC: | C10: 47773459 | E10: ORIGEN: | F10: CHINA | I10: MEDIDA: | J10: 0
B11: TELEFONO: | C11: 51921284934 | E11: CLIENTE: | F11: NUEVO | I11: CBM | J11: 2.01
B13: CALCULO DE BASE IMPONIBLE | K13: MONTO | L13: MONEDA
B14: VALOR DE CARGA | K14: ='2'!F11 -> 1653 | L14: USD
B15: FLETE INTERNACIONAL + SEGURO | K15: ='2'!F14 + '2'!F17 -> 48145.53 | L15: USD
B16: VALOR CIF | K16: =SUM(K14:K15) -> 49798.53 | L16: USD
B19: CALCULO DE TRIBUTOS | J19: % | K19: MONTO | L19: MONEDA
B20: ADVALOREM | J20: =MAX('2'!C26:E26) -> 0 | K20: ='2'!F28 -> 204.32328 | L20: USD | N20: Hola BRAIN HANS RINCÓN SONCCO 😁 un gusto saludarte! A continuación te envío la cotización final de tu importación📋📦. 🙋‍♂️ PAGO PENDIENTE : ☑️Costo CBM: $1897.5003 ☑️Impuestos: $598.72 ☑️ Total: $2496.2203 Pronto le aviso nuevos avances, que tengan buen día🚢 Último día de pago:
B21: IGV | J21: 0.16 | K21: ='2'!F29 -> 25.54041 | L21: USD
B22: IPM | J22: 0.02 | K22: ='2'!F30 -> 52.740946 | L22: USD
B23: SUB TOTAL | K23: =SUM(K20:K22) -> 282.60463 | L23: USD
B25: PERCEPCIÓN | J25: 3.5% | K25: ='2'!F31 -> 316.11511 | L25: USD
B26: TOTAL | K26: =K23+K25 -> 598.71974 | L26: USD
B28: RESUMEN DE COTIZACIÓN | K28: MONTO | L28: MONEDA
B29: VALOR DE CARGA (PAGO AL PROVEEDOR) | K29: =K14 -> 1653 | L29: USD
B30: SERVICIO DE IMPORTACIÓN (ORIGEN -FLETE - DESTINO) | K30: =IF(J11<1, '2'!F14, '2'!F14*J11) -> 1897.5003 | L30: USD
B31: IMPUESTOS | K31: =K26 -> 598.71974 | L31: USD
B32: MONTO TOTAL | K32: =SUM(K29:K31) -> 4149.22 | L32: USD
B34: SIMULACIÓN DEL PRECIO PUESTO EN PERÚ POR PIEZA
B35: # ITEM | C35: NOMBRE PRODUCTO | F35: CANTIDAD | G35: COSTO UNI. | I35: PRECIO U. | J35: TOTAL | K35: PRECIO UNIT. (SOLES)
B36: 1 | C36: =+'2'!$C$6 -> 0 | F36: =+'2'!$C$45 -> 50 | G36: =+'2'!$C$10 -> 50 | I36: =+'2'!$C$46 -> 3374.1082 | J36: =+F36*I36 -> 168705.41 | K36: =I36*3.7 -> 12484.2
B37: 2 | C37: =+'2'!$D$6 -> 0 | F37: =+'2'!$D$45 -> 100 | G37: =+'2'!$D$10 -> 100 | I37: =+'2'!$D$46 -> 21.294281 | J37: =+F37*I37 -> 2129.4281 | K37: =I37*3.7 -> 78.788838
B38: 3 | C38: =+'2'!$E$6 -> 0 | F38: =+'2'!$E$45 -> 4 | G38: =+'2'!$E$10 -> 4 | I38: =+'2'!$E$46 -> 19888.805 | J38: =+F38*I38 -> 79555.22 | K38: =I38*3.7 -> 73588.579
B39: TOTAL | F39: =+SUM(F36:F38) -> 154 | J39: =+SUM(J36:J38) -> 250390.06
B42: NOTAS:
B43: *Las fechas brindadas son estimadas, estan sujetas a variación.
B44: *No se emite comprobante por concepto de "PERCEPCIÓN, ANTI DUMPING, GESTIÓN DE COMPRA"
B45: *A nosotros se nos pagan los Gastos Logísticos + Impuestos una semana antes de que el contenedor
B46: llegue al puerto del Callao.
B47: *El tipo de cambio referencial usado para la conversión a soles es del 3.70
D50: PRO MUNDO COMEX S.A.C.
D51: RUC: 20612452432
B54: TÉRMINOS Y CONDICIONES:
B56: 1. Todos los pagos se realizan en dólares.
B57: 2.Todas las marcas de los productos deben ser verificadas por el cliente,
...

Sheet 2
B3: Calculo de Tributos
B5: Nombres | C5: CILINDRO MAESTRO DE EMBRAGUE | D5: PINZA DE FRENO DELANTERA | E5: MECANISMO DIFERENCIAL TRASERO | F5: RODAMIENTO DE BLOQUE DE ALMOHADA | G5: Total
B6: Peso | C6: 0 | D6: 0 | E6: 0 | F6: 0 | G6: 1.83 | J6: Tipo Cliente | K6: Tarifa
B7: Valor CBM | C7: 0 | D7: 0 | E7: 0 | F7: 0 | G7: 1.89 | J7: NUEVO | K7: 350
B8: Valor Unitario | C8: 3.9 | D8: 18.25 | E8: 138 | F8: 16.53
B9: Valoracion | C9: 0 | D9: 0 | E9: 0 | F9: 0
B10: Cantidad | C10: 50 | D10: 100 | E10: 4 | F10: 100 | G10: =SUM(C10:F10) -> 254
B11: Valor FOB | C11: =C8*C10 -> 195 | D11: =D8*D10 -> 1825 | E11: =E8*E10 -> 552 | F11: =F8*F10 -> 1653 | G11: =SUM(C11:F11) -> 4225
B12: Valor FOB Valoracion | C12: =C10*C9 -> 0 | D12: =D10*D9 -> 0 | E12: =E10*E9 -> 0 | F12: =F10*F9 -> 0
B13: Distribucion % | C13: =C11/G11 -> 636 | D13: =D11/G11 -> 8.03 | E13: =E11/G11 -> 300 | F13: =F11/G11 -> 944.03
B14: Flete | C14: =G14*C13 -> 636 | D14: =G14*D13 -> 8.03 | E14: =G14*E13 -> 300 | F14: =G14*F13 -> 944.03 | G14: =IF(G7<1, K7*0.6, K7*0.6*G7) -> 396.9
B15: Valor CFR | C15: =C11+C14 -> 0.6737074 | D15: =D11+D14 -> 0.0085060856 | E15: =E11+E14 -> 0.31778651 | F15: =F11+F14 -> 2597.03
B16: CFR Valorizado | C16: =C12+C14 -> 168.07652 | D16: =D12+D14 -> 2.1220982 | E16: =E12+E14 -> 79.281379 | F16: =F12+F14 -> 249.48
B17: Seguro | C17: =IF(G11>5000,100*C13,50*C13) -> 804.07652 | D17: =IF(G11>5000,100*D13,50*D13) -> 10.152098 | E17: =IF(G11>5000,100*E13,50*E13) -> 379.28138 | F17: =IF(G11>5000,100*F13,50*F13) -> 47201.5
B18: Valor CIF | C18: =C15+C17 -> 804.07652 | D18: =D15+D17 -> 10.160604 | E18: =E15+E17 -> 379.59917 | F18: =F15+F17 -> 49798.53
B19: CIF Valorizado | C19: =C16+C17 -> 33.68537 | D19: =D16+D17 -> 0.42530428 | E19: =E16+E17 -> 15.889326 | F19: =F16+F17 -> 50
B23: Tributos Aplicables
B26: ANTIDUMPING | C26: 0 | D26: 0 | E26: 0 | F26: 0 | G26: =SUM(C26:F26) -> 0
C27: 0 | D27: 0 | E27: 0 | F27: 0 | G27: =SUM(C27:F27) -> 0
B28: AD VALOREM | C28: =MAX(C19,C18)*C27 -> 139.40358 | D28: =MAX(D19,D18)*D27 -> 1.6923844 | E28: =MAX(E19,E18)*E27 -> 63.227313 | F28: =MAX(F19,F18)*F27 -> 204.32328 | G28: =SUM(C28:F28) -> 408.64655
B29: IGV | C29: =0.16*(MAX(C19,C18)+C28) -> 17.425447 | D29: =0.16*(MAX(D19,D18)+D28) -> 0.21154805 | E29: =0.16*(MAX(E19,E18)+E28) -> 7.9034141 | F29: =0.16*(MAX(F19,F18)+F28) -> 25.54041 | G29: =SUM(C29:F29) -> 51.080819
B30: IPM | C30: =0.02*(MAX(C19,C18)+C28) -> 35.983549 | D30: =0.02*(MAX(D19,D18)+D28) -> 0.43684672 | E30: =0.02*(MAX(E19,E18)+E28) -> 16.32055 | F30: =0.02*(MAX(F19,F18)+F28) -> 52.740946 | G30: =SUM(C30:F30) -> 105.48189
B31: PERCEPCION | C31: =0.035*(MAX(C18,C19) +C28+C29+C30) -> 226.32305 | D31: =0.035*(MAX(D18,D19) +D28+D29+D30) -> 2.3407792 | E31: =0.035*(MAX(E18,E19) +E28+E29+E30) -> 87.451277 | F31: =0.035*(MAX(F18,F19) +F28+F29+F30) -> 316.11511 | G31: =SUM(C31:F31) -> 632.23021
B32: TOTAL | C32: =SUM(C28:C31) -> 419.13563 | D32: =SUM(D28:D31) -> 4.6815584 | E32: =SUM(E28:E31) -> 174.90255 | F32: =SUM(F28:F31) -> 598.71974 | G32: =SUM(G28:G31) -> 1197.4395
B37: Costos Destinos
B40: ITEM | C40: =C13*G40 -> 168285.6 | D40: =D13*G40 -> 2124.738 | E40: =E13*G40 -> 79380 | F40: =F13*G40 -> 249790.34 | G40: =IF(G7<1, K7*0.4,K7*0.4*G7) -> 264.6
B43: ITEM | C43: CILINDRO MAESTRO DE EMBRAGUE | D43: PINZA DE FRENO DELANTERA | E43: MECANISMO DIFERENCIAL TRASERO | F43: RODAMIENTO DE BLOQUE DE ALMOHADA | G43: Total
B44: COSTO TOTAL | C44: =SUM(C15,C40,C32,(C26)) -> 168705.41 | D44: =SUM(D15,D40,D32,(D26)) -> 2129.4281 | E44: =SUM(E15,E40,E32,(E26)) -> 79555.22 | F44: =SUM(F15,F40,F32,(F26)) -> 252986.09 | G44: =SUM(C44:F44) -> 503376.15
B45: CANTIDAD | C45: 50 | D45: 100 | E45: 4 | F45: 100
B46: COSTO UNITARIO | C46: =SUM(C44/C45) -> 3374.1082 | D46: =SUM(D44/D45) -> 21.294281 | E46: =SUM(E44/E45) -> 19888.805 | F46: =SUM(F44/F45) -> 2529.8609
B47: COSTO SOLES | C47: =C46*3.7 -> 12484.2 | D47: =D46*3.7 -> 78.788838 | E47: =E46*3.7 -> 73588.579 | F47: =F46*3.7 -> 9360.4852
