Workbook

Sheet 1
E3: PRO MUNDO COMEX S.A.C.
E4: RUC: 20612452432
E7: COTIZACION N002
B8: NOMBRE: | C8: FREDY EBER AYMA GARCIA 2 | E8: SERVICIO: | F8: CARGA CONSOLIDADA | I8: N° CAJAS: | J8: =+'2'!F7 -> 0
B9: APELLIDO: | E9: FECHA: | F9: =+TODAY() -> 45917 | I9: PESO: | J9: 356.66 Kg
B10: DNI/RUC: | C10: 46888785 | E10: ORIGEN: | F10: CHINA | I10: MEDIDA: | J10: 0
B11: TELEFONO: | C11: 51 958761250 | E11: CLIENTE: | F11: ANTIGUO | I11: CBM | J11: ='2'!F7 -> 0
B13: CALCULO DE BASE IMPONIBLE | K13: MONTO | L13: MONEDA
B14: VALOR DE CARGA | K14: ='2'!F11 -> 2000 | L14: USD
B15: FLETE INTERNACIONAL + SEGURO | K15: ='2'!F14 + '2'!F17 -> 242.04405 | L15: USD
B16: VALOR CIF | K16: =SUM(K14:K15) -> 2242.0441 | L16: USD
B19: CALCULO DE TRIBUTOS | J19: % | K19: MONTO | L19: MONEDA
B20: ADVALOREM | J20: =MAX('2'!C26:E26) -> 0 | K20: ='2'!F28 -> 0 | L20: USD | N20: Hola FREDY EBER AYMA GARCIA 2 😁 un gusto saludarte! A continuación te envío la cotización final de tu importación📋📦. 🙋‍♂️ PAGO PENDIENTE : ☑️Costo CBM: $957 ☑️Impuestos: $598.72 ☑️ Total: $1555.72 Pronto le aviso nuevos avances, que tengan buen día🚢 Último día de pago:
B21: IGV | J21: 0.16 | K21: ='2'!F29 -> 358.72705 | L21: USD
B22: IPM | J22: 0.02 | K22: ='2'!F30 -> 44.840881 | L22: USD
B23: SUB TOTAL | K23: =SUM(K20:K22) -> 403.56793 | L23: USD
B25: PERCEPCIÓN | J25: 3.5% | K25: ='2'!F31 -> 92.596419 | L25: USD
B26: TOTAL | K26: =K23+K25 -> 496.16435 | L26: USD
B28: RESUMEN DE COTIZACIÓN | K28: MONTO | L28: MONEDA
B29: VALOR DE CARGA (PAGO AL PROVEEDOR) | K29: =K14 -> 2000 | L29: USD
B30: SERVICIO DE IMPORTACIÓN (ORIGEN -FLETE - DESTINO) | K30: =IF(J11<1, 300, 300*J11) -> 300 | L30: USD
B31: IMPUESTOS | K31: =K20+K21+K22+K25 -> 496.16435 | L31: USD
B32: MONTO TOTAL | K32: =K29+K30+K31 -> 2796.1643 | L32: USD
B34: SIMULACIÓN DEL PRECIO PUESTO EN PERÚ POR PIEZA
B35: # ITEM | C35: NOMBRE PRODUCTO | F35: CANTIDAD | G35: COSTO UNI. | I35: PRECIO U. | J35: TOTAL | K35: PRECIO UNIT. (SOLES)
B36: 1 | C36: CABLE DE IMPRESORA | F36: ='2'!C10 -> 500 | G36: ='2'!C8 -> 2.8 | I36: ='2'!C46 -> 3.9771675 | J36: ='2'!C44 -> 1988.5838 | K36: ='2'!C47 -> 14.71552
B37: 2 | C37: ALMOHADILLA DE ESPONJA DE TINTA L4160 | F37: ='2'!D10 -> 5000 | G37: ='2'!D8 -> 0.35 | I37: ='2'!D46 -> 0.49714594 | J37: ='2'!D44 -> 2485.7297 | K37: ='2'!D47 -> 1.83944
B38: 3 | C38: ALMOHADILLA DE ESPONJA DE TINTA G3110 | F38: ='2'!E10 -> 1300 | G38: ='2'!E8 -> 0.40384615 | I38: ='2'!E46 -> 0.57362993 | J38: ='2'!E44 -> 745.71891 | K38: ='2'!E47 -> 2.1224308
B39: 4 | C39: FUENTE DE ALIMENTACION PARA IMPRESORA | F39: ='2'!F10 -> 500 | G39: ='2'!F8 -> 4 | I39: ='2'!F46 -> 5.6816679 | J39: ='2'!F44 -> 2840.834 | K39: ='2'!F47 -> 21.022171
B40: TOTAL | F40: =SUM(F36:F39) -> 7300 | J40: =SUM(J36:J39) -> 8060.8663
B42: NOTAS:
B43: *Las fechas brindadas son estimadas, estan sujetas a variación.
B44: *No se emite comprobante por concepto de "PERCEPCIÓN, ANTI DUMPING, GESTIÓN DE COMPRA"
B45: *A nosotros se nos pagan los Gastos Logísticos + Impuestos una semana antes de que el contenedor
B46: llegue al puerto del Callao.
B47: *El tipo de cambio referencial usado para la conversión a soles es del 3.70
D50: PRO MUNDO COMEX S.A.C.
D51: RUC: 20612452432
B54: TÉRMINOS Y CONDICIONES:
B56: 1. Todos los pagos se realizan en dólares.
...

Sheet 2
B3: Calculo de Tributos
B5: Nombres | C5: CABLE DE IMPRESORA | D5: ALMOHADILLA DE ESPONJA DE TINTA L4160 | E5: ALMOHADILLA DE ESPONJA DE TINTA G3110 | F5: FUENTE DE ALIMENTACION PARA IMPRESORA | G5: Total
B6: Peso | C6: 0 | D6: 0 | E6: 0 | F6: 0 | G6: 356.66 | J6: Tipo Cliente | K6: Tarifa
B7: Valor CBM | C7: 0 | D7: 0 | E7: 0 | F7: 0 | G7: 3.26 | J7: ANTIGUO | K7: 300
B8: Valor Unitario | C8: 2.8 | D8: 0.35 | E8: 0.40384615 | F8: 4
B9: Valoracion | C9: 0 | D9: 0 | E9: 0 | F9: 0
B10: Cantidad | C10: 500 | D10: 5000 | E10: 1300 | F10: 500 | G10: =SUM(C10:F10) -> 7300
B11: Valor FOB | C11: =C8*C10 -> 1400 | D11: =D8*D10 -> 1750 | E11: =E8*E10 -> 525 | F11: =F8*F10 -> 2000 | G11: =SUM(C11:F11) -> 5675
B12: Valor FOB Valoracion | C12: =C10*C9 -> 0 | D12: =D10*D9 -> 0 | E12: =E10*E9 -> 0 | F12: =F10*F9 -> 0
B13: Distribucion % | C13: =C11/G11 -> 0.24669604 | D13: =D11/G11 -> 0.30837004 | E13: =E11/G11 -> 0.092511013 | F13: =F11/G11 -> 0.35242291
B14: Flete | C14: =G14*C13 -> 144.76123 | D14: =G14*D13 -> 180.95154 | E14: =G14*E13 -> 54.285463 | F14: =G14*F13 -> 206.80176 | G14: =IF(G7<1, K7*0.6, K7*0.6*G7) -> 586.8
B15: Valor CFR | C15: =C11+C14 -> 1544.7612 | D15: =D11+D14 -> 1930.9515 | E15: =E11+E14 -> 579.28546 | F15: =F11+F14 -> 2206.8018
B16: CFR Valorizado | C16: =C12+C14 -> 144.76123 | D16: =D12+D14 -> 180.95154 | E16: =E12+E14 -> 54.285463 | F16: =F12+F14 -> 206.80176
B17: Seguro | C17: =IF(G11>5000,100*C13,50*C13) -> 24.669604 | D17: =IF(G11>5000,100*D13,50*D13) -> 30.837004 | E17: =IF(G11>5000,100*E13,50*E13) -> 9.2511013 | F17: =IF(G11>5000,100*F13,50*F13) -> 35.242291
B18: Valor CIF | C18: =C15+C17 -> 1569.4308 | D18: =D15+D17 -> 1961.7885 | E18: =E15+E17 -> 588.53656 | F18: =F15+F17 -> 2242.0441
B19: CIF Valorizado | C19: =C16+C17 -> 169.43084 | D19: =D16+D17 -> 211.78855 | E19: =E16+E17 -> 63.536564 | F19: =F16+F17 -> 242.04405
B23: Tributos Aplicables
B26: ANTIDUMPING | C26: 0 | D26: 0 | E26: 0 | F26: 0 | G26: =SUM(C26:F26) -> 0
C27: 0 | D27: 0 | E27: 0 | F27: 0 | G27: =SUM(C27:F27) -> 0
B28: AD VALOREM | C28: =MAX(C19,C18)*C27 -> 0 | D28: =MAX(D19,D18)*D27 -> 0 | E28: =MAX(E19,E18)*E27 -> 0 | F28: =MAX(F19,F18)*F27 -> 0 | G28: =SUM(C28:F28) -> 0
B29: IGV | C29: =0.16*(MAX(C19,C18)+C28) -> 251.10893 | D29: =0.16*(MAX(D19,D18)+D28) -> 313.88617 | E29: =0.16*(MAX(E19,E18)+E28) -> 94.16585 | F29: =0.16*(MAX(F19,F18)+F28) -> 358.72705 | G29: =SUM(C29:F29) -> 1017.888
B30: IPM | C30: =0.02*(MAX(C19,C18)+C28) -> 31.388617 | D30: =0.02*(MAX(D19,D18)+D28) -> 39.235771 | E30: =0.02*(MAX(E19,E18)+E28) -> 11.770731 | F30: =0.02*(MAX(F19,F18)+F28) -> 44.840881 | G30: =SUM(C30:F30) -> 127.236
B31: PERCEPCION | C31: =0.035*(MAX(C18,C19) +C28+C29+C30) -> 64.817494 | D31: =0.035*(MAX(D18,D19) +D28+D29+D30) -> 81.021867 | E31: =0.035*(MAX(E18,E19) +E28+E29+E30) -> 24.30656 | F31: =0.035*(MAX(F18,F19) +F28+F29+F30) -> 92.596419 | G31: =SUM(C31:F31) -> 262.74234
B32: TOTAL | C32: =SUM(C28:C31) -> 347.31504 | D32: =SUM(D28:D31) -> 434.14381 | E32: =SUM(E28:E31) -> 130.24314 | F32: =SUM(F28:F31) -> 496.16435 | G32: =SUM(G28:G31) -> 1407.8663
B37: Costos Destinos
B40: ITEM | C40: =C13*G40 -> 96.507489 | D40: =D13*G40 -> 120.63436 | E40: =E13*G40 -> 36.190308 | F40: =F13*G40 -> 137.86784 | G40: =IF(G7<1, K7*0.4,K7*0.4*G7) -> 391.2
B43: ITEM | C43: CABLE DE IMPRESORA | D43: ALMOHADILLA DE ESPONJA DE TINTA L4160 | E43: ALMOHADILLA DE ESPONJA DE TINTA G3110 | F43: FUENTE DE ALIMENTACION PARA IMPRESORA | G43: Total
B44: COSTO TOTAL | C44: =SUM(C15,C40,C32,(C26)) -> 1988.5838 | D44: =SUM(D15,D40,D32,(D26)) -> 2485.7297 | E44: =SUM(E15,E40,E32,(E26)) -> 745.71891 | F44: =SUM(F15,F40,F32,(F26)) -> 2840.834 | G44: =SUM(C44:F44) -> 8060.8663
B45: CANTIDAD | C45: 500 | D45: 5000 | E45: 1300 | F45: 500
B46: COSTO UNITARIO | C46: =SUM(C44/C45) -> 3.9771675 | D46: =SUM(D44/D45) -> 0.49714594 | E46: =SUM(E44/E45) -> 0.57362993 | F46: =SUM(F44/F45) -> 5.6816679
B47: COSTO SOLES | C47: =C46*3.7 -> 14.71552 | D47: =D46*3.7 -> 1.83944 | E47: =E46*3.7 -> 2.1224308 | F47: =F46*3.7 -> 21.022171
