Workbook

Sheet 1
E3: PRO MUNDO COMEX S.A.C.
E4: RUC: 20612452432
E7: COTIZACION N002
B8: NOMBRE: | C8: MARIBEL VILMA GONZALES HUANCA | E8: SERVICIO: | F8: CARGA CONSOLIDADA | I8: N° CAJAS: | J8: =+'2'!F7 -> 0
B9: APELLIDO: | E9: FECHA: | F9: =+TODAY() -> 45917 | I9: PESO: | J9: 100 Kg
B10: DNI/RUC: | C10: 41877382 | E10: ORIGEN: | F10: CHINA | I10: MEDIDA: | J10: 0
B11: TELEFONO: | C11: 51 940 469 505 | E11: CLIENTE: | F11: NUEVO | I11: CBM | J11: 2.1
B13: CALCULO DE BASE IMPONIBLE | K13: MONTO | L13: MONEDA
B14: VALOR DE CARGA | K14: ='2'!J11 -> 215.6 | L14: USD
B15: FLETE INTERNACIONAL + SEGURO | K15: ='2'!J14 + '2'!J17 -> 20.637101 | L15: USD
B16: VALOR CIF | K16: =SUM(K14:K15) -> 236.2371 | L16: USD
B19: CALCULO DE TRIBUTOS | J19: % | K19: MONTO | L19: MONEDA
B20: ADVALOREM | J20: =MAX('2'!C26:E26) -> 0 | K20: ='2'!J28 | L20: USD | N20: Hola MARIBEL VILMA GONZALES HUANCA 😁 un gusto saludarte! A continuación te envío la cotización final de tu importación📋📦. 🙋‍♂️ PAGO PENDIENTE : ☑️Costo CBM: $735 ☑️Impuestos: $0 ☑️ Total: $735 Pronto le aviso nuevos avances, que tengan buen día🚢 Último día de pago:
B21: IGV | J21: 0.16 | K21: ='2'!J29 | L21: USD
B22: IPM | J22: 0.02 | K22: ='2'!J30 | L22: USD
B23: SUB TOTAL | K23: =SUM(K20:K22) -> 0 | L23: USD
B25: PERCEPCIÓN | J25: 3.5% | K25: ='2'!J31 -> T. CAMBIO | L25: USD
B26: TOTAL | K26: =K23+K25 -> #VALUE! | L26: USD
B28: RESUMEN DE COTIZACIÓN | K28: MONTO | L28: MONEDA
B29: VALOR DE CARGA (PAGO AL PROVEEDOR) | K29: =K14 -> 215.6 | L29: USD
B30: SERVICIO DE IMPORTACIÓN (ORIGEN -FLETE - DESTINO) | K30: =IF(J11<1, 350, 350*J11) -> 735 | L30: USD
B31: IMPUESTOS | K31: =K20+K21+K22+K25 -> #VALUE! | L31: USD
B32: MONTO TOTAL | K32: =K29+K30+K31 -> #VALUE! | L32: USD
B34: SIMULACIÓN DEL PRECIO PUESTO EN PERÚ POR PIEZA
B35: # ITEM | C35: NOMBRE PRODUCTO | F35: CANTIDAD | G35: COSTO UNI. | I35: PRECIO U. | J35: TOTAL | K35: PRECIO UNIT. (SOLES)
B36: 1 | C36: =+'2'!$C$6 -> 0 | F36: =+'2'!$C$45 -> 250 | G36: =+'2'!$C$10 -> 250 | I36: =+'2'!$C$46 -> 2.4853903 | J36: =+F36*I36 -> 621.34757 | K36: =I36*3.7 -> 9.195944
B37: 2 | C37: =+'2'!$D$6 -> 0 | F37: =+'2'!$D$45 -> 390 | G37: =+'2'!$D$10 -> 390 | I37: =+'2'!$D$46 -> 2.1401972 | J37: =+F37*I37 -> 834.6769 | K37: =I37*3.7 -> 7.9187295
B38: 3 | C38: =+'2'!$E$6 -> 0 | F38: =+'2'!$E$45 -> 199 | G38: =+'2'!$E$10 -> 199 | I38: =+'2'!$E$46 -> 2.8305834 | J38: =+F38*I38 -> 563.28609 | K38: =I38*3.7 -> 10.473158
B39: TOTAL | F39: =+SUM(F36:F38) -> 839 | J39: =+SUM(J36:J38) -> 2019.3106
B42: NOTAS:
B43: *Las fechas brindadas son estimadas, estan sujetas a variación.
B44: *No se emite comprobante por concepto de "PERCEPCIÓN, ANTI DUMPING, GESTIÓN DE COMPRA"
B45: *A nosotros se nos pagan los Gastos Logísticos + Impuestos una semana antes de que el contenedor
B46: llegue al puerto del Callao.
B47: *El tipo de cambio referencial usado para la conversión a soles es del 3.70
D50: PRO MUNDO COMEX S.A.C.
D51: RUC: 20612452432
B54: TÉRMINOS Y CONDICIONES:
B56: 1. Todos los pagos se realizan en dólares.
B57: 2.Todas las marcas de los productos deben ser verificadas por el cliente,
...

Sheet 2
B3: Calculo de Tributos
B5: Nombres | C5: GORRO CON TRENZAS PARA NIÑA | D5: SOMBRERO MODELO CON OREJITAS | E5: SOMBRERO VINTAGE PARA NIÑA | F5: SOMBRERO DE VERANO PARA NIÑAS | G5: SOMBRERO MODELO GIRASOL | H5: GORRO MODELO LAZO | I5: GORRO CON CUELLERA PARA INVIERNO | J5: GORRO DE INVIERNO MODELO CASTOR | K5: Total
B6: Peso | C6: 0 | D6: 0 | E6: 0 | F6: 0 | G6: 0 | H6: 0 | I6: 0 | J6: 0 | K6: 100 | N6: Tipo Cliente | O6: Tarifa
B7: Valor CBM | C7: 0 | D7: 0 | E7: 0 | F7: 0 | G7: 0 | H7: 0 | I7: 0 | J7: 0 | K7: 1.55 | N7: NUEVO | O7: 350
B8: Valor Unitario | C8: 1.8 | D8: 1.55 | E8: 2.05 | F8: 1.65 | G8: 2.2 | H8: 1.65 | I8: 1.334375 | J8: 1.54
B9: Valoracion | C9: 0 | D9: 0 | E9: 0 | F9: 0 | G9: 0 | H9: 0 | I9: 0 | J9: 0
B10: Cantidad | C10: 250 | D10: 390 | E10: 199 | F10: 265 | G10: 300 | H10: 275 | I10: 520 | J10: 140 | K10: =SUM(C10:J10) -> 2339
B11: Valor FOB | C11: =C8*C10 -> 450 | D11: =D8*D10 -> 604.5 | E11: =E8*E10 -> 407.95 | F11: =F8*F10 -> 437.25 | G11: =G8*G10 -> 660 | H11: =H8*H10 -> 453.75 | I11: =I8*I10 -> 693.875 | J11: =J8*J10 -> 215.6 | K11: =SUM(C11:J11) -> 3922.925
B12: Valor FOB Valoracion | C12: =C10*C9 -> 0 | D12: =D10*D9 -> 0 | E12: =E10*E9 -> 0 | F12: =F10*F9 -> 0 | G12: =G10*G9 -> 0 | H12: =H10*H9 -> 0 | I12: =I10*I9 -> 0 | J12: =J10*J9 -> 0
B13: Distribucion % | C13: =C11/K11 -> 0.11471032 | D13: =D11/K11 -> 0.1540942 | E13: =E11/K11 -> 0.10399128 | F13: =F11/K11 -> 0.1114602 | G13: =G11/K11 -> 0.16824181 | H13: =H11/K11 -> 0.11566624 | I13: =I11/K11 -> 0.17687695 | J13: =J11/K11 -> 0.054958991
B14: Flete | C14: =K14*C13 -> 37.338211 | D14: =K14*D13 -> 50.157663 | E14: =K14*E13 -> 33.849162 | F14: =K14*F13 -> 36.280295 | G14: =K14*G13 -> 54.762709 | H14: =K14*H13 -> 37.649362 | I14: =K14*I13 -> 57.573446 | J14: =K14*J13 -> 17.889152 | K14: =IF(K7<1, O7*0.6, O7*0.6*K7) -> 325.5
B15: Valor CFR | C15: =C11+C14 -> 487.33821 | D15: =D11+D14 -> 654.65766 | E15: =E11+E14 -> 441.79916 | F15: =F11+F14 -> 473.53029 | G15: =G11+G14 -> 714.76271 | H15: =H11+H14 -> 491.39936 | I15: =I11+I14 -> 751.44845 | J15: =J11+J14 -> 233.48915
B16: CFR Valorizado | C16: =C12+C14 -> 37.338211 | D16: =D12+D14 -> 50.157663 | E16: =E12+E14 -> 33.849162 | F16: =F12+F14 -> 36.280295 | G16: =G12+G14 -> 54.762709 | H16: =H12+H14 -> 37.649362 | I16: =I12+I14 -> 57.573446 | J16: =J12+J14 -> 17.889152
B17: Seguro | C17: =IF(K11>5000,100*C13,50*C13) -> 5.7355162 | D17: =IF(K11>5000,100*D13,50*D13) -> 7.7047101 | E17: =IF(K11>5000,100*E13,50*E13) -> 5.1995641 | F17: =IF(K11>5000,100*F13,50*F13) -> 5.5730099 | G17: =IF(K11>5000,100*G13,50*G13) -> 8.4120905 | H17: =IF(K11>5000,100*H13,50*H13) -> 5.7833122 | I17: =IF(K11>5000,100*I13,50*I13) -> 8.8438474 | J17: =IF(K11>5000,100*J13,50*J13) -> 2.7479496
B18: Valor CIF | C18: =C15+C17 -> 493.07373 | D18: =D15+D17 -> 662.36237 | E18: =E15+E17 -> 446.99873 | F18: =F15+F17 -> 479.1033 | G18: =G15+G17 -> 723.1748 | H18: =H15+H17 -> 497.18267 | I18: =I15+I17 -> 760.29229 | J18: =J15+J17 -> 236.2371
B19: CIF Valorizado | C19: =C16+C17 -> 43.073727 | D19: =D16+D17 -> 57.862373 | E19: =E16+E17 -> 39.048726 | F19: =F16+F17 -> 41.853305 | G19: =G16+G17 -> 63.174799 | H19: =H16+H17 -> 43.432675 | I19: =I16+I17 -> 66.417294 | J19: =J16+J17 -> 20.637101
B23: Tributos Aplicables
B26: ANTIDUMPING | C26: 0 | D26: 0 | E26: 0 | F26: 0 | G26: 0 | H26: 0 | I26: 0 | J26: 0 | K26: =SUM(C26:J26) -> 0
C27: 0 | D27: 0 | E27: 0 | F27: 0 | G27: 0 | H27: 0 | I27: 0 | J27: 0 | K27: =SUM(C27:J27) -> 0
B28: AD VALOREM | C28: =MAX(C19,C18)*C27 -> 0 | D28: =MAX(D19,D18)*D27 -> 0 | E28: =MAX(E19,E18)*E27 -> 0 | F28: =MAX(F19,F18)*F27 -> 0 | G28: =MAX(G19,G18)*G27 -> 0 | H28: =MAX(H19,H18)*H27 -> 0 | I28: =MAX(I19,I18)*I27 -> 0 | J28: =MAX(J19,J18)*J27 -> 0 | K28: =SUM(C28:J28) -> 0
B29: IGV | C29: =0.16*(MAX(C19,C18)+C28) -> 78.891796 | D29: =0.16*(MAX(D19,D18)+D28) -> 105.97798 | E29: =0.16*(MAX(E19,E18)+E28) -> 71.519796 | F29: =0.16*(MAX(F19,F18)+F28) -> 76.656529 | G29: =0.16*(MAX(G19,G18)+G28) -> 115.70797 | H29: =0.16*(MAX(H19,H18)+H28) -> 79.549228 | I29: =0.16*(MAX(I19,I18)+I28) -> 121.64677 | J29: =0.16*(MAX(J19,J18)+J28) -> 37.797936 | K29: =SUM(C29:J29) -> 687.748
B30: IPM | C30: =0.02*(MAX(C19,C18)+C28) -> 9.8614745 | D30: =0.02*(MAX(D19,D18)+D28) -> 13.247247 | E30: =0.02*(MAX(E19,E18)+E28) -> 8.9399745 | F30: =0.02*(MAX(F19,F18)+F28) -> 9.5820661 | G30: =0.02*(MAX(G19,G18)+G28) -> 14.463496 | H30: =0.02*(MAX(H19,H18)+H28) -> 9.9436535 | I30: =0.02*(MAX(I19,I18)+I28) -> 15.205846 | J30: =0.02*(MAX(J19,J18)+J28) -> 4.724742 | K30: =SUM(C30:J30) -> 85.9685
B31: PERCEPCION | C31: =0.035*(MAX(C18,C19) +C28+C29+C30) -> 20.363945 | D31: =0.035*(MAX(D18,D19) +D28+D29+D30) -> 27.355566 | E31: =0.035*(MAX(E18,E19) +E28+E29+E30) -> 18.461047 | F31: =0.035*(MAX(F18,F19) +F28+F29+F30) -> 19.786966 | G31: =0.035*(MAX(G18,G19) +G28+G29+G30) -> 29.867119 | H31: =0.035*(MAX(H18,H19) +H28+H29+H30) -> 20.533644 | I31: =0.035*(MAX(I18,I19) +I28+I29+I30) -> 31.400072 | J31: =0.035*(MAX(J18,J19) +J28+J29+J30) -> 9.7565923 | K31: =SUM(C31:J31) -> 177.52495
B32: TOTAL | C32: =SUM(C28:C31) -> 109.11722 | D32: =SUM(D28:D31) -> 146.58079 | E32: =SUM(E28:E31) -> 98.920818 | F32: =SUM(F28:F31) -> 106.02556 | G32: =SUM(G28:G31) -> 160.03858 | H32: =SUM(H28:H31) -> 110.02653 | I32: =SUM(I28:I31) -> 168.25268 | J32: =SUM(J28:J31) -> 52.27927 | K32: =SUM(K28:K31) -> 951.24145
B37: Costos Destinos
B40: ITEM | C40: =C13*K40 -> 24.89214 | D40: =D13*K40 -> 33.438442 | E40: =E13*K40 -> 22.566108 | F40: =F13*K40 -> 24.186863 | G40: =G13*K40 -> 36.508473 | H40: =H13*K40 -> 25.099575 | I40: =I13*K40 -> 38.382298 | J40: =J13*K40 -> 11.926101 | K40: =IF(K7<1, O7*0.4,O7*0.4*K7) -> 217
B43: ITEM | C43: GORRO CON TRENZAS PARA NIÑA | D43: SOMBRERO MODELO CON OREJITAS | E43: SOMBRERO VINTAGE PARA NIÑA | F43: SOMBRERO DE VERANO PARA NIÑAS | G43: SOMBRERO MODELO GIRASOL | H43: GORRO MODELO LAZO | I43: GORRO CON CUELLERA PARA INVIERNO | J43: GORRO DE INVIERNO MODELO CASTOR | K43: Total
B44: COSTO TOTAL | C44: =SUM(C15,C40,C32,(C26)) -> 621.34757 | D44: =SUM(D15,D40,D32,(D26)) -> 834.6769 | E44: =SUM(E15,E40,E32,(E26)) -> 563.28609 | F44: =SUM(F15,F40,F32,(F26)) -> 603.74272 | G44: =SUM(G15,G40,G32,(G26)) -> 911.30976 | H44: =SUM(H15,H40,H32,(H26)) -> 626.52546 | I44: =SUM(I15,I40,I32,(I26)) -> 958.08343 | J44: =SUM(J15,J40,J32,(J26)) -> 297.69452 | K44: =SUM(C44:J44) -> 5416.6665
B45: CANTIDAD | C45: 250 | D45: 390 | E45: 199 | F45: 265 | G45: 300 | H45: 275 | I45: 520 | J45: 140
B46: COSTO UNITARIO | C46: =SUM(C44/C45) -> 2.4853903 | D46: =SUM(D44/D45) -> 2.1401972 | E46: =SUM(E44/E45) -> 2.8305834 | F46: =SUM(F44/F45) -> 2.2782744 | G46: =SUM(G44/G45) -> 3.0376992 | H46: =SUM(H44/H45) -> 2.2782744 | I46: =SUM(I44/I45) -> 1.8424681 | J46: =SUM(J44/J45) -> 2.1263895
B47: COSTO SOLES | C47: =C46*3.7 -> 9.195944 | D47: =D46*3.7 -> 7.9187295 | E47: =E46*3.7 -> 10.473158 | F47: =F46*3.7 -> 8.4296153 | G47: =G46*3.7 -> 11.239487 | H47: =H46*3.7 -> 8.4296153 | I47: =I46*3.7 -> 6.8171321 | J47: =J46*3.7 -> 7.867641
