Workbook

Sheet 1
E3: PRO MUNDO COMEX S.A.C.
E4: RUC: 20612452432
E7: COTIZACION N002
B8: NOMBRE: | C8: CARLOS PINEDA GARCIA | E8: SERVICIO: | F8: CARGA CONSOLIDADA | I8: N° CAJAS: | J8: =+'2'!F7 -> 0
B9: APELLIDO: | E9: FECHA: | F9: =+TODAY() -> 45917 | I9: PESO: | J9: 524.2 Kg
B10: DNI/RUC: | C10: 20607564974 | E10: ORIGEN: | F10: CHINA | I10: MEDIDA: | J10: 0
B11: TELEFONO: | C11: 51936222770 | E11: CLIENTE: | F11: MANUAL | I11: CBM | J11: 1.5
B13: CALCULO DE BASE IMPONIBLE | K13: MONTO | L13: MONEDA
B14: VALOR DE CARGA | K14: ='2'!G11 -> 646 | L14: USD
B15: FLETE INTERNACIONAL + SEGURO | K15: ='2'!G14 + '2'!G17 -> 130.81475 | L15: USD
B16: VALOR CIF | K16: =SUM(K14:K15) -> 776.81475 | L16: USD
B19: CALCULO DE TRIBUTOS | J19: % | K19: MONTO | L19: MONEDA
B20: ADVALOREM | J20: =MAX('2'!C26:E26) -> 0 | K20: ='2'!G28 | L20: USD | N20: Hola CARLOS PINEDA GARCIA 😁 un gusto saludarte! A continuación te envío la cotización final de tu importación📋📦. 🙋‍♂️ PAGO PENDIENTE : ☑️Costo CBM: $0 ☑️Impuestos: $0 ☑️ Total: $0 Pronto le aviso nuevos avances, que tengan buen día🚢 Último día de pago:
B21: IGV | J21: 0.16 | K21: ='2'!G29 | L21: USD
B22: IPM | J22: 0.02 | K22: ='2'!G30 | L22: USD
B23: SUB TOTAL | K23: =SUM(K20:K22) -> 0 | L23: USD
B25: PERCEPCIÓN | J25: 3.5% | K25: ='2'!G31 | L25: USD
B26: TOTAL | K26: =K23+K25 -> 0 | L26: USD
B28: RESUMEN DE COTIZACIÓN | K28: MONTO | L28: MONEDA
B29: VALOR DE CARGA (PAGO AL PROVEEDOR) | K29: =K14 -> 646 | L29: USD
B30: SERVICIO DE IMPORTACIÓN (ORIGEN -FLETE - DESTINO) | K30: =IF(J11<1, '2'!G40, '2'!G40*J11) -> 0 | L30: USD
B31: IMPUESTOS | K31: =K20+K21+K22+K25 -> 0 | L31: USD
B32: MONTO TOTAL | K32: =K29+K30+K31 -> 646 | L32: USD
B34: SIMULACIÓN DEL PRECIO PUESTO EN PERÚ POR PIEZA
B35: # ITEM | C35: NOMBRE PRODUCTO | F35: CANTIDAD | G35: COSTO UNI. | I35: PRECIO U. | J35: TOTAL | K35: PRECIO UNIT. (SOLES)
B36: 1 | C36: =+'2'!$C$6 -> 0 | F36: =+'2'!$C$45 -> 96 | G36: =+'2'!$C$10 -> 96 | I36: =+'2'!$C$46 -> 8.0928052 | J36: =+F36*I36 -> 776.9093 | K36: =I36*3.7 -> 29.943379
B37: 2 | C37: =+'2'!$D$6 -> 0 | F37: =+'2'!$D$45 -> 12 | G37: =+'2'!$D$10 -> 12 | I37: =+'2'!$D$46 -> 18.379169 | J37: =+F37*I37 -> 220.55003 | K37: =I37*3.7 -> 68.002927
B38: 3 | C38: =+'2'!$E$6 -> 0 | F38: =+'2'!$E$45 -> 200 | G38: =+'2'!$E$10 -> 200 | I38: =+'2'!$E$46 -> 1.0902897 | J38: =+F38*I38 -> 218.05794 | K38: =I38*3.7 -> 4.0340719
B39: TOTAL | F39: =+SUM(F36:F38) -> 308 | J39: =+SUM(J36:J38) -> 1215.5173
B42: NOTAS:
B43: *Las fechas brindadas son estimadas, estan sujetas a variación.
B44: *No se emite comprobante por concepto de "PERCEPCIÓN, ANTI DUMPING, GESTIÓN DE COMPRA"
B45: *A nosotros se nos pagan los Gastos Logísticos + Impuestos una semana antes de que el contenedor
B46: llegue al puerto del Callao.
B47: *El tipo de cambio referencial usado para la conversión a soles es del 3.70
D50: PRO MUNDO COMEX S.A.C.
D51: RUC: 20612452432
B54: TÉRMINOS Y CONDICIONES:
B56: 1. Todos los pagos se realizan en dólares.
B57: 2.Todas las marcas de los productos deben ser verificadas por el cliente,
...

Sheet 2
B3: Calculo de Tributos
B5: Nombres | C5: ESTUCHE ORGANIZADOR PARA CONSOLAS | D5: ESTUCHE DE TRANSPORTE PARA CONSOLAS | E5: PROTECTOR DE PANTALLA PARA CONSOLAS | F5: CASE TRANSPARENTE PARA CONSOLA | G5: PROTECTOR PARA COMPUTADORAS | H5: Total
B6: Peso | C6: 0 | D6: 0 | E6: 0 | F6: 0 | G6: 0 | H6: 524.2 | K6: Tipo Cliente | L6: Tarifa
B7: Valor CBM | C7: 0 | D7: 0 | E7: 0 | F7: 0 | G7: 0 | H7: 1.4 | K7: MANUAL | L7: 376.67
B8: Valor Unitario | C8: 5.1958333 | D8: 11.8 | E8: 0.7 | F8: 2.2529412 | G8: 8.075
B9: Valoracion | C9: 0 | D9: 0 | E9: 0 | F9: 0 | G9: 0
B10: Cantidad | C10: 96 | D10: 12 | E10: 200 | F10: 170 | G10: 80 | H10: =SUM(C10:G10) -> 558
B11: Valor FOB | C11: =C8*C10 -> 498.8 | D11: =D8*D10 -> 141.6 | E11: =E8*E10 -> 140 | F11: =F8*F10 -> 383 | G11: =G8*G10 -> 646 | H11: =SUM(C11:G11) -> 1809.4
B12: Valor FOB Valoracion | C12: =C10*C9 -> 0 | D12: =D10*D9 -> 0 | E12: =E10*E9 -> 0 | F12: =F10*F9 -> 0 | G12: =G10*G9 -> 0
B13: Distribucion % | C13: =C11/H11 -> 0.27567149 | D13: =D11/H11 -> 0.078257986 | E13: =E11/H11 -> 0.077373715 | F13: =F11/H11 -> 0.21167238 | G13: =G11/H11 -> 0.35702443
B14: Flete | C14: =H14*C13 -> 87.223232 | D14: =H14*D13 -> 24.761046 | E14: =H14*E13 -> 24.48126 | F14: =H14*F13 -> 66.973733 | G14: =H14*G13 -> 112.96353 | H14: =IF(H7<1, L7*0.6, L7*0.6*H7) -> 316.4028
B15: Valor CFR | C15: =C11+C14 -> 586.02323 | D15: =D11+D14 -> 166.36105 | E15: =E11+E14 -> 164.48126 | F15: =F11+F14 -> 449.97373 | G15: =G11+G14 -> 758.96353
B16: CFR Valorizado | C16: =C12+C14 -> 87.223232 | D16: =D12+D14 -> 24.761046 | E16: =E12+E14 -> 24.48126 | F16: =F12+F14 -> 66.973733 | G16: =G12+G14 -> 112.96353
B17: Seguro | C17: =IF(H11>5000,100*C13,50*C13) -> 13.783575 | D17: =IF(H11>5000,100*D13,50*D13) -> 3.9128993 | E17: =IF(H11>5000,100*E13,50*E13) -> 3.8686858 | F17: =IF(H11>5000,100*F13,50*F13) -> 10.583619 | G17: =IF(H11>5000,100*G13,50*G13) -> 17.851221
B18: Valor CIF | C18: =C15+C17 -> 599.80681 | D18: =D15+D17 -> 170.27395 | E18: =E15+E17 -> 168.34995 | F18: =F15+F17 -> 460.55735 | G18: =G15+G17 -> 776.81475
B19: CIF Valorizado | C19: =C16+C17 -> 101.00681 | D19: =D16+D17 -> 28.673945 | E19: =E16+E17 -> 28.349946 | F19: =F16+F17 -> 77.557352 | G19: =G16+G17 -> 130.81475
B23: Tributos Aplicables
B26: ANTIDUMPING | C26: 0 | D26: 0 | E26: 0 | F26: 0 | G26: 0 | H26: =SUM(C26:G26) -> 0
C27: 0 | D27: 0 | E27: 0 | F27: 0 | G27: 0 | H27: =SUM(C27:G27) -> 0
B28: AD VALOREM | C28: =MAX(C19,C18)*C27 -> 0 | D28: =MAX(D19,D18)*D27 -> 0 | E28: =MAX(E19,E18)*E27 -> 0 | F28: =MAX(F19,F18)*F27 -> 0 | G28: =MAX(G19,G18)*G27 -> 0 | H28: =SUM(C28:G28) -> 0
B29: IGV | C29: =0.16*(MAX(C19,C18)+C28) -> 95.969089 | D29: =0.16*(MAX(D19,D18)+D28) -> 27.243831 | E29: =0.16*(MAX(E19,E18)+E28) -> 26.935991 | F29: =0.16*(MAX(F19,F18)+F28) -> 73.689176 | G29: =0.16*(MAX(G19,G18)+G28) -> 124.29036 | H29: =SUM(C29:G29) -> 348.12845
B30: IPM | C30: =0.02*(MAX(C19,C18)+C28) -> 11.996136 | D30: =0.02*(MAX(D19,D18)+D28) -> 3.4054789 | E30: =0.02*(MAX(E19,E18)+E28) -> 3.3669989 | F30: =0.02*(MAX(F19,F18)+F28) -> 9.211147 | G30: =0.02*(MAX(G19,G18)+G28) -> 15.536295 | H30: =SUM(C30:G30) -> 43.516056
B31: PERCEPCION | C31: =0.035*(MAX(C18,C19) +C28+C29+C30) -> 24.772021 | D31: =0.035*(MAX(D18,D19) +D28+D29+D30) -> 7.0323139 | E31: =0.035*(MAX(E18,E19) +E28+E29+E30) -> 6.9528528 | F31: =0.035*(MAX(F18,F19) +F28+F29+F30) -> 19.021019 | G31: =0.035*(MAX(G18,G19) +G28+G29+G30) -> 32.082449 | H31: =SUM(C31:G31) -> 89.860656
B32: TOTAL | C32: =SUM(C28:C31) -> 132.73725 | D32: =SUM(D28:D31) -> 37.681624 | E32: =SUM(E28:E31) -> 37.255843 | F32: =SUM(F28:F31) -> 101.92134 | G32: =SUM(G28:G31) -> 171.9091 | H32: =SUM(H28:H31) -> 481.50516
B37: Costos Destinos
B40: ITEM | C40: =C13*H40 -> 58.148822 | D40: =D13*H40 -> 16.507364 | E40: =E13*H40 -> 16.32084 | F40: =F13*H40 -> 44.649155 | G40: =G13*H40 -> 75.309019 | H40: =IF(H7<1, L7*0.4,L7*0.4*H7) -> 210.9352
B43: ITEM | C43: ESTUCHE ORGANIZADOR PARA CONSOLAS | D43: ESTUCHE DE TRANSPORTE PARA CONSOLAS | E43: PROTECTOR DE PANTALLA PARA CONSOLAS | F43: CASE TRANSPARENTE PARA CONSOLA | G43: PROTECTOR PARA COMPUTADORAS | H43: Total
B44: COSTO TOTAL | C44: =SUM(C15,C40,C32,(C26)) -> 776.9093 | D44: =SUM(D15,D40,D32,(D26)) -> 220.55003 | E44: =SUM(E15,E40,E32,(E26)) -> 218.05794 | F44: =SUM(F15,F40,F32,(F26)) -> 596.54423 | G44: =SUM(G15,G40,G32,(G26)) -> 1006.1817 | H44: =SUM(C44:G44) -> 2818.2432
B45: CANTIDAD | C45: 96 | D45: 12 | E45: 200 | F45: 170 | G45: 80
B46: COSTO UNITARIO | C46: =SUM(C44/C45) -> 8.0928052 | D46: =SUM(D44/D45) -> 18.379169 | E46: =SUM(E44/E45) -> 1.0902897 | F46: =SUM(F44/F45) -> 3.5090837 | G46: =SUM(G44/G45) -> 12.577271
B47: COSTO SOLES | C47: =C46*3.7 -> 29.943379 | D47: =D46*3.7 -> 68.002927 | E47: =E46*3.7 -> 4.0340719 | F47: =F46*3.7 -> 12.98361 | G47: =G46*3.7 -> 46.535901
