Workbook

Sheet 1
E3: PRO MUNDO COMEX S.A.C.
E4: RUC: 20612452432
E7: COTIZACION N002
B8: NOMBRE: | C8: LEONOR ANAYELY RIVERA SANCHEZ | E8: SERVICIO: | F8: CARGA CONSOLIDADA | I8: N° CAJAS: | J8: =+'2'!F7 -> 0
B9: APELLIDO: | E9: FECHA: | F9: =+TODAY() -> 45917 | I9: PESO: | J9: 116 Kg
B10: DNI/RUC: | E10: ORIGEN: | F10: CHINA | I10: MEDIDA: | J10: 0
B11: TELEFONO: | C11: 51 928252181 | E11: CLIENTE: | F11: ANTIGUO | I11: CBM | J11: ='2'!D7 -> 0
B13: CALCULO DE BASE IMPONIBLE | K13: MONTO | L13: MONEDA
B14: VALOR DE CARGA | K14: ='2'!D11 -> 590 | L14: USD
B15: FLETE INTERNACIONAL + SEGURO | K15: ='2'!D14 + '2'!D17 -> 146.32833 | L15: USD
B16: VALOR CIF | K16: =SUM(K14:K15) -> 736.32833 | L16: USD
B19: CALCULO DE TRIBUTOS | J19: % | K19: MONTO | L19: MONEDA
B20: ADVALOREM | J20: =MAX('2'!C26:E26) -> 0 | K20: ='2'!D28 -> 44.1797 | L20: USD | N20: Hola LEONOR ANAYELY RIVERA SANCHEZ 😁 un gusto saludarte! A continuación te envío la cotización final de tu importación📋📦. 🙋‍♂️ PAGO PENDIENTE : ☑️Costo CBM: $350 ☑️Impuestos: $4.68 ☑️ Total: $354.68 Pronto le aviso nuevos avances, que tengan buen día🚢 Último día de pago:
B21: IGV | J21: 0.16 | K21: ='2'!D29 -> 124.88129 | L21: USD
B22: IPM | J22: 0.02 | K22: ='2'!D30 -> 15.610161 | L22: USD
B23: SUB TOTAL | K23: =SUM(K20:K22) -> 184.67115 | L23: USD
B25: PERCEPCIÓN | J25: 3.5% | K25: ='2'!D31 -> 32.234982 | L25: USD
B26: TOTAL | K26: =K23+K25 -> 216.90613 | L26: USD
B28: RESUMEN DE COTIZACIÓN | K28: MONTO | L28: MONEDA
B29: VALOR DE CARGA (PAGO AL PROVEEDOR) | K29: =K14 -> 590 | L29: USD
B30: SERVICIO DE IMPORTACIÓN (ORIGEN -FLETE - DESTINO) | K30: =IF(J11<1, 350, 350*J11) -> 350 | L30: USD
B31: IMPUESTOS | K31: =K20+K21+K22+K25 -> 216.90613 | L31: USD
B32: MONTO TOTAL | K32: =K29+K30+K31 -> 1156.9061 | L32: USD
B34: SIMULACIÓN DEL PRECIO PUESTO EN PERÚ POR PIEZA
B35: # ITEM | C35: NOMBRE PRODUCTO | F35: CANTIDAD | G35: COSTO UNI. | I35: PRECIO U. | J35: TOTAL | K35: PRECIO UNIT. (SOLES)
B36: 1 | C36: PISTOLA DE AGUA PARA INODORO | F36: ='2'!C10 -> 120 | G36: ='2'!C8 -> 4.525 | I36: ='2'!C46 -> 7.3123609 | J36: ='2'!C44 -> 877.4833 | K36: ='2'!C47 -> 27.055735
B37: 2 | C37: ORGANIZADOR DE BAÑO SET DE 5 | F37: ='2'!D10 -> 100 | G37: ='2'!D8 -> 5.9 | I37: ='2'!D46 -> 10.073916 | J37: ='2'!D44 -> 1007.3916 | K37: ='2'!D47 -> 37.273488
B38: TOTAL | F38: =SUM(F36:F37) -> 220 | J38: =SUM(J36:J37) -> 1884.8749
B42: NOTAS:
B43: *Las fechas brindadas son estimadas, estan sujetas a variación.
B44: *No se emite comprobante por concepto de "PERCEPCIÓN, ANTI DUMPING, GESTIÓN DE COMPRA"
B45: *A nosotros se nos pagan los Gastos Logísticos + Impuestos una semana antes de que el contenedor
B46: llegue al puerto del Callao.
B47: *El tipo de cambio referencial usado para la conversión a soles es del 3.70
D50: PRO MUNDO COMEX S.A.C.
D51: RUC: 20612452432
B54: TÉRMINOS Y CONDICIONES:
B56: 1. Todos los pagos se realizan en dólares.
B57: 2.Todas las marcas de los productos deben ser verificadas por el cliente,
B58: No se aceptan marcas con medidas de frontera.
...

Sheet 2
B3: Calculo de Tributos
B5: Nombres | C5: PISTOLA DE AGUA PARA INODORO | D5: ORGANIZADOR DE BAÑO SET DE 5 | E5: Total
B6: Peso | C6: 0 | D6: 0 | E6: 116 | H6: Tipo Cliente | I6: Tarifa
B7: Valor CBM | C7: 0 | D7: 0 | E7: 1.1 | H7: ANTIGUO | I7: 350
B8: Valor Unitario | C8: 4.525 | D8: 5.9
B9: Valoracion | C9: 0 | D9: 0
B10: Cantidad | C10: 120 | D10: 100 | E10: =SUM(C10:D10) -> 220
B11: Valor FOB | C11: =C8*C10 -> 543 | D11: =D8*D10 -> 590 | E11: =SUM(C11:D11) -> 1133
B12: Valor FOB Valoracion | C12: =C10*C9 -> 0 | D12: =D10*D9 -> 0
B13: Distribucion % | C13: =C11/E11 -> 0.47925861 | D13: =D11/E11 -> 0.52074139
B14: Flete | C14: =E14*C13 -> 110.70874 | D14: =E14*D13 -> 120.29126 | E14: =IF(E7<1, I7*0.6, I7*0.6*E7) -> 231
B15: Valor CFR | C15: =C11+C14 -> 653.70874 | D15: =D11+D14 -> 710.29126
B16: CFR Valorizado | C16: =C12+C14 -> 110.70874 | D16: =D12+D14 -> 120.29126
B17: Seguro | C17: =IF(E11>5000,100*C13,50*C13) -> 23.96293 | D17: =IF(E11>5000,100*D13,50*D13) -> 26.03707
B18: Valor CIF | C18: =C15+C17 -> 677.67167 | D18: =D15+D17 -> 736.32833
B19: CIF Valorizado | C19: =C16+C17 -> 134.67167 | D19: =D16+D17 -> 146.32833
B23: Tributos Aplicables
B26: ANTIDUMPING | C26: 0 | D26: 0 | E26: =SUM(C26:D26) -> 0
C27: 0 | D27: 0.06 | E27: =SUM(C27:D27) -> 0.06
B28: AD VALOREM | C28: =MAX(C19,C18)*C27 -> 0 | D28: =MAX(D19,D18)*D27 -> 44.1797 | E28: =SUM(C28:D28) -> 44.1797
B29: IGV | C29: =0.16*(MAX(C19,C18)+C28) -> 108.42747 | D29: =0.16*(MAX(D19,D18)+D28) -> 124.88129 | E29: =SUM(C29:D29) -> 233.30875
B30: IPM | C30: =0.02*(MAX(C19,C18)+C28) -> 13.553433 | D30: =0.02*(MAX(D19,D18)+D28) -> 15.610161 | E30: =SUM(C30:D30) -> 29.163594
B31: PERCEPCION | C31: =0.035*(MAX(C18,C19) +C28+C29+C30) -> 27.98784 | D31: =0.035*(MAX(D18,D19) +D28+D29+D30) -> 32.234982 | E31: =SUM(C31:D31) -> 60.222822
B32: TOTAL | C32: =SUM(C28:C31) -> 149.96874 | D32: =SUM(D28:D31) -> 216.90613 | E32: =SUM(E28:E31) -> 366.87487
B37: Costos Destinos
B40: ITEM | C40: =C13*E40 -> 73.805825 | D40: =D13*E40 -> 80.194175 | E40: =IF(E7<1, I7*0.4,I7*0.4*E7) -> 154
B43: ITEM | C43: PISTOLA DE AGUA PARA INODORO | D43: ORGANIZADOR DE BAÑO SET DE 5 | E43: Total
B44: COSTO TOTAL | C44: =SUM(C15,C40,C32,(C26)) -> 877.4833 | D44: =SUM(D15,D40,D32,(D26)) -> 1007.3916 | E44: =SUM(C44:D44) -> 1884.8749
B45: CANTIDAD | C45: 120 | D45: 100
B46: COSTO UNITARIO | C46: =SUM(C44/C45) -> 7.3123609 | D46: =SUM(D44/D45) -> 10.073916
B47: COSTO SOLES | C47: =C46*3.7 -> 27.055735 | D47: =D46*3.7 -> 37.273488
