Workbook

Sheet 1
E3: PRO MUNDO COMEX S.A.C.
E4: RUC: 20612452432
E7: COTIZACION N002
B8: NOMBRE: | C8: ANDERSON HANS MORI | E8: SERVICIO: | F8: CARGA CONSOLIDADA | I8: N° CAJAS: | J8: =+'2'!F7 -> 0
B9: APELLIDO: | E9: FECHA: | F9: =+TODAY() -> 45917 | I9: PESO: | J9: 1.04 Tn
B10: DNI/RUC: | C10: 47434498 | E10: ORIGEN: | F10: CHINA | I10: MEDIDA: | J10: 0
B11: TELEFONO: | C11: 51948537604 | E11: CLIENTE: | F11: NUEVO | I11: CBM | J11: 2
B13: CALCULO DE BASE IMPONIBLE | K13: MONTO | L13: MONEDA
B14: VALOR DE CARGA | K14: ='2'!C11 -> 4100 | L14: USD
B15: FLETE INTERNACIONAL + SEGURO | K15: ='2'!C14 + '2'!C17 -> 1440.0765 | L15: USD
B16: VALOR CIF | K16: =SUM(K14:K15) -> 5540.0765 | L16: USD
B19: CALCULO DE TRIBUTOS | J19: % | K19: MONTO | L19: MONEDA
B20: ADVALOREM | J20: =MAX('2'!C26:E26) -> 0 | K20: ='2'!C28 -> 139.40358 | L20: USD | N20: Hola ANDERSON HANS MORI 😁 un gusto saludarte! A continuación te envío la cotización final de tu importación📋📦. 🙋‍♂️ PAGO PENDIENTE : ☑️Costo CBM: $0 ☑️Impuestos: $419.14 ☑️ Total: $419.14 Pronto le aviso nuevos avances, que tengan buen día🚢 Último día de pago:
B21: IGV | J21: 0.16 | K21: ='2'!C29 -> 17.425447 | L21: USD
B22: IPM | J22: 0.02 | K22: ='2'!C30 -> 35.983549 | L22: USD
B23: SUB TOTAL | K23: =SUM(K20:K22) -> 192.81258 | L23: USD
B25: PERCEPCIÓN | J25: 3.5% | K25: ='2'!C31 -> 226.32305 | L25: USD
B26: TOTAL | K26: =K23+K25 -> 419.13563 | L26: USD
B28: RESUMEN DE COTIZACIÓN | K28: MONTO | L28: MONEDA
B29: VALOR DE CARGA (PAGO AL PROVEEDOR) | K29: =K14 -> 4100 | L29: USD
B30: SERVICIO DE IMPORTACIÓN (ORIGEN -FLETE - DESTINO) | K30: =IF(J11<1, '2'!C40, '2'!C40*J11) -> 0 | L30: USD
B31: IMPUESTOS | K31: =K20+K21+K22+K25 -> 419.13563 | L31: USD
B32: MONTO TOTAL | K32: =K29+K30+K31 -> 4519.1356 | L32: USD
B34: SIMULACIÓN DEL PRECIO PUESTO EN PERÚ POR PIEZA
B35: # ITEM | C35: NOMBRE PRODUCTO | F35: CANTIDAD | G35: COSTO UNI. | I35: PRECIO U. | J35: TOTAL | K35: PRECIO UNIT. (SOLES)
B36: 1 | C36: =+'2'!$C$6 -> 0 | F36: =+'2'!$C$45 -> 2000 | G36: =+'2'!$C$10 -> 2000 | I36: =+'2'!$C$46 -> 92.270905 | J36: =+F36*I36 -> 184541.81 | K36: =I36*3.7 -> 341.40235
B37: 2 | C37: =+'2'!$D$6 -> 1.04 | F37: =+'2'!$D$45 | G37: =+'2'!$D$10 -> 2000 | I37: =+'2'!$D$46 | J37: =+F37*I37 -> 0 | K37: =I37*3.7 -> 0
B38: 3 | C38: =+'2'!$E$6 -> 0 | F38: =+'2'!$E$45 -> 0 | G38: =+'2'!$E$10 -> 0 | I38: =+'2'!$E$46 -> 0 | J38: =+F38*I38 -> 0 | K38: =I38*3.7 -> 0
B39: TOTAL | F39: =+SUM(F36:F38) -> 2000 | J39: =+SUM(J36:J38) -> 184541.81
B42: NOTAS:
B43: *Las fechas brindadas son estimadas, estan sujetas a variación.
B44: *No se emite comprobante por concepto de "PERCEPCIÓN, ANTI DUMPING, GESTIÓN DE COMPRA"
B45: *A nosotros se nos pagan los Gastos Logísticos + Impuestos una semana antes de que el contenedor
B46: llegue al puerto del Callao.
B47: *El tipo de cambio referencial usado para la conversión a soles es del 3.70
D50: PRO MUNDO COMEX S.A.C.
D51: RUC: 20612452432
B54: TÉRMINOS Y CONDICIONES:
B56: 1. Todos los pagos se realizan en dólares.
B57: 2.Todas las marcas de los productos deben ser verificadas por el cliente,
...

Sheet 2
B3: Calculo de Tributos
B5: Nombres | C5: BOLAS ACRILICAS PARA BISUTERIA | D5: Total
B6: Peso | C6: 0 | D6: 1.04 | G6: Tipo Cliente | H6: Tarifa
B7: Valor CBM | C7: 0 | D7: 1.93 | G7: NUEVO | H7: 375
B8: Valor Unitario | C8: 2.05
B9: Valoracion | C9: 0
B10: Cantidad | C10: 2000 | D10: =SUM(C10:C10) -> 2000
B11: Valor FOB | C11: =C8*C10 -> 4100 | D11: =SUM(C11:C11) -> 4100
B12: Valor FOB Valoracion | C12: =C10*C9 -> 0
B13: Distribucion % | C13: =C11/D11 -> 636
B14: Flete | C14: =D14*C13 -> 636 | D14: =IF(D7<1, H7*0.6, H7*0.6*D7) -> 434.25
B15: Valor CFR | C15: =C11+C14 -> 0.6737074
B16: CFR Valorizado | C16: =C12+C14 -> 168.07652
B17: Seguro | C17: =IF(D11>5000,100*C13,50*C13) -> 804.07652
B18: Valor CIF | C18: =C15+C17 -> 804.07652
B19: CIF Valorizado | C19: =C16+C17 -> 33.68537
B23: Tributos Aplicables
B26: ANTIDUMPING | C26: 0 | D26: =SUM(C26:C26) -> 0
C27: 0 | D27: =SUM(C27:C27) -> 0
B28: AD VALOREM | C28: =MAX(C19,C18)*C27 -> 139.40358 | D28: =SUM(C28:C28) -> 139.40358
B29: IGV | C29: =0.16*(MAX(C19,C18)+C28) -> 17.425447 | D29: =SUM(C29:C29) -> 17.425447
B30: IPM | C30: =0.02*(MAX(C19,C18)+C28) -> 35.983549 | D30: =SUM(C30:C30) -> 35.983549
B31: PERCEPCION | C31: =0.035*(MAX(C18,C19) +C28+C29+C30) -> 226.32305 | D31: =SUM(C31:C31) -> 226.32305
B32: TOTAL | C32: =SUM(C28:C31) -> 419.13563 | D32: =SUM(D28:D31) -> 419.13563
B37: Costos Destinos
B40: ITEM | C40: =C13*D40 -> 184122 | D40: =IF(D7<1, H7*0.4,H7*0.4*D7) -> 289.5
B43: ITEM | C43: BOLAS ACRILICAS PARA BISUTERIA | D43: Total
B44: COSTO TOTAL | C44: =SUM(C15,C40,C32,(C26)) -> 184541.81 | D44: =SUM(C44:C44) -> 184541.81
B45: CANTIDAD | C45: 2000
B46: COSTO UNITARIO | C46: =SUM(C44/C45) -> 92.270905
B47: COSTO SOLES | C47: =C46*3.7 -> 341.40235
