Workbook

Sheet 1
E3: PRO MUNDO COMEX S.A.C.
E4: RUC: 20612452432
E7: COTIZACION N002
B8: NOMBRE: | C8: CESAR ANTONIO ORTIZ OCAMPO | E8: SERVICIO: | F8: CARGA CONSOLIDADA | I8: N° CAJAS: | J8: =+'2'!F7 -> 0
B9: APELLIDO: | E9: FECHA: | F9: =+TODAY() -> 45917 | I9: PESO: | J9: 1.227 Tn
B10: DNI/RUC: | C10: 41842422 | E10: ORIGEN: | F10: CHINA | I10: MEDIDA: | J10: 0
B11: TELEFONO: | C11: 51 997 412 500 | E11: CLIENTE: | F11: MANUAL | I11: CBM | J11: 2.65
B13: CALCULO DE BASE IMPONIBLE | K13: MONTO | L13: MONEDA
B14: VALOR DE CARGA | K14: ='2'!N11 -> 180 | L14: USD
B15: FLETE INTERNACIONAL + SEGURO | K15: ='2'!N14 + '2'!N17 -> 32.237774 | L15: USD
B16: VALOR CIF | K16: =SUM(K14:K15) -> 212.23777 | L16: USD
B19: CALCULO DE TRIBUTOS | J19: % | K19: MONTO | L19: MONEDA
B20: ADVALOREM | J20: =MAX('2'!C26:E26) -> 15.75 | K20: ='2'!N28 -> 0 | L20: USD | N20: Hola CESAR ANTONIO ORTIZ OCAMPO 😁 un gusto saludarte! A continuación te envío la cotización final de tu importación📋📦. 🙋‍♂️ PAGO PENDIENTE : ☑️Costo CBM: $0 ☑️Impuestos: $0 ☑️ Total: $0 Pronto le aviso nuevos avances, que tengan buen día🚢 Último día de pago:
B21: IGV | J21: 0.16 | K21: ='2'!N29 -> 33.958044 | L21: USD
B22: IPM | J22: 0.02 | K22: ='2'!N30 | L22: USD
B23: SUB TOTAL | K23: =SUM(K20:K22) -> 0 | L23: USD
B25: PERCEPCIÓN | J25: 3.5% | K25: ='2'!N31 | L25: USD
B26: TOTAL | K26: =K23+K25 -> 0 | L26: USD
B28: RESUMEN DE COTIZACIÓN | K28: MONTO | L28: MONEDA
B29: VALOR DE CARGA (PAGO AL PROVEEDOR) | K29: =K14 -> 180 | L29: USD
B30: SERVICIO DE IMPORTACIÓN (ORIGEN -FLETE - DESTINO) | K30: =IF(J11<1, '2'!N14, '2'!N14*J11) -> 0 | L30: USD
B31: IMPUESTOS | K31: =K26 -> 0 | L31: USD
B32: MONTO TOTAL | K32: =SUM(K29:K31) -> 180 | L32: USD
B34: SIMULACIÓN DEL PRECIO PUESTO EN PERÚ POR PIEZA
B35: # ITEM | C35: NOMBRE PRODUCTO | F35: CANTIDAD | G35: COSTO UNI. | I35: PRECIO U. | J35: TOTAL | K35: PRECIO UNIT. (SOLES)
B36: 1 | C36: =+'2'!$C$6 -> 0 | F36: =+'2'!$C$45 -> 2 | G36: =+'2'!$C$10 -> 2 | I36: =+'2'!$C$46 -> 5.0897247 | J36: =+F36*I36 -> 10.179449 | K36: =I36*3.7 -> 18.831981
B37: 2 | C37: =+'2'!$D$6 -> 0 | F37: =+'2'!$D$45 -> 25 | G37: =+'2'!$D$10 -> 25 | I37: =+'2'!$D$46 -> 34.629361 | J37: =+F37*I37 -> 865.73403 | K37: =I37*3.7 -> 128.12864
B38: 3 | C38: =+'2'!$E$6 -> 0 | F38: =+'2'!$E$45 -> 16 | G38: =+'2'!$E$10 -> 16 | I38: =+'2'!$E$46 -> 29.259701 | J38: =+F38*I38 -> 468.15522 | K38: =I38*3.7 -> 108.2609
B39: TOTAL | F39: =+SUM(F36:F38) -> 43 | J39: =+SUM(J36:J38) -> 1344.0687
B42: NOTAS:
B43: *Las fechas brindadas son estimadas, estan sujetas a variación.
B44: *No se emite comprobante por concepto de "PERCEPCIÓN, ANTI DUMPING, GESTIÓN DE COMPRA"
B45: *A nosotros se nos pagan los Gastos Logísticos + Impuestos una semana antes de que el contenedor
B46: llegue al puerto del Callao.
B47: *El tipo de cambio referencial usado para la conversión a soles es del 3.70
D50: PRO MUNDO COMEX S.A.C.
D51: RUC: 20612452432
B54: TÉRMINOS Y CONDICIONES:
B56: 1. Todos los pagos se realizan en dólares.
B57: 2.Todas las marcas de los productos deben ser verificadas por el cliente,
...

Sheet 2
B3: Calculo de Tributos
B5: Nombres | C5: MUÑEQUERAS PARA LEVANTAMIENTO DE PESAS | D5: ZAPATILLAS PARA BOXEO | E5: ZAPATILLAS PARA HALTEROFILIA | F5: CINTURON PARA LEVANTAMIENTO DE PESO | G5: MALETIN PARA GIMNASIO | H5: MOCHILA PARA GIMNASIO | I5: ZAPATILLA PARA GIMNASIO | J5: RODILLERAS PARA HALTEROFILIA | K5: BARRA OLÍMPICA PARA GIMNASIO | L5: KIT DE DISCOS PARA PESAS | M5: RACK PARA ALZAR PESAS JK-01 | N5: MÁQUINA DE GIMNASIO PARA SENTADILLAS | O5: Total
B6: Peso | C6: 0 | D6: 0 | E6: 0 | F6: 0 | G6: 0 | H6: 0 | I6: 0 | J6: 0 | K6: 0 | L6: 0 | M6: 0 | N6: 0 | O6: 1.23 | R6: Tipo Cliente | S6: Tarifa
B7: Valor CBM | C7: 0 | D7: 0 | E7: 0 | F7: 0 | G7: 0 | H7: 0 | I7: 0 | J7: 0 | K7: 0 | L7: 0 | M7: 0 | N7: 0 | O7: 3.16 | R7: MANUAL | S7: 343.87
B8: Valor Unitario | C8: 3 | D8: 20.04 | E8: 16.875 | F8: 30 | G8: 5 | H8: 30 | I8: 8.4658385 | J8: 9 | K8: 50 | L8: 17.015625 | M8: 300 | N8: 180
B9: Valoracion | C9: 0 | D9: 0 | E9: 0 | F9: 0 | G9: 0 | H9: 0 | I9: 0 | J9: 0 | K9: 0 | L9: 0 | M9: 0 | N9: 0
B10: Cantidad | C10: 2 | D10: 25 | E10: 16 | F10: 2 | G10: 20 | H10: 2 | I10: 161 | J10: 15 | K10: 8 | L10: 32 | M10: 1 | N10: 1 | O10: =SUM(C10:N10) -> 285
B11: Valor FOB | C11: =C8*C10 -> 6 | D11: =D8*D10 -> 501 | E11: =E8*E10 -> 270 | F11: =F8*F10 -> 60 | G11: =G8*G10 -> 100 | H11: =H8*H10 -> 60 | I11: =I8*I10 -> 1363 | J11: =J8*J10 -> 135 | ... N11: =N8*N10 -> 180 | O11: =SUM(C11:N11) -> 3919.5
B12: Valor FOB Valoracion | C12: =C10*C9 -> 0 | D12: =D10*D9 -> 0 | E12: =E10*E9 -> 0 | F12: =F10*F9 -> 0 | G12: =G10*G9 -> 0 | H12: =H10*H9 -> 0 | I12: =I10*I9 -> 0 | J12: =J10*J9 -> 0 | ... N12: =N10*N9 -> 0
B13: Distribucion % | C13: =C11/O11 -> 0.0015308075 | D13: =D11/O11 -> 0.12782243 | E13: =E11/O11 -> 0.068886338 | F13: =F11/O11 -> 0.015308075 | G13: =G11/O11 -> 0.025513458 | H13: =H11/O11 -> 0.015308075 | I13: =I11/O11 -> 0.34774844 | J13: =J11/O11 -> 0.034443169 | K13: =K11/O11 -> 0.10205383 | L13: =L11/O11 -> 0.13892078 | M13: =M11/O11 -> 0.076540375 | N13: =N11/O11 -> 0.045924225
B14: Flete | C14: =O14*C13 -> 0.99805208 | D14: =O14*D13 -> 83.337349 | E14: =O14*E13 -> 44.912344 | F14: =O14*F13 -> 9.9805208 | G14: =O14*G13 -> 16.634201 | H14: =O14*H13 -> 9.9805208 | I14: =O14*I13 -> 226.72416 | J14: =O14*J13 -> 22.456172 | K14: =O14*K13 -> 66.536805 | L14: =O14*L13 -> 90.573226 | M14: =O14*M13 -> 49.902604 | N14: =O14*N13 -> 29.941562 | O14: =IF(O7<1, S7*0.6, S7*0.6*O7) -> 651.97752
B15: Valor CFR | C15: =C11+C14 -> 6.9980521 | D15: =D11+D14 -> 584.33735 | E15: =E11+E14 -> 314.91234 | F15: =F11+F14 -> 69.980521 | G15: =G11+G14 -> 116.6342 | H15: =H11+H14 -> 69.980521 | I15: =I11+I14 -> 1589.7242 | J15: =J11+J14 -> 157.45617 | ... N15: =N11+N14 -> 209.94156
B16: CFR Valorizado | C16: =C12+C14 -> 0.99805208 | D16: =D12+D14 -> 83.337349 | E16: =E12+E14 -> 44.912344 | F16: =F12+F14 -> 9.9805208 | G16: =G12+G14 -> 16.634201 | H16: =H12+H14 -> 9.9805208 | I16: =I12+I14 -> 226.72416 | J16: =J12+J14 -> 22.456172 | ... N16: =N12+N14 -> 29.941562
B17: Seguro | C17: =IF(O11>5000,100*C13,50*C13) -> 0.076540375 | D17: =IF(O11>5000,100*D13,50*D13) -> 6.3911213 | E17: =IF(O11>5000,100*E13,50*E13) -> 3.4443169 | F17: =IF(O11>5000,100*F13,50*F13) -> 0.76540375 | G17: =IF(O11>5000,100*G13,50*G13) -> 1.2756729 | H17: =IF(O11>5000,100*H13,50*H13) -> 0.76540375 | I17: =IF(O11>5000,100*I13,50*I13) -> 17.387422 | J17: =IF(O11>5000,100*J13,50*J13) -> 1.7221584 | K17: =IF(O11>5000,100*K13,50*K13) -> 5.1026917 | L17: =IF(O11>5000,100*L13,50*L13) -> 6.946039 | M17: =IF(O11>5000,100*M13,50*M13) -> 3.8270188 | N17: =IF(O11>5000,100*N13,50*N13) -> 2.2962113
B18: Valor CIF | C18: =C15+C17 -> 7.0745925 | D18: =D15+D17 -> 590.72847 | E18: =E15+E17 -> 318.35666 | F18: =F15+F17 -> 70.745925 | G18: =G15+G17 -> 117.90987 | H18: =H15+H17 -> 70.745925 | I18: =I15+I17 -> 1607.1116 | J18: =J15+J17 -> 159.17833 | ... N18: =N15+N17 -> 212.23777
B19: CIF Valorizado | C19: =C16+C17 -> 1.0745925 | D19: =D16+D17 -> 89.72847 | E19: =E16+E17 -> 48.35666 | F19: =F16+F17 -> 10.745925 | G19: =G16+G17 -> 17.909874 | H19: =H16+H17 -> 10.745925 | I19: =I16+I17 -> 244.11159 | J19: =J16+J17 -> 24.17833 | ... N19: =N16+N17 -> 32.237774
B23: Tributos Aplicables
B26: ANTIDUMPING | C26: 0 | D26: =D10*0.63 -> 15.75 | E26: =E10*0.63 -> 10.08 | F26: 0 | G26: 0 | H26: 0 | I26: =I10*0.63 -> 101.43 | J26: 0 | K26: 0 | L26: 0 | M26: 0 | N26: 0 | O26: =SUM(C26:N26) -> 127.26
C27: 0.11 | D27: 0.11 | E27: 0.11 | F27: 0.06 | G27: 0 | H27: 0.06 | I27: 0.11 | J27: 0.11 | K27: 0 | L27: 0 | M27: 0 | N27: 0 | O27: =SUM(C27:N27) -> 0.67
B28: AD VALOREM | C28: =MAX(C19,C18)*C27 -> 0.77820517 | D28: =MAX(D19,D18)*D27 -> 64.980132 | E28: =MAX(E19,E18)*E27 -> 35.019233 | F28: =MAX(F19,F18)*F27 -> 4.2447555 | G28: =MAX(G19,G18)*G27 -> 0 | H28: =MAX(H19,H18)*H27 -> 4.2447555 | I28: =MAX(I19,I18)*I27 -> 176.78227 | J28: =MAX(J19,J18)*J27 -> 17.509616 | ... N28: =MAX(N19,N18)*N27 -> 0 | O28: =SUM(C28:N28) -> 303.55897
B29: IGV | C29: =0.16*(MAX(C19,C18)+C28) -> 1.2564476 | D29: =0.16*(MAX(D19,D18)+D28) -> 104.91338 | E29: =0.16*(MAX(E19,E18)+E28) -> 56.540143 | F29: =0.16*(MAX(F19,F18)+F28) -> 11.998509 | G29: =0.16*(MAX(G19,G18)+G28) -> 18.86558 | H29: =0.16*(MAX(H19,H18)+H28) -> 11.998509 | I29: =0.16*(MAX(I19,I18)+I28) -> 285.42302 | J29: =0.16*(MAX(J19,J18)+J28) -> 28.270071 | ... N29: =0.16*(MAX(N19,N18)+N28) -> 33.958044 | O29: =SUM(C29:N29) -> 788.00584
B30: IPM | C30: =0.02*(MAX(C19,C18)+C28) -> 0.15705595 | D30: =0.02*(MAX(D19,D18)+D28) -> 13.114172 | E30: =0.02*(MAX(E19,E18)+E28) -> 7.0675179 | F30: =0.02*(MAX(F19,F18)+F28) -> 1.4998136 | G30: =0.02*(MAX(G19,G18)+G28) -> 2.3581975 | H30: =0.02*(MAX(H19,H18)+H28) -> 1.4998136 | I30: =0.02*(MAX(I19,I18)+I28) -> 35.677877 | J30: =0.02*(MAX(J19,J18)+J28) -> 3.5337589 | ... N30: =0.02*(MAX(N19,N18)+N28) -> 4.2447555 | O30: =SUM(C30:N30) -> 98.50073
B31: PERCEPCION | C31: =0.035*(MAX(C18,C19) +C28+C29+C30) -> 0.32432054 | D31: =0.035*(MAX(D18,D19) +D28+D29+D30) -> 27.080765 | E31: =0.035*(MAX(E18,E19) +E28+E29+E30) -> 14.594424 | F31: =0.035*(MAX(F18,F19) +F28+F29+F30) -> 3.0971151 | G31: =0.035*(MAX(G18,G19) +G28+G29+G30) -> 4.8696778 | H31: =0.035*(MAX(H18,H19) +H28+H29+H30) -> 3.0971151 | I31: =0.035*(MAX(I18,I19) +I28+I29+I30) -> 73.674816 | J31: =0.035*(MAX(J18,J19) +J28+J29+J30) -> 7.2972122 | ... N31: =0.035*(MAX(N18,N19) +N28+N29+N30) -> 8.76542 | O31: =SUM(C31:N31) -> 203.40401
B32: TOTAL | C32: =SUM(C28:C31) -> 2.5160293 | D32: =SUM(D28:D31) -> 210.08845 | E32: =SUM(E28:E31) -> 113.22132 | F32: =SUM(F28:F31) -> 20.840193 | G32: =SUM(G28:G31) -> 26.093455 | H32: =SUM(H28:H31) -> 20.840193 | I32: =SUM(I28:I31) -> 571.55799 | J32: =SUM(J28:J31) -> 56.610659 | ... O32: =SUM(O28:O31) -> 1393.4695
B37: Costos Destinos
B40: ITEM | C40: =C13*O40 -> 0.66536805 | D40: =D13*O40 -> 55.558232 | E40: =E13*O40 -> 29.941562 | F40: =F13*O40 -> 6.6536805 | G40: =G13*O40 -> 11.089468 | H40: =H13*O40 -> 6.6536805 | I40: =I13*O40 -> 151.14944 | J40: =J13*O40 -> 14.970781 | K40: =K13*O40 -> 44.35787 | L40: =L13*O40 -> 60.382151 | M40: =M13*O40 -> 33.268403 | N40: =N13*O40 -> 19.961042 | O40: =IF(O7<1, S7*0.4,S7*0.4*O7) -> 434.65168
B43: ITEM | C43: MUÑEQUERAS PARA LEVANTAMIENTO DE PESAS | D43: ZAPATILLAS PARA BOXEO | E43: ZAPATILLAS PARA HALTEROFILIA | F43: CINTURON PARA LEVANTAMIENTO DE PESO | G43: MALETIN PARA GIMNASIO | H43: MOCHILA PARA GIMNASIO | I43: ZAPATILLA PARA GIMNASIO | J43: RODILLERAS PARA HALTEROFILIA | K43: BARRA OLÍMPICA PARA GIMNASIO | L43: KIT DE DISCOS PARA PESAS | M43: RACK PARA ALZAR PESAS JK-01 | N43: MÁQUINA DE GIMNASIO PARA SENTADILLAS | O43: Total
B44: COSTO TOTAL | C44: =SUM(C15,C40,C32,(C26)) -> 10.179449 | D44: =SUM(D15,D40,D32,(D26)) -> 865.73403 | E44: =SUM(E15,E40,E32,(E26)) -> 468.15522 | F44: =SUM(F15,F40,F32,(F26)) -> 97.474394 | G44: =SUM(G15,G40,G32,(G26)) -> 153.81712 | H44: =SUM(H15,H40,H32,(H26)) -> 97.474394 | I44: =SUM(I15,I40,I32,(I26)) -> 2413.8616 | J44: =SUM(J15,J40,J32,(J26)) -> 229.03761 | ... N44: =SUM(N15,N40,N32,(N26)) -> 276.87082 | O44: =SUM(C44:N44) -> 6526.8587
B45: CANTIDAD | C45: 2 | D45: 25 | E45: 16 | F45: 2 | G45: 20 | H45: 2 | I45: 161 | J45: 15 | K45: 8 | L45: 32 | M45: 1 | N45: 1
B46: COSTO UNITARIO | C46: =SUM(C44/C45) -> 5.0897247 | D46: =SUM(D44/D45) -> 34.629361 | E46: =SUM(E44/E45) -> 29.259701 | F46: =SUM(F44/F45) -> 48.737197 | G46: =SUM(G44/G45) -> 7.6908562 | H46: =SUM(H44/H45) -> 48.737197 | I46: =SUM(I44/I45) -> 14.992929 | J46: =SUM(J44/J45) -> 15.269174 | ... N46: =SUM(N44/N45) -> 276.87082
B47: COSTO SOLES | C47: =C46*3.7 -> 18.831981 | D47: =D46*3.7 -> 128.12864 | E47: =E46*3.7 -> 108.2609 | F47: =F46*3.7 -> 180.32763 | G47: =G46*3.7 -> 28.456168 | H47: =H46*3.7 -> 180.32763 | I47: =I46*3.7 -> 55.473838 | J47: =J46*3.7 -> 56.495944 | ... N47: =N46*3.7 -> 1024.422
