Workbook

Sheet 1
E3: PRO MUNDO COMEX S.A.C.
E4: RUC: 20612452432
E7: COTIZACION N002
B8: NOMBRE: | C8: ANTHONY ROCCA CAQUI 2 | E8: SERVICIO: | F8: CARGA CONSOLIDADA | I8: N° CAJAS: | J8: =+'2'!F7 -> 0
B9: APELLIDO: | E9: FECHA: | F9: =+TODAY() -> 45917 | I9: PESO: | J9: 22.3 Kg
B10: DNI/RUC: | E10: ORIGEN: | F10: CHINA | I10: MEDIDA: | J10: 0
B11: TELEFONO: | C11: 51 951880948 | E11: CLIENTE: | F11: ANTIGUO | I11: CBM | J11: ='2'!C7 -> 0
B13: CALCULO DE BASE IMPONIBLE | K13: MONTO | L13: MONEDA
B14: VALOR DE CARGA | K14: ='2'!C11 -> 2300 | L14: USD
B15: FLETE INTERNACIONAL + SEGURO | K15: ='2'!C14 + '2'!C17 -> 245 | L15: USD
B16: VALOR CIF | K16: =SUM(K14:K15) -> 2545 | L16: USD
B19: CALCULO DE TRIBUTOS | J19: % | K19: MONTO | L19: MONEDA
B20: ADVALOREM | J20: =MAX('2'!C26:E26) -> 0 | K20: ='2'!C28 -> 0 | L20: USD | N20: Hola ANTHONY ROCCA CAQUI 2 😁 un gusto saludarte! A continuación te envío la cotización final de tu importación📋📦. 🙋‍♂️ PAGO PENDIENTE : ☑️Costo CBM: $936 ☑️Impuestos: $419.14 ☑️ Total: $1355.14 Pronto le aviso nuevos avances, que tengan buen día🚢 Último día de pago:
B21: IGV | J21: 0.16 | K21: ='2'!C29 -> 407.2 | L21: USD
B22: IPM | J22: 0.02 | K22: ='2'!C30 -> 50.9 | L22: USD
B23: SUB TOTAL | K23: =SUM(K20:K22) -> 458.1 | L23: USD
B25: PERCEPCIÓN | J25: 3.5% | K25: ='2'!C31 -> 105.1085 | L25: USD
B26: TOTAL | K26: =K23+K25 -> 563.2085 | L26: USD
B28: RESUMEN DE COTIZACIÓN | K28: MONTO | L28: MONEDA
B29: VALOR DE CARGA (PAGO AL PROVEEDOR) | K29: =K14 -> 2300 | L29: USD
B30: SERVICIO DE IMPORTACIÓN (ORIGEN -FLETE - DESTINO) | K30: =IF(J11<1, 325, 325*J11) -> 325 | L30: USD
B31: IMPUESTOS | K31: =K20+K21+K22+K25 -> 563.2085 | L31: USD
B32: MONTO TOTAL | K32: =K29+K30+K31 -> 3188.2085 | L32: USD
B34: SIMULACIÓN DEL PRECIO PUESTO EN PERÚ POR PIEZA
B35: # ITEM | C35: NOMBRE PRODUCTO | F35: CANTIDAD | G35: COSTO UNI. | I35: PRECIO U. | J35: TOTAL | K35: PRECIO UNIT. (SOLES)
B36: 1 | C36: MOCHILA VIAJERA | F36: ='2'!C10 -> 250 | G36: ='2'!C8 -> 9.2 | I36: ='2'!C46 -> 12.752834 | J36: ='2'!C44 -> 3188.2085 | K36: ='2'!C47 -> 47.185486
B37: TOTAL | F37: =SUM(F36:F36) -> 250 | J37: =SUM(J36:J36) -> 3188.2085
B42: NOTAS:
B43: *Las fechas brindadas son estimadas, estan sujetas a variación.
B44: *No se emite comprobante por concepto de "PERCEPCIÓN, ANTI DUMPING, GESTIÓN DE COMPRA"
B45: *A nosotros se nos pagan los Gastos Logísticos + Impuestos una semana antes de que el contenedor
B46: llegue al puerto del Callao.
B47: *El tipo de cambio referencial usado para la conversión a soles es del 3.70
D50: PRO MUNDO COMEX S.A.C.
D51: RUC: 20612452432
B54: TÉRMINOS Y CONDICIONES:
B56: 1. Todos los pagos se realizan en dólares.
B57: 2.Todas las marcas de los productos deben ser verificadas por el cliente,
B58: No se aceptan marcas con medidas de frontera.
B59: 3. No somos responsables de retraso del proveedor para entregar la carga.
...

Sheet 2
B3: Calculo de Tributos
B5: Nombres | C5: MOCHILA VIAJERA | D5: Total
B6: Peso | C6: 0 | D6: 22.3 | G6: Tipo Cliente | H6: Tarifa
B7: Valor CBM | C7: 0 | D7: 0.06 | G7: ANTIGUO | H7: 325
B8: Valor Unitario | C8: 9.2
B9: Valoracion | C9: 0
B10: Cantidad | C10: 250 | D10: =SUM(C10:C10) -> 250
B11: Valor FOB | C11: =C8*C10 -> 2300 | D11: =SUM(C11:C11) -> 2300
B12: Valor FOB Valoracion | C12: =C10*C9 -> 0
B13: Distribucion % | C13: =C11/D11 -> 1
B14: Flete | C14: =D14*C13 -> 195 | D14: =IF(D7<1, H7*0.6, H7*0.6*D7) -> 195
B15: Valor CFR | C15: =C11+C14 -> 2495
B16: CFR Valorizado | C16: =C12+C14 -> 195
B17: Seguro | C17: =IF(D11>5000,100*C13,50*C13) -> 50
B18: Valor CIF | C18: =C15+C17 -> 2545
B19: CIF Valorizado | C19: =C16+C17 -> 245
B23: Tributos Aplicables
B26: ANTIDUMPING | C26: 0 | D26: =SUM(C26:C26) -> 0
C27: 0 | D27: =SUM(C27:C27) -> 0
B28: AD VALOREM | C28: =MAX(C19,C18)*C27 -> 0 | D28: =SUM(C28:C28) -> 0
B29: IGV | C29: =0.16*(MAX(C19,C18)+C28) -> 407.2 | D29: =SUM(C29:C29) -> 407.2
B30: IPM | C30: =0.02*(MAX(C19,C18)+C28) -> 50.9 | D30: =SUM(C30:C30) -> 50.9
B31: PERCEPCION | C31: =0.035*(MAX(C18,C19) +C28+C29+C30) -> 105.1085 | D31: =SUM(C31:C31) -> 105.1085
B32: TOTAL | C32: =SUM(C28:C31) -> 563.2085 | D32: =SUM(D28:D31) -> 563.2085
B37: Costos Destinos
B40: ITEM | C40: =C13*D40 -> 130 | D40: =IF(D7<1, H7*0.4,H7*0.4*D7) -> 130
B43: ITEM | C43: MOCHILA VIAJERA | D43: Total
B44: COSTO TOTAL | C44: =SUM(C15,C40,C32,(C26)) -> 3188.2085 | D44: =SUM(C44:C44) -> 3188.2085
B45: CANTIDAD | C45: 250
B46: COSTO UNITARIO | C46: =SUM(C44/C45) -> 12.752834
B47: COSTO SOLES | C47: =C46*3.7 -> 47.185486
