Workbook

Sheet 1
E3: PRO MUNDO COMEX S.A.C.
E4: RUC: 20612452432
E7: COTIZACION N002
B8: NOMBRE: | C8: MARCO CORDERO | E8: SERVICIO: | F8: CARGA CONSOLIDADA | I8: N° CAJAS: | J8: =+'2'!F7 -> 1.77
B9: APELLIDO: | E9: FECHA: | F9: =+TODAY() -> 45917 | I9: PESO: | J9: 328 Kg
B10: DNI/RUC: | E10: ORIGEN: | F10: CHINA | I10: MEDIDA: | J10: 0
B11: TELEFONO: | C11: 51923338802 | E11: CLIENTE: | F11: NUEVO | I11: CBM | J11: ='2'!E7 -> 0
B13: CALCULO DE BASE IMPONIBLE | K13: MONTO | L13: MONEDA
B14: VALOR DE CARGA | K14: ='2'!E11 -> 292.5 | L14: USD
B15: FLETE INTERNACIONAL + SEGURO | K15: ='2'!E14 + '2'!E17 -> 75.07193 | L15: USD
B16: VALOR CIF | K16: =SUM(K14:K15) -> 367.57193 | L16: USD
B19: CALCULO DE TRIBUTOS | J19: % | K19: MONTO | L19: MONEDA
B20: ADVALOREM | J20: =MAX('2'!C26:E26) -> 0 | K20: ='2'!E28 -> 0 | L20: USD | N20: Hola MARCO CORDERO 😁 un gusto saludarte! A continuación te envío la cotización final de tu importación📋📦. 🙋‍♂️ PAGO PENDIENTE : ☑️Costo CBM: $686.25 ☑️Impuestos: $174.9 ☑️ Total: $861.15 Pronto le aviso nuevos avances, que tengan buen día🚢 Último día de pago:
B21: IGV | J21: 0.16 | K21: ='2'!E29 -> 58.811509 | L21: USD
B22: IPM | J22: 0.02 | K22: ='2'!E30 -> 7.3514386 | L22: USD
B23: SUB TOTAL | K23: =SUM(K20:K22) -> 66.162947 | L23: USD
B25: PERCEPCIÓN | J25: 3.5% | K25: ='2'!E31 -> 15.180721 | L25: USD
B26: TOTAL | K26: =K23+K25 -> 81.343668 | L26: USD
B28: RESUMEN DE COTIZACIÓN | K28: MONTO | L28: MONEDA
B29: VALOR DE CARGA (PAGO AL PROVEEDOR) | K29: =K14 -> 292.5 | L29: USD
B30: SERVICIO DE IMPORTACIÓN (ORIGEN -FLETE - DESTINO) | K30: =IF(J11<1, 375, 375*J11) -> 375 | L30: USD
B31: IMPUESTOS | K31: =K20+K21+K22+K25 -> 81.343668 | L31: USD
B32: MONTO TOTAL | K32: =K29+K30+K31 -> 748.84367 | L32: USD
B34: SIMULACIÓN DEL PRECIO PUESTO EN PERÚ POR PIEZA
B35: # ITEM | C35: NOMBRE PRODUCTO | F35: CANTIDAD | G35: COSTO UNI. | I35: PRECIO U. | J35: TOTAL | K35: PRECIO UNIT. (SOLES)
B36: 1 | C36: TANQUE MEZCLADORA DE LIQUIDOS | F36: ='2'!C10 -> 1 | G36: ='2'!C8 -> 1262 | I36: ='2'!C46 -> 2092.5775 | J36: ='2'!C44 -> 2092.5775 | K36: ='2'!C47 -> 7742.5367
B37: 2 | C37: SACOS DE RESINA PARA PURIFICACION DE AGUA | F37: ='2'!D10 -> 4 | G37: ='2'!D8 -> 48 | I37: ='2'!D46 -> 79.590903 | J37: ='2'!D44 -> 318.36361 | K37: ='2'!D47 -> 294.48634
B38: 3 | C38: PANEL LED PARA PUBLICIDAD | F38: ='2'!E10 -> 15 | G38: ='2'!E8 -> 19.5 | I38: ='2'!E46 -> 32.333804 | J38: ='2'!E44 -> 485.00707 | K38: ='2'!E47 -> 119.63508
B39: TOTAL | F39: =SUM(F36:F38) -> 20 | J39: =SUM(J36:J38) -> 2895.9482
B42: NOTAS:
B43: *Las fechas brindadas son estimadas, estan sujetas a variación.
B44: *No se emite comprobante por concepto de "PERCEPCIÓN, ANTI DUMPING, GESTIÓN DE COMPRA"
B45: *A nosotros se nos pagan los Gastos Logísticos + Impuestos una semana antes de que el contenedor
B46: llegue al puerto del Callao.
B47: *El tipo de cambio referencial usado para la conversión a soles es del 3.70
D50: PRO MUNDO COMEX S.A.C.
D51: RUC: 20612452432
B54: TÉRMINOS Y CONDICIONES:
B56: 1. Todos los pagos se realizan en dólares.
B57: 2.Todas las marcas de los productos deben ser verificadas por el cliente,
...

Sheet 2
B3: Calculo de Tributos
B5: Nombres | C5: TANQUE MEZCLADORA DE LIQUIDOS | D5: SACOS DE RESINA PARA PURIFICACION DE AGUA | E5: PANEL LED PARA PUBLICIDAD | F5: Total
B6: Peso | C6: 0 | D6: 0 | E6: 0 | F6: 328 | I6: Tipo Cliente | J6: Tarifa
B7: Valor CBM | C7: 0 | D7: 0 | E7: 0 | F7: 1.77 | I7: NUEVO | J7: 375
B8: Valor Unitario | C8: 1262 | D8: 48 | E8: 19.5
B9: Valoracion | C9: 0 | D9: 0 | E9: 0
B10: Cantidad | C10: 1 | D10: 4 | E10: 15 | F10: =SUM(C10:E10) -> 20
B11: Valor FOB | C11: =C8*C10 -> 1262 | D11: =D8*D10 -> 192 | E11: =E8*E10 -> 292.5 | F11: =SUM(C11:E11) -> 1746.5
B12: Valor FOB Valoracion | C12: =C10*C9 -> 0 | D12: =D10*D9 -> 0 | E12: =E10*E9 -> 0
B13: Distribucion % | C13: =C11/F11 -> 0.72258803 | D13: =D11/F11 -> 0.10993415 | E13: =E11/F11 -> 0.16747781
B14: Flete | C14: =F14*C13 -> 287.77068 | D14: =F14*D13 -> 43.781277 | E14: =F14*E13 -> 66.698039 | F14: =IF(F7<1, J7*0.6, J7*0.6*F7) -> 398.25
B15: Valor CFR | C15: =C11+C14 -> 1549.7707 | D15: =D11+D14 -> 235.78128 | E15: =E11+E14 -> 359.19804
B16: CFR Valorizado | C16: =C12+C14 -> 287.77068 | D16: =D12+D14 -> 43.781277 | E16: =E12+E14 -> 66.698039
B17: Seguro | C17: =IF(F11>5000,100*C13,50*C13) -> 36.129402 | D17: =IF(F11>5000,100*D13,50*D13) -> 5.4967077 | E17: =IF(F11>5000,100*E13,50*E13) -> 8.3738906
B18: Valor CIF | C18: =C15+C17 -> 1585.9001 | D18: =D15+D17 -> 241.27798 | E18: =E15+E17 -> 367.57193
B19: CIF Valorizado | C19: =C16+C17 -> 323.90009 | D19: =D16+D17 -> 49.277985 | E19: =E16+E17 -> 75.07193
B23: Tributos Aplicables
B26: ANTIDUMPING | C26: 0 | D26: 0 | E26: 0 | F26: =SUM(C26:E26) -> 0
C27: 0 | D27: 0 | E27: 0 | F27: =SUM(C27:E27) -> 0
B28: AD VALOREM | C28: =MAX(C19,C18)*C27 -> 0 | D28: =MAX(D19,D18)*D27 -> 0 | E28: =MAX(E19,E18)*E27 -> 0 | F28: =SUM(C28:E28) -> 0
B29: IGV | C29: =0.16*(MAX(C19,C18)+C28) -> 253.74401 | D29: =0.16*(MAX(D19,D18)+D28) -> 38.604478 | E29: =0.16*(MAX(E19,E18)+E28) -> 58.811509 | F29: =SUM(C29:E29) -> 351.16
B30: IPM | C30: =0.02*(MAX(C19,C18)+C28) -> 31.718002 | D30: =0.02*(MAX(D19,D18)+D28) -> 4.8255597 | E30: =0.02*(MAX(E19,E18)+E28) -> 7.3514386 | F30: =SUM(C30:E30) -> 43.895
B31: PERCEPCION | C31: =0.035*(MAX(C18,C19) +C28+C29+C30) -> 65.497674 | D31: =0.035*(MAX(D18,D19) +D28+D29+D30) -> 9.9647808 | E31: =0.035*(MAX(E18,E19) +E28+E29+E30) -> 15.180721 | F31: =SUM(C31:E31) -> 90.643175
B32: TOTAL | C32: =SUM(C28:C31) -> 350.95969 | D32: =SUM(D28:D31) -> 53.394818 | E32: =SUM(E28:E31) -> 81.343668 | F32: =SUM(F28:F31) -> 485.69817
B37: Costos Destinos
B40: ITEM | C40: =C13*F40 -> 191.84712 | D40: =D13*F40 -> 29.187518 | E40: =E13*F40 -> 44.465359 | F40: =IF(F7<1, J7*0.4,J7*0.4*F7) -> 265.5
B43: ITEM | C43: TANQUE MEZCLADORA DE LIQUIDOS | D43: SACOS DE RESINA PARA PURIFICACION DE AGUA | E43: PANEL LED PARA PUBLICIDAD | F43: Total
B44: COSTO TOTAL | C44: =SUM(C15,C40,C32,(C26)) -> 2092.5775 | D44: =SUM(D15,D40,D32,(D26)) -> 318.36361 | E44: =SUM(E15,E40,E32,(E26)) -> 485.00707 | F44: =SUM(C44:E44) -> 2895.9482
B45: CANTIDAD | C45: 1 | D45: 4 | E45: 15
B46: COSTO UNITARIO | C46: =SUM(C44/C45) -> 2092.5775 | D46: =SUM(D44/D45) -> 79.590903 | E46: =SUM(E44/E45) -> 32.333804
B47: COSTO SOLES | C47: =C46*3.7 -> 7742.5367 | D47: =D46*3.7 -> 294.48634 | E47: =E46*3.7 -> 119.63508
