Workbook

Sheet 1
E3: PRO MUNDO COMEX S.A.C.
E4: RUC: 20612452432
E7: COTIZACION N002
B8: NOMBRE: | C8: VICTOR LUIS SAN MIGUEL CASAS | E8: SERVICIO: | F8: CARGA CONSOLIDADA | I8: N° CAJAS: | J8: =+'2'!F7 -> 0
B9: APELLIDO: | E9: FECHA: | F9: =+TODAY() -> 45917 | I9: PESO: | J9: 800 Kg
B10: DNI/RUC: | C10: 74143306 | E10: ORIGEN: | F10: CHINA | I10: MEDIDA: | J10: 0
B11: TELEFONO: | C11: 51 956 686 057 | E11: CLIENTE: | F11: MANUAL | I11: CBM | J11: 3.2
B13: CALCULO DE BASE IMPONIBLE | K13: MONTO | L13: MONEDA
B14: VALOR DE CARGA | K14: ='2'!I11 -> 629 | L14: USD
B15: FLETE INTERNACIONAL + SEGURO | K15: ='2'!I14 + '2'!I17 -> 53.55613 | L15: USD
B16: VALOR CIF | K16: =SUM(K14:K15) -> 682.55613 | L16: USD
B19: CALCULO DE TRIBUTOS | J19: % | K19: MONTO | L19: MONEDA
B20: ADVALOREM | J20: =MAX('2'!C26:E26) -> 0 | K20: ='2'!I28 -> 0 | L20: USD | N20: Hola VICTOR LUIS SAN MIGUEL CASAS 😁 un gusto saludarte! A continuación te envío la cotización final de tu importación📋📦. 🙋‍♂️ PAGO PENDIENTE : ☑️Costo CBM: $0 ☑️Impuestos: $0 ☑️ Total: $0 Pronto le aviso nuevos avances, que tengan buen día🚢 Último día de pago:
B21: IGV | J21: 0.16 | K21: ='2'!I29 -> 109.20898 | L21: USD
B22: IPM | J22: 0.02 | K22: ='2'!I30 | L22: USD
B23: SUB TOTAL | K23: =SUM(K20:K22) -> 109.20898 | L23: USD
B25: PERCEPCIÓN | J25: 3.5% | K25: ='2'!I31 | L25: USD
B26: TOTAL | K26: =K23+K25 -> 109.20898 | L26: USD
B28: RESUMEN DE COTIZACIÓN | K28: MONTO | L28: MONEDA
B29: VALOR DE CARGA (PAGO AL PROVEEDOR) | K29: =K14 -> 629 | L29: USD
B30: SERVICIO DE IMPORTACIÓN (ORIGEN -FLETE - DESTINO) | K30: =IF(J11<1, '2'!I40, '2'!I40*J11) -> 0 | L30: USD
B31: IMPUESTOS | K31: =K20+K21+K22+K25 -> 0 | L31: USD
B32: MONTO TOTAL | K32: =K29+K30+K31 -> 629 | L32: USD
B34: SIMULACIÓN DEL PRECIO PUESTO EN PERÚ POR PIEZA
B35: # ITEM | C35: NOMBRE PRODUCTO | F35: CANTIDAD | G35: COSTO UNI. | I35: PRECIO U. | J35: TOTAL | K35: PRECIO UNIT. (SOLES)
B36: 1 | C36: =+'2'!$C$6 -> 0 | F36: =+'2'!$C$45 -> 200 | G36: =+'2'!$C$10 -> 200 | I36: =+'2'!$C$46 -> 12.83098 | J36: =+F36*I36 -> 2566.196 | K36: =I36*3.7 -> 47.474625
B37: 2 | C37: =+'2'!$D$6 -> 0 | F37: =+'2'!$D$45 -> 442 | G37: =+'2'!$D$10 -> 442 | I37: =+'2'!$D$46 -> 12.390003 | J37: =+F37*I37 -> 5476.3813 | K37: =I37*3.7 -> 45.843011
B38: 3 | C38: =+'2'!$E$6 -> 0 | F38: =+'2'!$E$45 -> 50 | G38: =+'2'!$E$10 -> 50 | I38: =+'2'!$E$46 -> 1.0321552 | J38: =+F38*I38 -> 51.607762 | K38: =I38*3.7 -> 3.8189744
B39: TOTAL | F39: =+SUM(F36:F38) -> 692 | J39: =+SUM(J36:J38) -> 8094.185
B42: NOTAS:
B43: *Las fechas brindadas son estimadas, estan sujetas a variación.
B44: *No se emite comprobante por concepto de "PERCEPCIÓN, ANTI DUMPING, GESTIÓN DE COMPRA"
B45: *A nosotros se nos pagan los Gastos Logísticos + Impuestos una semana antes de que el contenedor
B46: llegue al puerto del Callao.
B47: *El tipo de cambio referencial usado para la conversión a soles es del 3.70
D50: PRO MUNDO COMEX S.A.C.
D51: RUC: 20612452432
B54: TÉRMINOS Y CONDICIONES:
B56: 1. Todos los pagos se realizan en dólares.
B57: 2.Todas las marcas de los productos deben ser verificadas por el cliente,
...

Sheet 2
B3: Calculo de Tributos
B5: Nombres | C5: CASACA TACTICA MILITAR | D5: PANTALON TACTICO MILITAR | E5: PULSERA MULTIFUNCIONAL 5 EN 1 | F5: PASAMONTAÑA MILITAR | G5: GORRO TACTICO MILITAR | H5: CAMISETA TACTICA MILITAR | I5: CAMISETA MANGA LARGA MILITAR | J5: Total
B6: Peso | C6: 0 | D6: 0 | E6: 0 | F6: 0 | G6: 0 | H6: 0 | I6: 0 | J6: 800 | M6: Tipo Cliente | N6: Tarifa
B7: Valor CBM | C7: 0 | D7: 0 | E7: 0 | F7: 0 | G7: 0 | H7: 0 | I7: 0 | J7: 2.55 | M7: MANUAL | N7: 321.88
B8: Valor Unitario | C8: 9.44775 | D8: 8.2386878 | E8: 0.76 | F8: 1.45 | G8: 1.2182609 | H8: 2.5 | I8: 7.4
B9: Valoracion | C9: 0 | D9: 0 | E9: 0 | F9: 0 | G9: 0 | H9: 0 | I9: 0
B10: Cantidad | C10: 200 | D10: 442 | E10: 50 | F10: 50 | G10: 460 | H10: 51 | I10: 85 | J10: =SUM(C10:I10) -> 1338
B11: Valor FOB | C11: =C8*C10 -> 1889.55 | D11: =D8*D10 -> 3641.5 | E11: =E8*E10 -> 38 | F11: =F8*F10 -> 72.5 | G11: =G8*G10 -> 560.4 | H11: =H8*H10 -> 127.5 | I11: =I8*I10 -> 629 | J11: =SUM(C11:I11) -> 6958.45
B12: Valor FOB Valoracion | C12: =C10*C9 -> 0 | D12: =D10*D9 -> 0 | E12: =E10*E9 -> 0 | F12: =F10*F9 -> 0 | G12: =G10*G9 -> 0 | H12: =H10*H9 -> 0 | I12: =I10*I9 -> 0
B13: Distribucion % | C13: =C11/J11 -> 0.27154754 | D13: =D11/J11 -> 0.52332057 | E13: =E11/J11 -> 0.0054609863 | F13: =F11/J11 -> 0.010418987 | G13: =G11/J11 -> 0.080535177 | H13: =H11/J11 -> 0.018323046 | I13: =I11/J11 -> 0.090393694
B14: Flete | C14: =J14*C13 -> 133.73076 | D14: =J14*D13 -> 257.72303 | E14: =J14*E13 -> 2.6894069 | F14: =J14*F13 -> 5.1311052 | G14: =J14*G13 -> 39.661674 | H14: =J14*H13 -> 9.0236678 | I14: =J14*I13 -> 44.516761 | J14: =IF(J7<1, N7*0.6, N7*0.6*J7) -> 492.4764
B15: Valor CFR | C15: =C11+C14 -> 2023.2808 | D15: =D11+D14 -> 3899.223 | E15: =E11+E14 -> 40.689407 | F15: =F11+F14 -> 77.631105 | G15: =G11+G14 -> 600.06167 | H15: =H11+H14 -> 136.52367 | I15: =I11+I14 -> 673.51676
B16: CFR Valorizado | C16: =C12+C14 -> 133.73076 | D16: =D12+D14 -> 257.72303 | E16: =E12+E14 -> 2.6894069 | F16: =F12+F14 -> 5.1311052 | G16: =G12+G14 -> 39.661674 | H16: =H12+H14 -> 9.0236678 | I16: =I12+I14 -> 44.516761
B17: Seguro | C17: =IF(J11>5000,100*C13,50*C13) -> 27.154754 | D17: =IF(J11>5000,100*D13,50*D13) -> 52.332057 | E17: =IF(J11>5000,100*E13,50*E13) -> 0.54609863 | F17: =IF(J11>5000,100*F13,50*F13) -> 1.0418987 | G17: =IF(J11>5000,100*G13,50*G13) -> 8.0535177 | H17: =IF(J11>5000,100*H13,50*H13) -> 1.8323046 | I17: =IF(J11>5000,100*I13,50*I13) -> 9.0393694
B18: Valor CIF | C18: =C15+C17 -> 2050.4355 | D18: =D15+D17 -> 3951.5551 | E18: =E15+E17 -> 41.235505 | F18: =F15+F17 -> 78.673004 | G18: =G15+G17 -> 608.11519 | H18: =H15+H17 -> 138.35597 | I18: =I15+I17 -> 682.55613
B19: CIF Valorizado | C19: =C16+C17 -> 160.88551 | D19: =D16+D17 -> 310.05509 | E19: =E16+E17 -> 3.2355055 | F19: =F16+F17 -> 6.1730039 | G19: =G16+G17 -> 47.715192 | H19: =H16+H17 -> 10.855972 | I19: =I16+I17 -> 53.55613
B23: Tributos Aplicables
B26: ANTIDUMPING | C26: 0 | D26: 0 | E26: 0 | F26: 0 | G26: 0 | H26: 0 | I26: 0 | J26: =SUM(C26:I26) -> 0
C27: 0 | D27: 0.11 | E27: 0 | F27: 0.06 | G27: 0 | H27: 0 | I27: 0 | J27: =SUM(C27:I27) -> 0.17
B28: AD VALOREM | C28: =MAX(C19,C18)*C27 -> 0 | D28: =MAX(D19,D18)*D27 -> 434.67106 | E28: =MAX(E19,E18)*E27 -> 0 | F28: =MAX(F19,F18)*F27 -> 4.7203802 | G28: =MAX(G19,G18)*G27 -> 0 | H28: =MAX(H19,H18)*H27 -> 0 | I28: =MAX(I19,I18)*I27 -> 0 | J28: =SUM(C28:I28) -> 439.39144
B29: IGV | C29: =0.16*(MAX(C19,C18)+C28) -> 328.06968 | D29: =0.16*(MAX(D19,D18)+D28) -> 701.79618 | E29: =0.16*(MAX(E19,E18)+E28) -> 6.5976809 | F29: =0.16*(MAX(F19,F18)+F28) -> 13.342941 | G29: =0.16*(MAX(G19,G18)+G28) -> 97.298431 | H29: =0.16*(MAX(H19,H18)+H28) -> 22.136956 | I29: =0.16*(MAX(I19,I18)+I28) -> 109.20898 | J29: =SUM(C29:I29) -> 1278.4509
B30: IPM | C30: =0.02*(MAX(C19,C18)+C28) -> 41.00871 | D30: =0.02*(MAX(D19,D18)+D28) -> 87.724523 | E30: =0.02*(MAX(E19,E18)+E28) -> 0.82471011 | F30: =0.02*(MAX(F19,F18)+F28) -> 1.6678677 | G30: =0.02*(MAX(G19,G18)+G28) -> 12.162304 | H30: =0.02*(MAX(H19,H18)+H28) -> 2.7671194 | I30: =0.02*(MAX(I19,I18)+I28) -> 13.651123 | J30: =SUM(C30:I30) -> 159.80636
B31: PERCEPCION | C31: =0.035*(MAX(C18,C19) +C28+C29+C30) -> 84.682987 | D31: =0.035*(MAX(D18,D19) +D28+D29+D30) -> 181.15114 | E31: =0.035*(MAX(E18,E19) +E28+E29+E30) -> 1.7030264 | F31: =0.035*(MAX(F18,F19) +F28+F29+F30) -> 3.4441468 | G31: =0.035*(MAX(G18,G19) +G28+G29+G30) -> 25.115157 | H31: =0.035*(MAX(H18,H19) +H28+H29+H30) -> 5.7141017 | I31: =0.035*(MAX(I18,I19) +I28+I29+I30) -> 28.189568 | J31: =SUM(C31:I31) -> 330.00013
B32: TOTAL | C32: =SUM(C28:C31) -> 453.76138 | D32: =SUM(D28:D31) -> 1405.3429 | E32: =SUM(E28:E31) -> 9.1254174 | F32: =SUM(F28:F31) -> 23.175336 | G32: =SUM(G28:G31) -> 134.57589 | H32: =SUM(H28:H31) -> 30.618177 | I32: =SUM(I28:I31) -> 151.04967 | J32: =SUM(J28:J31) -> 2207.6488
B37: Costos Destinos
B40: ITEM | C40: =C13*J40 -> 89.153838 | D40: =D13*J40 -> 171.81535 | E40: =E13*J40 -> 1.7929379 | F40: =F13*J40 -> 3.4207368 | G40: =G13*J40 -> 26.441116 | H40: =H13*J40 -> 6.0157785 | I40: =I13*J40 -> 29.677841 | J40: =IF(J7<1, N7*0.4,N7*0.4*J7) -> 328.3176
B43: ITEM | C43: CASACA TACTICA MILITAR | D43: PANTALON TACTICO MILITAR | E43: PULSERA MULTIFUNCIONAL 5 EN 1 | F43: PASAMONTAÑA MILITAR | G43: GORRO TACTICO MILITAR | H43: CAMISETA TACTICA MILITAR | I43: CAMISETA MANGA LARGA MILITAR | J43: Total
B44: COSTO TOTAL | C44: =SUM(C15,C40,C32,(C26)) -> 2566.196 | D44: =SUM(D15,D40,D32,(D26)) -> 5476.3813 | E44: =SUM(E15,E40,E32,(E26)) -> 51.607762 | F44: =SUM(F15,F40,F32,(F26)) -> 104.22718 | G44: =SUM(G15,G40,G32,(G26)) -> 761.07868 | H44: =SUM(H15,H40,H32,(H26)) -> 173.15762 | I44: =SUM(I15,I40,I32,(I26)) -> 854.24427 | J44: =SUM(C44:I44) -> 9986.8928
B45: CANTIDAD | C45: 200 | D45: 442 | E45: 50 | F45: 50 | G45: 460 | H45: 51 | I45: 85
B46: COSTO UNITARIO | C46: =SUM(C44/C45) -> 12.83098 | D46: =SUM(D44/D45) -> 12.390003 | E46: =SUM(E44/E45) -> 1.0321552 | F46: =SUM(F44/F45) -> 2.0845436 | G46: =SUM(G44/G45) -> 1.6545189 | H46: =SUM(H44/H45) -> 3.3952475 | I46: =SUM(I44/I45) -> 10.049933
B47: COSTO SOLES | C47: =C46*3.7 -> 47.474625 | D47: =D46*3.7 -> 45.843011 | E47: =E46*3.7 -> 3.8189744 | F47: =F46*3.7 -> 7.7128112 | G47: =G46*3.7 -> 6.1217198 | H47: =H46*3.7 -> 12.562416 | I47: =I46*3.7 -> 37.184751
