Workbook

Sheet 1
E3: PRO MUNDO COMEX S.A.C.
E4: RUC: 20612452432
E7: COTIZACION N002
B8: NOMBRE: | C8: THALIA HUANCA MELO | E8: SERVICIO: | F8: CARGA CONSOLIDADA | I8: N° CAJAS: | J8: =+'2'!F7 -> 0
B9: APELLIDO: | E9: FECHA: | F9: =+TODAY() -> 45917 | I9: PESO: | J9: 24.1 Kg
B10: DNI/RUC: | C10: 77130005 | E10: ORIGEN: | F10: CHINA | I10: MEDIDA: | J10: 0
B11: TELEFONO: | C11: 51 963317709 | E11: CLIENTE: | F11: MANUAL | I11: CBM | J11: ='2'!I7 -> 0
B13: CALCULO DE BASE IMPONIBLE | K13: MONTO | L13: MONEDA
B14: VALOR DE CARGA | K14: ='2'!I11 -> 174 | L14: USD
B15: FLETE INTERNACIONAL + SEGURO | K15: ='2'!I14 + '2'!I17 -> 70.912765 | L15: USD
B16: VALOR CIF | K16: =SUM(K14:K15) -> 244.91277 | L16: USD
B19: CALCULO DE TRIBUTOS | J19: % | K19: MONTO | L19: MONEDA
B20: ADVALOREM | J20: =MAX('2'!C26:E26) -> 0 | K20: ='2'!I28 -> 0 | L20: USD | N20: Hola THALIA HUANCA MELO 😁 un gusto saludarte! A continuación te envío la cotización final de tu importación📋📦. 🙋‍♂️ PAGO PENDIENTE : ☑️Costo CBM: $320 ☑️Impuestos: $0 ☑️ Total: $320 Pronto le aviso nuevos avances, que tengan buen día🚢 Último día de pago:
B21: IGV | J21: 0.16 | K21: ='2'!I29 -> 39.186042 | L21: USD
B22: IPM | J22: 0.02 | K22: ='2'!I30 -> 4.8982553 | L22: USD
B23: SUB TOTAL | K23: =SUM(K20:K22) -> 44.084298 | L23: USD
B25: PERCEPCIÓN | J25: 3.5% | K25: ='2'!I31 -> 10.114897 | L25: USD
B26: TOTAL | K26: =K23+K25 -> 54.199195 | L26: USD
B28: RESUMEN DE COTIZACIÓN | K28: MONTO | L28: MONEDA
B29: VALOR DE CARGA (PAGO AL PROVEEDOR) | K29: =K14 -> 174 | L29: USD
B30: SERVICIO DE IMPORTACIÓN (ORIGEN -FLETE - DESTINO) | K30: =IF(J11<1, 320.00, 320.00*J11) -> 320 | L30: USD
B31: IMPUESTOS | K31: =K20+K21+K22+K25 -> 54.199195 | L31: USD
B32: MONTO TOTAL | K32: =K29+K30+K31 -> 548.19919 | L32: USD
B34: SIMULACIÓN DEL PRECIO PUESTO EN PERÚ POR PIEZA
B35: # ITEM | C35: NOMBRE PRODUCTO | F35: CANTIDAD | G35: COSTO UNI. | I35: PRECIO U. | J35: TOTAL | K35: PRECIO UNIT. (SOLES)
B36: 1 | C36: GUANTES DE INVIERTO | F36: ='2'!C10 -> 70 | G36: ='2'!C8 -> 0.81857143 | I36: ='2'!C46 -> 1.5146777 | J36: ='2'!C44 -> 106.02744 | K36: ='2'!C47 -> 5.6043075
B37: 2 | C37: BUFANDA DE PUNTO | F37: ='2'!D10 -> 50 | G37: ='2'!D8 -> 1.65 | I37: ='2'!D46 -> 3.0531462 | J37: ='2'!D44 -> 152.65731 | K37: ='2'!D47 -> 11.296641
B38: 3 | C38: SOMBRERO DE PESCADOR | F38: ='2'!E10 -> 60 | G38: ='2'!E8 -> 1.2 | I38: ='2'!E46 -> 2.3442404 | J38: ='2'!E44 -> 140.65442 | K38: ='2'!E47 -> 8.6736895
B39: 4 | C39: GORRO DE INVIERNO | F39: ='2'!F10 -> 50 | G39: ='2'!F8 -> 1.36 | I39: ='2'!F46 -> 2.5165326 | J39: ='2'!F44 -> 125.82663 | K39: ='2'!F47 -> 9.3111706
B40: 5 | C40: GORRO DE BEISBOL | F40: ='2'!G10 -> 50 | G40: ='2'!G8 -> 1.4 | I40: ='2'!G46 -> 2.5905483 | J40: ='2'!G44 -> 129.52741 | K40: ='2'!G47 -> 9.5850286
B41: 6 | C41: GORRO DE INVIERNO DE OSO | F41: ='2'!H10 -> 50 | G41: ='2'!H8 -> 1.4 | I41: ='2'!H46 -> 2.5905483 | J41: ='2'!H44 -> 129.52741 | K41: ='2'!H47 -> 9.5850286
B42: 7 | C42: BUFANDA PARA INVIERNO | F42: ='2'!I10 -> 70 | G42: ='2'!I8 -> 2.4857143 | I42: ='2'!I46 -> 4.5995449 | J42: ='2'!I44 -> 321.96814 | K42: ='2'!I47 -> 17.018316
B43: TOTAL | F43: =SUM(F36:F42) -> 400 | J43: =SUM(J36:J42) -> 1106.1888
B44: *No se emite comprobante por concepto de "PERCEPCIÓN, ANTI DUMPING, GESTIÓN DE COMPRA"
B45: *A nosotros se nos pagan los Gastos Logísticos + Impuestos una semana antes de que el contenedor
B46: llegue al puerto del Callao.
B47: *El tipo de cambio referencial usado para la conversión a soles es del 3.70
D50: PRO MUNDO COMEX S.A.C.
D51: RUC: 20612452432
B54: TÉRMINOS Y CONDICIONES:
...

Sheet 2
B3: Calculo de Tributos
B5: Nombres | C5: GUANTES DE INVIERTO | D5: BUFANDA DE PUNTO | E5: SOMBRERO DE PESCADOR | F5: GORRO DE INVIERNO | G5: GORRO DE BEISBOL | H5: GORRO DE INVIERNO DE OSO | I5: BUFANDA PARA INVIERNO | J5: Total
B6: Peso | C6: 0 | D6: 0 | E6: 0 | F6: 0 | G6: 0 | H6: 0 | I6: 0 | J6: 24.1 | M6: Tipo Cliente | N6: Tarifa
B7: Valor CBM | C7: 0 | D7: 0 | E7: 0 | F7: 0 | G7: 0 | H7: 0 | I7: 0 | J7: 0.56 | M7: MANUAL | N7: 320
B8: Valor Unitario | C8: 0.81857143 | D8: 1.65 | E8: 1.2 | F8: 1.36 | G8: 1.4 | H8: 1.4 | I8: 2.4857143
B9: Valoracion | C9: 0 | D9: 0 | E9: 0 | F9: 0 | G9: 0 | H9: 0 | I9: 0
B10: Cantidad | C10: 70 | D10: 50 | E10: 60 | F10: 50 | G10: 50 | H10: 50 | I10: 70 | J10: =SUM(C10:I10) -> 400
B11: Valor FOB | C11: =C8*C10 -> 57.3 | D11: =D8*D10 -> 82.5 | E11: =E8*E10 -> 72 | F11: =F8*F10 -> 68 | G11: =G8*G10 -> 70 | H11: =H8*H10 -> 70 | I11: =I8*I10 -> 174 | J11: =SUM(C11:I11) -> 593.8
B12: Valor FOB Valoracion | C12: =C10*C9 -> 0 | D12: =D10*D9 -> 0 | E12: =E10*E9 -> 0 | F12: =F10*F9 -> 0 | G12: =G10*G9 -> 0 | H12: =H10*H9 -> 0 | I12: =I10*I9 -> 0
B13: Distribucion % | C13: =C11/J11 -> 0.096497137 | D13: =D11/J11 -> 0.13893567 | E13: =E11/J11 -> 0.12125295 | F13: =F11/J11 -> 0.11451667 | G13: =G11/J11 -> 0.11788481 | H13: =H11/J11 -> 0.11788481 | I13: =I11/J11 -> 0.29302796
B14: Flete | C14: =J14*C13 -> 18.52745 | D14: =J14*D13 -> 26.675648 | E14: =J14*E13 -> 23.280566 | F14: =J14*F13 -> 21.987201 | G14: =J14*G13 -> 22.633883 | H14: =J14*H13 -> 22.633883 | I14: =J14*I13 -> 56.261367 | J14: =IF(J7<1, N7*0.6, N7*0.6*J7) -> 192
B15: Valor CFR | C15: =C11+C14 -> 75.82745 | D15: =D11+D14 -> 109.17565 | E15: =E11+E14 -> 95.280566 | F15: =F11+F14 -> 89.987201 | G15: =G11+G14 -> 92.633883 | H15: =H11+H14 -> 92.633883 | I15: =I11+I14 -> 230.26137
B16: CFR Valorizado | C16: =C12+C14 -> 18.52745 | D16: =D12+D14 -> 26.675648 | E16: =E12+E14 -> 23.280566 | F16: =F12+F14 -> 21.987201 | G16: =G12+G14 -> 22.633883 | H16: =H12+H14 -> 22.633883 | I16: =I12+I14 -> 56.261367
B17: Seguro | C17: =IF(J11>5000,100*C13,50*C13) -> 4.8248569 | D17: =IF(J11>5000,100*D13,50*D13) -> 6.9467834 | E17: =IF(J11>5000,100*E13,50*E13) -> 6.0626474 | F17: =IF(J11>5000,100*F13,50*F13) -> 5.7258336 | G17: =IF(J11>5000,100*G13,50*G13) -> 5.8942405 | H17: =IF(J11>5000,100*H13,50*H13) -> 5.8942405 | I17: =IF(J11>5000,100*I13,50*I13) -> 14.651398
B18: Valor CIF | C18: =C15+C17 -> 80.652307 | D18: =D15+D17 -> 116.12243 | E18: =E15+E17 -> 101.34321 | F18: =F15+F17 -> 95.713035 | G18: =G15+G17 -> 98.528124 | H18: =H15+H17 -> 98.528124 | I18: =I15+I17 -> 244.91277
B19: CIF Valorizado | C19: =C16+C17 -> 23.352307 | D19: =D16+D17 -> 33.622432 | E19: =E16+E17 -> 29.343213 | F19: =F16+F17 -> 27.713035 | G19: =G16+G17 -> 28.528124 | H19: =H16+H17 -> 28.528124 | I19: =I16+I17 -> 70.912765
B23: Tributos Aplicables
B26: ANTIDUMPING | C26: 0 | D26: 0 | E26: 0 | F26: 0 | G26: 0 | H26: 0 | I26: 0 | J26: =SUM(C26:I26) -> 0
C27: 0 | D27: 0 | E27: 0.06 | F27: 0 | G27: 0 | H27: 0 | I27: 0 | J27: =SUM(C27:I27) -> 0.06
B28: AD VALOREM | C28: =MAX(C19,C18)*C27 -> 0 | D28: =MAX(D19,D18)*D27 -> 0 | E28: =MAX(E19,E18)*E27 -> 6.0805928 | F28: =MAX(F19,F18)*F27 -> 0 | G28: =MAX(G19,G18)*G27 -> 0 | H28: =MAX(H19,H18)*H27 -> 0 | I28: =MAX(I19,I18)*I27 -> 0 | J28: =SUM(C28:I28) -> 6.0805928
B29: IGV | C29: =0.16*(MAX(C19,C18)+C28) -> 12.904369 | D29: =0.16*(MAX(D19,D18)+D28) -> 18.579589 | E29: =0.16*(MAX(E19,E18)+E28) -> 17.187809 | F29: =0.16*(MAX(F19,F18)+F28) -> 15.314086 | G29: =0.16*(MAX(G19,G18)+G28) -> 15.7645 | H29: =0.16*(MAX(H19,H18)+H28) -> 15.7645 | I29: =0.16*(MAX(I19,I18)+I28) -> 39.186042 | J29: =SUM(C29:I29) -> 134.70089
B30: IPM | C30: =0.02*(MAX(C19,C18)+C28) -> 1.6130461 | D30: =0.02*(MAX(D19,D18)+D28) -> 2.3224486 | E30: =0.02*(MAX(E19,E18)+E28) -> 2.1484761 | F30: =0.02*(MAX(F19,F18)+F28) -> 1.9142607 | G30: =0.02*(MAX(G19,G18)+G28) -> 1.9705625 | H30: =0.02*(MAX(H19,H18)+H28) -> 1.9705625 | I30: =0.02*(MAX(I19,I18)+I28) -> 4.8982553 | J30: =SUM(C30:I30) -> 16.837612
B31: PERCEPCION | C31: =0.035*(MAX(C18,C19) +C28+C29+C30) -> 3.3309403 | D31: =0.035*(MAX(D18,D19) +D28+D29+D30) -> 4.7958564 | E31: =0.035*(MAX(E18,E19) +E28+E29+E30) -> 4.4366032 | F31: =0.035*(MAX(F18,F19) +F28+F29+F30) -> 3.9529483 | G31: =0.035*(MAX(G18,G19) +G28+G29+G30) -> 4.0692115 | H31: =0.035*(MAX(H18,H19) +H28+H29+H30) -> 4.0692115 | I31: =0.035*(MAX(I18,I19) +I28+I29+I30) -> 10.114897 | J31: =SUM(C31:I31) -> 34.769668
B32: TOTAL | C32: =SUM(C28:C31) -> 17.848356 | D32: =SUM(D28:D31) -> 25.697894 | E32: =SUM(E28:E31) -> 29.853481 | F32: =SUM(F28:F31) -> 21.181295 | G32: =SUM(G28:G31) -> 21.804274 | H32: =SUM(H28:H31) -> 21.804274 | I32: =SUM(I28:I31) -> 54.199195 | J32: =SUM(J28:J31) -> 192.38877
B37: Costos Destinos
B40: ITEM | C40: =C13*J40 -> 12.351634 | D40: =D13*J40 -> 17.783766 | E40: =E13*J40 -> 15.520377 | F40: =F13*J40 -> 14.658134 | G40: =G13*J40 -> 15.089256 | H40: =H13*J40 -> 15.089256 | I40: =I13*J40 -> 37.507578 | J40: =IF(J7<1, N7*0.4,N7*0.4*J7) -> 128
B43: ITEM | C43: GUANTES DE INVIERTO | D43: BUFANDA DE PUNTO | E43: SOMBRERO DE PESCADOR | F43: GORRO DE INVIERNO | G43: GORRO DE BEISBOL | H43: GORRO DE INVIERNO DE OSO | I43: BUFANDA PARA INVIERNO | J43: Total
B44: COSTO TOTAL | C44: =SUM(C15,C40,C32,(C26)) -> 106.02744 | D44: =SUM(D15,D40,D32,(D26)) -> 152.65731 | E44: =SUM(E15,E40,E32,(E26)) -> 140.65442 | F44: =SUM(F15,F40,F32,(F26)) -> 125.82663 | G44: =SUM(G15,G40,G32,(G26)) -> 129.52741 | H44: =SUM(H15,H40,H32,(H26)) -> 129.52741 | I44: =SUM(I15,I40,I32,(I26)) -> 321.96814 | J44: =SUM(C44:I44) -> 1106.1888
B45: CANTIDAD | C45: 70 | D45: 50 | E45: 60 | F45: 50 | G45: 50 | H45: 50 | I45: 70
B46: COSTO UNITARIO | C46: =SUM(C44/C45) -> 1.5146777 | D46: =SUM(D44/D45) -> 3.0531462 | E46: =SUM(E44/E45) -> 2.3442404 | F46: =SUM(F44/F45) -> 2.5165326 | G46: =SUM(G44/G45) -> 2.5905483 | H46: =SUM(H44/H45) -> 2.5905483 | I46: =SUM(I44/I45) -> 4.5995449
B47: COSTO SOLES | C47: =C46*3.7 -> 5.6043075 | D47: =D46*3.7 -> 11.296641 | E47: =E46*3.7 -> 8.6736895 | F47: =F46*3.7 -> 9.3111706 | G47: =G46*3.7 -> 9.5850286 | H47: =H46*3.7 -> 9.5850286 | I47: =I46*3.7 -> 17.018316
