Workbook

Sheet 1
E3: PRO MUNDO COMEX S.A.C.
E4: RUC: 20612452432
E7: COTIZACION N002
B8: NOMBRE: | C8: AQUILES TORRES | E8: SERVICIO: | F8: CARGA CONSOLIDADA | I8: N° CAJAS: | J8: =+'2'!F7 -> 0
B9: APELLIDO: | E9: FECHA: | F9: =+TODAY() -> 45917 | I9: PESO: | J9: 110 Kg
B10: DNI/RUC: | E10: ORIGEN: | F10: CHINA | I10: MEDIDA: | J10: 0
B11: TELEFONO: | C11: 51948105071 | E11: CLIENTE: | F11: MANUAL | I11: CBM | J11: 0.5
B13: CALCULO DE BASE IMPONIBLE | K13: MONTO | L13: MONEDA
B14: VALOR DE CARGA | K14: ='2'!D11 -> 2115.5 | L14: USD
B15: FLETE INTERNACIONAL + SEGURO | K15: ='2'!D14 + '2'!D17 -> 18.182098 | L15: USD
B16: VALOR CIF | K16: =SUM(K14:K15) -> 2133.6821 | L16: USD
B19: CALCULO DE TRIBUTOS | J19: % | K19: MONTO | L19: MONEDA
B20: ADVALOREM | J20: =MAX('2'!C26:E26) -> 0 | K20: ='2'!D28 -> 1.6923844 | L20: USD | N20: Hola AQUILES TORRES 😁 un gusto saludarte! A continuación te envío la cotización final de tu importación📋📦. 🙋‍♂️ PAGO PENDIENTE : ☑️Costo CBM: $8.03 ☑️Impuestos: $4.68 ☑️ Total: $12.71 Pronto le aviso nuevos avances, que tengan buen día🚢 Último día de pago:
B21: IGV | J21: 0.16 | K21: ='2'!D29 -> 0.21154805 | L21: USD
B22: IPM | J22: 0.02 | K22: ='2'!D30 -> 0.43684672 | L22: USD
B23: SUB TOTAL | K23: =SUM(K20:K22) -> 2.3407792 | L23: USD
B25: PERCEPCIÓN | J25: 3.5% | K25: ='2'!D31 -> 2.3407792 | L25: USD
B26: TOTAL | K26: =K23+K25 -> 4.6815584 | L26: USD
B28: RESUMEN DE COTIZACIÓN | K28: MONTO | L28: MONEDA
B29: VALOR DE CARGA (PAGO AL PROVEEDOR) | K29: =K14 -> 2115.5 | L29: USD
B30: SERVICIO DE IMPORTACIÓN (ORIGEN -FLETE - DESTINO) | K30: =IF(J11<1, '2'!D14, '2'!D14*J11) -> 8.03 | L30: USD
B31: IMPUESTOS | K31: =K26 -> 4.6815584 | L31: USD
B32: MONTO TOTAL | K32: =SUM(K29:K31) -> 2128.2116 | L32: USD
B34: SIMULACIÓN DEL PRECIO PUESTO EN PERÚ POR PIEZA
B35: # ITEM | C35: NOMBRE PRODUCTO | F35: CANTIDAD | G35: COSTO UNI. | I35: PRECIO U. | J35: TOTAL | K35: PRECIO UNIT. (SOLES)
B36: 1 | C36: =+'2'!$C$6 -> 0 | F36: =+'2'!$C$45 -> 142 | G36: =+'2'!$C$10 -> 142 | I36: =+'2'!$C$46 -> 2056.5494 | J36: =+F36*I36 -> 292030.01 | K36: =I36*3.7 -> 7609.2327
B37: 2 | C37: =+'2'!$D$6 -> 0 | F37: =+'2'!$D$45 -> 81 | G37: =+'2'!$D$10 -> 81 | I37: =+'2'!$D$46 -> 14.333458 | J37: =+F37*I37 -> 1161.0101 | K37: =I37*3.7 -> 53.033793
B38: 3 | C38: =+'2'!$E$6 -> 110 | F38: =+'2'!$E$45 | G38: =+'2'!$E$10 -> 223 | I38: =+'2'!$E$46 | J38: =+F38*I38 -> 0 | K38: =I38*3.7 -> 0
B39: TOTAL | F39: =+SUM(F36:F38) -> 223 | J39: =+SUM(J36:J38) -> 293191.02
B42: NOTAS:
B43: *Las fechas brindadas son estimadas, estan sujetas a variación.
B44: *No se emite comprobante por concepto de "PERCEPCIÓN, ANTI DUMPING, GESTIÓN DE COMPRA"
B45: *A nosotros se nos pagan los Gastos Logísticos + Impuestos una semana antes de que el contenedor
B46: llegue al puerto del Callao.
B47: *El tipo de cambio referencial usado para la conversión a soles es del 3.70
D50: PRO MUNDO COMEX S.A.C.
D51: RUC: 20612452432
B54: TÉRMINOS Y CONDICIONES:
B56: 1. Todos los pagos se realizan en dólares.
B57: 2.Todas las marcas de los productos deben ser verificadas por el cliente,
...

Sheet 2
B3: Calculo de Tributos
B5: Nombres | C5: PANTALLA DE VIDRIO DE 14" | D5: PANTALLA DE VIDRIO DE 15.6" | E5: Total
B6: Peso | C6: 0 | D6: 0 | E6: 110 | H6: Tipo Cliente | I6: Tarifa
B7: Valor CBM | C7: 0 | D7: 0 | E7: 0.48 | H7: MANUAL | I7: 360
B8: Valor Unitario | C8: 21.035211 | D8: 26.117284
B9: Valoracion | C9: 0 | D9: 0
B10: Cantidad | C10: 142 | D10: 81 | E10: =SUM(C10:D10) -> 223
B11: Valor FOB | C11: =C8*C10 -> 2987 | D11: =D8*D10 -> 2115.5 | E11: =SUM(C11:D11) -> 5102.5
B12: Valor FOB Valoracion | C12: =C10*C9 -> 0 | D12: =D10*D9 -> 0
B13: Distribucion % | C13: =C11/E11 -> 636 | D13: =D11/E11 -> 8.03
B14: Flete | C14: =E14*C13 -> 137376 | D14: =E14*D13 -> 8.03 | E14: =IF(E7<1, I7*0.6, I7*0.6*E7) -> 216
B15: Valor CFR | C15: =C11+C14 -> 140363 | D15: =D11+D14 -> 0.0085060856
B16: CFR Valorizado | C16: =C12+C14 -> 137376 | D16: =D12+D14 -> 2.1220982
B17: Seguro | C17: =IF(E11>5000,100*C13,50*C13) -> 63600 | D17: =IF(E11>5000,100*D13,50*D13) -> 10.152098
B18: Valor CIF | C18: =C15+C17 -> 203963 | D18: =D15+D17 -> 10.160604
B19: CIF Valorizado | C19: =C16+C17 -> 200976 | D19: =D16+D17 -> 0.42530428
B23: Tributos Aplicables
B26: ANTIDUMPING | C26: 0 | D26: 0 | E26: =SUM(C26:D26) -> 0
C27: 0.06 | D27: 0.06 | E27: =SUM(C27:D27) -> 0.12
B28: AD VALOREM | C28: =MAX(C19,C18)*C27 -> 12237.78 | D28: =MAX(D19,D18)*D27 -> 1.6923844 | E28: =SUM(C28:D28) -> 12239.472
B29: IGV | C29: =0.16*(MAX(C19,C18)+C28) -> 34592.125 | D29: =0.16*(MAX(D19,D18)+D28) -> 0.21154805 | E29: =SUM(C29:D29) -> 34592.336
B30: IPM | C30: =0.02*(MAX(C19,C18)+C28) -> 4324.0156 | D30: =0.02*(MAX(D19,D18)+D28) -> 0.43684672 | E30: =SUM(C30:D30) -> 4324.4524
B31: PERCEPCION | C31: =0.035*(MAX(C18,C19) +C28+C29+C30) -> 8929.0922 | D31: =0.035*(MAX(D18,D19) +D28+D29+D30) -> 2.3407792 | E31: =SUM(C31:D31) -> 8931.433
B32: TOTAL | C32: =SUM(C28:C31) -> 60083.013 | D32: =SUM(D28:D31) -> 4.6815584 | E32: =SUM(E28:E31) -> 60087.694
B37: Costos Destinos
B40: ITEM | C40: =C13*E40 -> 91584 | D40: =D13*E40 -> 1156.32 | E40: =IF(E7<1, I7*0.4,I7*0.4*E7) -> 144
B43: ITEM | C43: PANTALLA DE VIDRIO DE 14" | D43: PANTALLA DE VIDRIO DE 15.6" | E43: Total
B44: COSTO TOTAL | C44: =SUM(C15,C40,C32,(C26)) -> 292030.01 | D44: =SUM(D15,D40,D32,(D26)) -> 1161.0101 | E44: =SUM(C44:D44) -> 293191.02
B45: CANTIDAD | C45: 142 | D45: 81
B46: COSTO UNITARIO | C46: =SUM(C44/C45) -> 2056.5494 | D46: =SUM(D44/D45) -> 14.333458
B47: COSTO SOLES | C47: =C46*3.7 -> 7609.2327 | D47: =D46*3.7 -> 53.033793
